Workbook

Sheet SIM1_通知メッセ有
A2: Ver. | B2: 46269
A4: 株式会社チェングロウス御中_LINEOA施策提案【SIM】（通知メッセージ有）
N5: ※これより→はPDFにするときに消すようにする（範囲外に）
A7: ■要件定義 | B7: 地点 | C7: 名称 | D7: 成果単価
A8: 新規CV | B8: ①_CV地点 | C8: 求人応募（LINE経由） | D8: 0 | G8: UU | H8: 6100 | J8: 想定顧客リスト | K8: 0 | N8: SimilarWeb等を参考に | O8: ※メルマガ、他SNS等でのリリースが出来るか
B9: ②_CV地点 | C9: 求人応募（リッチメニュー経由） | D9: 0 | G9: 広告・アフィUU | H9: 5000 | N9: 広告比率等を参考に | O9: LINEプレスリリースの可否 | P9: FALSE
A10: リピートCV | B10: ③_CV地点 | C10: - | D10: 0 | G10: サイト応募（広告経由） | H10: 45 | N10: CV聞けてれば→通知メッセ、サンクスLINE誘導
B11: ④_CV地点 | C11: - | D11: 0 | G11: CV（別施策）2 | H11: 0
O12: ↓調整可能です！
A13: 項目 | D13: ※↓現状数値 | E13: 1か月目（4月） | F13: 2か月目（5月） | G13: 3か月目（6月） | H13: 4か月目（7月） | I13: 5か月目（8月） | J13: 6か月目（9月） | K13: 半年合計 | L13: 単月平均（６ヶ月） | N13: 20%くらいの調整は可能です。 | O13: →DYM作業用
A14: WEBサイト | B14: UU全体 | D14: =+H8 | E14: 6207 | F14: 6112 | G14: 6066 | H14: 6179 | I14: 6005 | J14: 6243
B15: UU(うち広告) | D15: =+H9 | E15: 5088 | F15: 5010 | G15: 4972 | H15: 5065 | I15: 4922 | J15: 5118 | N15: （サイト固定リンク） | O15: AD以外のLINE誘導 | P15: 0.005 | S15: ■従量計算式↓
B16: CV（別施策） ※想定 | D16: =H10 | E16: 40 | F16: 41 | G16: 43 | H16: 45 | I16: 44 | J16: 47 | N16: （サイト固定リンク） | O16: ADでのLP/HP→LINE | P16: 0.0025 | S16: ■料金テーブル
A17: 施策 | B17: CPF | D17: FALSE | E17: FALSE | F17: FALSE | G17: FALSE | H17: FALSE | I17: FALSE | J17: FALSE | K17: -- | L17: -- | S17: 課金対象配信総数 | W17: 費用 | Z17: 単価
B18: 離脱防止 | D18: FALSE | E18: TRUE | F18: TRUE | G18: TRUE | H18: TRUE | I18: TRUE | J18: TRUE | K18: -- | L18: -- | N18: KaiU表示率 | O18: 離脱防止表示率（AD） | P18: 0.65 | S18: 0 | T18: - | U18: 200000 | W18: 0 | X18: - | Y18: 600000 | Z18: 3
B19: サンクスLINE誘導 | D19: FALSE | E19: TRUE | F19: TRUE | G19: TRUE | H19: TRUE | I19: TRUE | J19: TRUE | N19: KaiU表示率 | O19: 離脱防止表示率（SEO） | P19: 0.55 | S19: 200000 | T19: - | U19: 15000000 | W19: 600000 | X19: - | Y19: =+U19*2.5 | Z19: 2.5
B20: 通知メッセージ_CV | D20: FALSE | E20: TRUE | F20: TRUE | G20: TRUE | H20: TRUE | I20: TRUE | J20: TRUE
B21: 通知メッセージ_既存リスト | D21: FALSE | E21: FALSE | F21: FALSE | G21: FALSE | H21: FALSE | I21: FALSE | J21: FALSE | K21: -- | L21: -- | O21: ↓企画投稿
A22: 施策増分 ※友だち | B22: CPF | D22: -- | E22: =IF(E17=FALSE,0,IF(E65=0,0,IFERROR(E65/P30,"D63を記入してください"))) | F22: =E22*1.01 | G22: =F22*1.01 | H22: =G22*1.01 | I22: =H22*1.01 | J22: =I22*1.01 | N22: CPFコスト / CPFの単価設定 ※ブロック率が上がりやすい | O22: 開封率 | P22: 0.78
B23: 離脱防止 | D23: -- | E23: =IF(E18=FALSE,0,E14*0.4*0.125*0.125*0.62) | F23: =IF(F18=FALSE,0,F14*0.4*0.125*0.125*0.81) | G23: =IF(G18=FALSE,0,G14*0.4*0.125*0.125*0.93) | H23: =IF(H18=FALSE,0,H14*0.4*0.125*0.125*1.0) | I23: =IF(I18=FALSE,0,I14*0.4*0.125*0.125*1.03) | J23: =IF(J18=FALSE,0,J14*0.4*0.125*0.125*1.05) | N23: 離脱防止：UU×表示40%×クリック12.5%×追加12.5%×立ち上げ係数 | O23: クリック率 | P23: 0.1 | Q23: 4‐6か月後係数
B24: サンクスLINE誘導 | D24: -- | E24: =IF(E19=FALSE,0,E16*0.8*0.45*0.62) | F24: =IF(F19=FALSE,0,F16*0.8*0.45*0.81) | G24: =IF(G19=FALSE,0,G16*0.8*0.45*0.93) | H24: =IF(H19=FALSE,0,H16*0.8*0.45*1.0) | I24: =IF(I19=FALSE,0,I16*0.8*0.45*1.03) | J24: =IF(J19=FALSE,0,J16*0.8*0.45*1.05) | N24: 完了画面：サイト応募×遷移80%×追加45%×立ち上げ係数 | O24: audienceターゲ率 | P24: 0.8 | Q24: 0.8
B25: 通知メッセージ | D25: -- | E25: =IF(E20=FALSE,0,E16*(1-0.8*0.45*0.62)*0.7*0.3) | F25: =IF(F20=FALSE,0,F16*(1-0.8*0.45*0.81)*0.7*0.3) | G25: =IF(G20=FALSE,0,G16*(1-0.8*0.45*0.93)*0.7*0.3) | H25: =IF(H20=FALSE,0,H16*(1-0.8*0.45*1.0)*0.7*0.3) | I25: =IF(I20=FALSE,0,I16*(1-0.8*0.45*1.03)*0.7*0.3) | J25: =IF(J20=FALSE,0,J16*(1-0.8*0.45*1.05)*0.7*0.3) | N25: 通知メッセ：完了画面で追加しなかった応募者×情報一致70%×追加30% | O25: ↓ステップ配信
A26: 友だち数_増加数 | D26: -- | E26: =SUM(E22:E25)+E14*0.005*0.62 | F26: =SUM(F22:F25)+F14*0.005*0.81 | G26: =SUM(G22:G25)+G14*0.005*0.93 | H26: =SUM(H22:H25)+H14*0.005*1.0 | I26: =SUM(I22:I25)+I14*0.005*1.03 | J26: =SUM(J22:J25)+J14*0.005*1.05 | N26: ＋サイト内「LINEで登録」：UU×0.5%×立ち上げ係数 | O26: 開封率 | P26: 0.725
A27: ブロック率 | D27: 0 | E27: 0.406 | F27: 0.391 | G27: 0.378 | H27: 0.362 | I27: 0.359 | J27: 0.344 | N27: ブロック率：40%前後から出し分け配信で徐々に低下（目標30%以内） | O27: クリック率 | P27: 0.12 | Q27: 4‐6か月後係数
A28: 友だち数 | D28: 0 | E28: =+D28+E26 | F28: =+E28+F26 | G28: =+F28+G26 | H28: =+G28+H26 | I28: =+H28+I26 | J28: =+I28+J26 | O28: audienceターゲ率 | P28: 0.2 | Q28: 0.8
A29: ターゲット数 | D29: 0 | E29: =+E28*(1-E27) | F29: =+F28*(1-F27) | G29: =+G28*(1-G27) | H29: =+H28*(1-H27) | I29: =+I28*(1-I27) | J29: =+J28*(1-J27) | N29: ※ターゲット数の増加分が通常の増加分を超えないように調整する
A30: 企画投稿数 | D30: 0 | E30: 4 | F30: 4 | G30: 4 | H30: 4 | I30: 4 | J30: 4 | N30: ←基本本数が4本として設計する（ユーザー数と固定費で調整） | O30: CPFの単価設定
A31: 企画投稿からの流入 | D31: =+D30*D29*0.41*0.07 | E31: =+E29*E30*$P$24*$P$22*$P$23*$P$36 | F31: =+F29*F30*$P$24*$P$22*$P$23*$P$36 | G31: =+G29*G30*$P$24*$P$22*$P$23*$P$36 | H31: =+H29*H30*$P$24*$P$22*$P$23*$P$36*$Q$24 | I31: =+I29*I30*$P$24*$P$22*$P$23*$P$36*$Q$24 | J31: =+J29*J30*$P$24*$P$22*$P$23*$P$36*$Q$24
A32: ステップ配信本数 | D32: 0 | E32: 10 | F32: 10 | G32: 10 | H32: 10 | I32: 10 | J32: 10 | N32: ←基本本数が4本として設計する | O32: 特典の強さ | P32: TRUE | Q32: =+IF(P32=TRUE,1.1,0.95)
A33: ステップ配信からの流入 | D33: 0 | E33: =+E29*E32*$P$26*$P$27*$P$28*$P$36 | F33: =+F29*F32*$P$26*$P$27*$P$28*$P$36 | G33: =+G29*G32*$P$26*$P$27*$P$28*$P$36 | H33: =+H29*H32*$P$26*$P$27*$P$28*$P$36*$Q$28 | I33: =+I29*I32*$P$26*$P$27*$P$28*$P$36*$Q$28 | J33: =+J29*J32*$P$26*$P$27*$P$28*$P$36*$Q$28 | O33: クリエイティブ強さ | P33: TRUE | Q33: =+IF(P33=TRUE,1.1,0.95)
A34: 配信数 | D34: =+D29*D30 | E34: =+E29*E30*$P$24+E29*E32*$P$28 | F34: =+F29*F30*$P$24+F29*F32*$P$28 | G34: =+G29*G30*$P$24+G29*G32*$P$28 | H34: =+H29*H30*$P$24*$Q$24+H29*H32*$P$28*$Q$28 | I34: =+I29*I30*$P$24*$Q$24+I29*I32*$P$28*$Q$28 | J34: =+J29*J30*$P$24*$Q$24+J29*J32*$P$28*$Q$28 | O34: 知名度強さ | P34: TRUE | Q34: =+IF(P34=TRUE,1.1,0.95)
A35: 想定Click数 | D35: =+D31*1.02 | E35: =+E31+E33+1.05*(E31+E33)+E29*0.3*2 | F35: =+F31+F33+1.05*(F31+F33)+F29*0.3*2 | G35: =+G31+G33+1.05*(G31+G33)+G29*0.3*2 | H35: =+H31+H33+1.05*(H31+H33)+H29*0.3*2 | I35: =+I31+I33+1.05*(I31+I33)+I29*0.3*2 | J35: =+J31+J33+1.05*(J31+J33)+J29*0.3*2 | N35: ＋リッチメニューのタップ：有効な友だち×月に使う率30%×2回 | O35: 動線の強さ | P35: TRUE | Q35: =+IF(P35=TRUE,1.1,0.95)
A36: 新規CV | B36: =+C8 | D36: 0 | E36: 0 | F36: 1 | G36: 1 | H36: 2 | I36: 2 | J36: 3 | K36: =SUM(E36:J36) | N36: 新規向け_ | O36: 想定の係数（反応率） | P36: =1*(Q32*Q33*Q34*Q35)
B37: =+C9 | D37: 0 | E37: =ROUND(E29*0.3*2*0.015,0) | F37: =ROUND(F29*0.3*2*0.015,0) | G37: =ROUND(G29*0.3*2*0.015,0) | H37: =ROUND(H29*0.3*2*0.015,0) | I37: =ROUND(I29*0.3*2*0.015,0) | J37: =ROUND(J29*0.3*2*0.015,0) | K37: =SUM(E37:J37) | N37: リッチメニュー経由の応募：有効な友だち×月に使う率30%×2回検索×応募率1.5%
A38: リピートCV | B38: =+C10 | D38: 0 | E38: 0 | F38: 0 | G38: 0 | H38: 0 | I38: 0 | J38: 0 | K38: =SUM(E38:J38) | N38: 既存向け_休眠顧客向け | O38: ※①＞②で作成
B39: =+C11 | D39: 0 | E39: 0 | F39: 0 | G39: 0 | H39: 0 | I39: 0 | J39: 0 | K39: =SUM(E39:J39) | N39: 既存向け_休眠顧客向け | O39: ※③＞④で作成
A40: 合計CV | D40: =+SUM(D36:D39) | E40: =+SUM(E36:E39) | F40: =+SUM(F36:F39) | G40: =+SUM(G36:G39) | H40: =+SUM(H36:H39) | I40: =+SUM(I36:I39) | J40: =+SUM(J36:J39) | K40: =SUM(E40:J40)
B41: CVR | D41: =+IFERROR(D40/D35,0) | E41: =+IFERROR(E40/E35,0) | F41: =+IFERROR(F40/F35,0) | G41: =+IFERROR(G40/G35,0) | H41: =+IFERROR(H40/H35,0) | I41: =+IFERROR(I40/I35,0) | J41: =+IFERROR(J40/J35,0) | N41: CV/流入数で計算、0.3%〜1%とかで推移。
A43: ■成果報酬運営 | C43: 現状数値 | D43: 初期
A44: 従量課金 | D44: -- | E44: =+E75*E76 | F44: =+F75*F76 | G44: =+G75*G76 | H44: =+H75*H76 | I44: =+I75*I76 | J44: =+J75*J76
...

Sheet SIM1_比較
E1: →通数減らすように係数： | F1: 0.6
A3: 比較項目 | C3: DYM実装前 | D3: DYM実装後（③か月） | E3: DYM実装後（⑥か月）
A4: コスト想定 ※月額（成果報酬プラン） | C4: =+'SIM1_通知メッセ有'!D24 | D4: =+'SIM1_通知メッセ有'!G51 | E4: =+'SIM1_通知メッセ有'!J51
A5: コスト想定 ※月額（固定プラン） | C5: =+'SIM1_通知メッセ有'!D25 | D5: =+'SIM1_通知メッセ有'!G61 | E5: =+'SIM1_通知メッセ有'!J61
A6: 友だち数想定 | C6: =+'SIM1_通知メッセ有'!D28 | D6: =+'SIM1_通知メッセ有'!G28 | E6: =+'SIM1_通知メッセ有'!J28
A7: ブロック率想定 | C7: =+'SIM1_通知メッセ有'!D27 | D7: ='SIM1_通知メッセ有'!G27 | E7: ='SIM1_通知メッセ有'!J27
A8: 友だち数（アクティブ）想定 | C8: =+'SIM1_通知メッセ有'!D29 | D8: =+'SIM1_通知メッセ有'!G29 | E8: =+'SIM1_通知メッセ有'!J29
A10: メッセ通数 | C10: =+'SIM1_通知メッセ有'!D34 | D10: =+'SIM1_通知メッセ有'!G34 | E10: =+'SIM1_通知メッセ有'!J34
A11: サイト流入数（LINEから） | C11: =+'SIM1_通知メッセ有'!D35 | D11: =+'SIM1_通知メッセ有'!G35 | E11: =+'SIM1_通知メッセ有'!J35
A12: 想定CPC（LINEOA施策）_成果報酬プラン | C12: =+IFERROR(C5/C11,0) | D12: =+D4/D11 | E12: =+E4/E11
A13: 想定CPC（LINEOA施策）_固定運用プラン | C13: =+IFERROR(C6/C12,0) | D13: =+D5/D11 | E13: =+E5/E11
R14: ■従量計算式↓
A15: CV数（もともと） | C15: =+'SIM1_通知メッセ有'!D16 | D15: =+'SIM1_通知メッセ有'!E16 | E15: =+'SIM1_通知メッセ有'!F16 | R15: ■料金テーブル
A16: CV数（+LINEOA施策） | C16: =SUM(C17:C20) | D16: =SUM(D17:D20) | E16: =SUM(E17:E20) | R16: 課金対象配信総数 | V16: 費用 | Y16: 単価
A17: OA施策CV_内訳①_新規CV1 | C17: =+'SIM1_通知メッセ有'!D36 | D17: =+'SIM1_通知メッセ有'!G36 | E17: =+'SIM1_通知メッセ有'!J36 | R17: 0 | S17: - | T17: 200000 | V17: 0 | W17: - | X17: 600000 | Y17: 3
A18: OA施策CV_内訳②_新規CV2 | C18: =+'SIM1_通知メッセ有'!D37 | D18: =+'SIM1_通知メッセ有'!G37 | E18: =+'SIM1_通知メッセ有'!J37 | R18: 200000 | S18: - | T18: 15000000 | V18: 600000 | W18: - | X18: =+T18*2.5 | Y18: 2.5
A19: OA施策CV_内訳③_リピCV3 | C19: =+'SIM1_通知メッセ有'!D38 | D19: =+'SIM1_通知メッセ有'!G38 | E19: =+'SIM1_通知メッセ有'!J38
A20: OA施策CV_内訳④_リピCV4 | C20: =+'SIM1_通知メッセ有'!D39 | D20: =+'SIM1_通知メッセ有'!G39 | E20: =+'SIM1_通知メッセ有'!J39
A22: 成果報酬プラン_CPA（単純計算） | C22: =+IFERROR(C4/C16,"--") | D22: =+IFERROR(D4/D16,"--") | E22: =+IFERROR(E4/E16,"--")
A23: 固定費プラン_CPA（単純計算） | C23: =+IFERROR(C5/C16,"--") | D23: =+IFERROR(D5/D16,"--") | E23: =+IFERROR(E5/E16,"--")
A25: 備考_合計コスト(従量課金) ※アカウント費用 | C25: =15000+C29*C30 | D25: =15000+D29*D30 | E25: =15000+E29*E30
A29: 従量課金対象単価 | C29: =+IF(C10<=30000,0,C10-30000) | D29: =+IF(D10<=30000,0,D10-30000) | E29: =+IF(E10<=30000,0,E10-30000)
A30: 備考単価 | C30: =+IF(C29<=$T$17,$Y$17,IF(C29<=$T$18,$Y$18,IF(C29<=$T$19,$Y$19,IF(C29<=$T$20,$Y$20,IF(C29<=$T$21,$Y$21,IF(C29<=$T$22,$Y$22,IF(C29<=$T$23,$Y$23,IF(C29<=$T$24,$Y$24,IF(C29<=$T$25,$Y$25,IF(C29<=$T$26,$Y$26,IF(C29<=$T$27,$Y$27,IF(C29<=$T$28,$Y$28,IF(C29<=$T$29,$Y$29,0))))))))))))) | D30: =+IF(D29<=$T$17,$Y$17,IF(D29<=$T$18,$Y$18,IF(D29<=$T$19,$Y$19,IF(D29<=$T$20,$Y$20,IF(D29<=$T$21,$Y$21,IF(D29<=$T$22,$Y$22,IF(D29<=$T$23,$Y$23,IF(D29<=$T$24,$Y$24,IF(D29<=$T$25,$Y$25,IF(D29<=$T$26,$Y$26,IF(D29<=$T$27,$Y$27,IF(D29<=$T$28,$Y$28,IF(D29<=$T$29,$Y$29,0))))))))))))) | E30: =+IF(E29<=$T$17,$Y$17,IF(E29<=$T$18,$Y$18,IF(E29<=$T$19,$Y$19,IF(E29<=$T$20,$Y$20,IF(E29<=$T$21,$Y$21,IF(E29<=$T$22,$Y$22,IF(E29<=$T$23,$Y$23,IF(E29<=$T$24,$Y$24,IF(E29<=$T$25,$Y$25,IF(E29<=$T$26,$Y$26,IF(E29<=$T$27,$Y$27,IF(E29<=$T$28,$Y$28,IF(E29<=$T$29,$Y$29,0)))))))))))))
A35: 階層別 | C35: 母数 | D35: 誘導率 | E35: 想定CVR | F35: 想定CVR

Sheet SIM2_通知メッセ無
A2: Ver. | B2: 46269
A4: 株式会社チェングロウス御中_LINEOA施策提案【SIM】（通知メッセージ無）
N5: ※これより→はPDFにするときに消すようにする（範囲外に）
A7: ■要件定義 | B7: 地点 | C7: 名称 | D7: 成果単価
A8: 新規CV | B8: ①_CV地点 | C8: 求人応募（LINE経由） | D8: 0 | G8: UU | H8: 6100 | J8: 想定顧客リスト | K8: 0 | N8: SimilarWeb等を参考に | O8: ※メルマガ、他SNS等でのリリースが出来るか
B9: ②_CV地点 | C9: 求人応募（リッチメニュー経由） | D9: 0 | G9: 広告・アフィUU | H9: 5000 | N9: 広告比率等を参考に | O9: LINEプレスリリースの可否 | P9: FALSE
A10: リピートCV | B10: ③_CV地点 | C10: - | D10: 0 | G10: サイト応募（広告経由） | H10: 45 | N10: CV聞けてれば→通知メッセ、サンクスLINE誘導
B11: ④_CV地点 | C11: - | D11: 0 | G11: CV（別施策）2 | H11: 0
O12: ↓調整可能です！
A13: 項目 | D13: ※↓現状数値 | E13: 1か月目（4月） | F13: 2か月目（5月） | G13: 3か月目（6月） | H13: 4か月目（7月） | I13: 5か月目（8月） | J13: 6か月目（9月） | K13: 半年合計 | L13: 単月平均（６ヶ月） | N13: 20%くらいの調整は可能です。 | O13: →DYM作業用
A14: WEBサイト | B14: UU全体 | D14: =+H8 | E14: 6207 | F14: 6112 | G14: 6066 | H14: 6179 | I14: 6005 | J14: 6243
B15: UU(うち広告) | D15: =+H9 | E15: 5088 | F15: 5010 | G15: 4972 | H15: 5065 | I15: 4922 | J15: 5118 | N15: （サイト固定リンク） | O15: AD以外のLINE誘導 | P15: 0.005 | S15: ■従量計算式↓
B16: CV（別施策） ※想定 | D16: =H10 | E16: 40 | F16: 41 | G16: 43 | H16: 45 | I16: 44 | J16: 47 | N16: （サイト固定リンク） | O16: ADでのLP/HP→LINE | P16: 0.0025 | S16: ■料金テーブル
A17: 施策 | B17: CPF | D17: FALSE | E17: FALSE | F17: FALSE | G17: FALSE | H17: FALSE | I17: FALSE | J17: FALSE | K17: -- | L17: -- | S17: 課金対象配信総数 | W17: 費用 | Z17: 単価
B18: 離脱防止 | D18: FALSE | E18: TRUE | F18: TRUE | G18: TRUE | H18: TRUE | I18: TRUE | J18: TRUE | K18: -- | L18: -- | N18: KaiU表示率 | O18: 離脱防止表示率（AD） | P18: 0.65 | S18: 0 | T18: - | U18: 200000 | W18: 0 | X18: - | Y18: 600000 | Z18: 3
B19: サンクスLINE誘導 | D19: FALSE | E19: TRUE | F19: TRUE | G19: TRUE | H19: TRUE | I19: TRUE | J19: TRUE | N19: KaiU表示率 | O19: 離脱防止表示率（SEO） | P19: 0.55 | S19: 200000 | T19: - | U19: 15000000 | W19: 600000 | X19: - | Y19: =+U19*2.5 | Z19: 2.5
B20: 通知メッセージ_CV | D20: FALSE | E20: FALSE | F20: FALSE | G20: FALSE | H20: FALSE | I20: FALSE | J20: FALSE
B21: 通知メッセージ_既存リスト | D21: FALSE | E21: FALSE | F21: FALSE | G21: FALSE | H21: FALSE | I21: FALSE | J21: FALSE | K21: -- | L21: -- | O21: ↓企画投稿
A22: 施策増分 ※友だち | B22: CPF | D22: -- | E22: =IF(E17=FALSE,0,IF(E65=0,0,IFERROR(E65/P30,"D63を記入してください"))) | F22: =E22*1.01 | G22: =F22*1.01 | H22: =G22*1.01 | I22: =H22*1.01 | J22: =I22*1.01 | N22: CPFコスト / CPFの単価設定 ※ブロック率が上がりやすい | O22: 開封率 | P22: 0.78
B23: 離脱防止 | D23: -- | E23: =IF(E18=FALSE,0,E14*0.4*0.125*0.125*0.62) | F23: =IF(F18=FALSE,0,F14*0.4*0.125*0.125*0.81) | G23: =IF(G18=FALSE,0,G14*0.4*0.125*0.125*0.93) | H23: =IF(H18=FALSE,0,H14*0.4*0.125*0.125*1.0) | I23: =IF(I18=FALSE,0,I14*0.4*0.125*0.125*1.03) | J23: =IF(J18=FALSE,0,J14*0.4*0.125*0.125*1.05) | N23: 離脱防止：UU×表示40%×クリック12.5%×追加12.5%×立ち上げ係数 | O23: クリック率 | P23: 0.1 | Q23: 4‐6か月後係数
B24: サンクスLINE誘導 | D24: -- | E24: =IF(E19=FALSE,0,E16*0.8*0.45*0.62) | F24: =IF(F19=FALSE,0,F16*0.8*0.45*0.81) | G24: =IF(G19=FALSE,0,G16*0.8*0.45*0.93) | H24: =IF(H19=FALSE,0,H16*0.8*0.45*1.0) | I24: =IF(I19=FALSE,0,I16*0.8*0.45*1.03) | J24: =IF(J19=FALSE,0,J16*0.8*0.45*1.05) | N24: 完了画面：サイト応募×遷移80%×追加45%×立ち上げ係数 | O24: audienceターゲ率 | P24: 0.8 | Q24: 0.8
B25: 通知メッセージ | D25: -- | E25: =IF(E20=FALSE,0,E16*(1-0.8*0.45*0.62)*0.7*0.3) | F25: =IF(F20=FALSE,0,F16*(1-0.8*0.45*0.81)*0.7*0.3) | G25: =IF(G20=FALSE,0,G16*(1-0.8*0.45*0.93)*0.7*0.3) | H25: =IF(H20=FALSE,0,H16*(1-0.8*0.45*1.0)*0.7*0.3) | I25: =IF(I20=FALSE,0,I16*(1-0.8*0.45*1.03)*0.7*0.3) | J25: =IF(J20=FALSE,0,J16*(1-0.8*0.45*1.05)*0.7*0.3) | N25: 通知メッセ：完了画面で追加しなかった応募者×情報一致70%×追加30% | O25: ↓ステップ配信
A26: 友だち数_増加数 | D26: -- | E26: =SUM(E22:E25)+E14*0.005*0.62 | F26: =SUM(F22:F25)+F14*0.005*0.81 | G26: =SUM(G22:G25)+G14*0.005*0.93 | H26: =SUM(H22:H25)+H14*0.005*1.0 | I26: =SUM(I22:I25)+I14*0.005*1.03 | J26: =SUM(J22:J25)+J14*0.005*1.05 | N26: ＋サイト内「LINEで登録」：UU×0.5%×立ち上げ係数 | O26: 開封率 | P26: 0.725
A27: ブロック率 | D27: 0 | E27: 0.406 | F27: 0.391 | G27: 0.378 | H27: 0.362 | I27: 0.359 | J27: 0.344 | N27: ブロック率：40%前後から出し分け配信で徐々に低下（目標30%以内） | O27: クリック率 | P27: 0.12 | Q27: 4‐6か月後係数
A28: 友だち数 | D28: 0 | E28: =+D28+E26 | F28: =+E28+F26 | G28: =+F28+G26 | H28: =+G28+H26 | I28: =+H28+I26 | J28: =+I28+J26 | O28: audienceターゲ率 | P28: 0.2 | Q28: 0.8
A29: ターゲット数 | D29: 0 | E29: =+E28*(1-E27) | F29: =+F28*(1-F27) | G29: =+G28*(1-G27) | H29: =+H28*(1-H27) | I29: =+I28*(1-I27) | J29: =+J28*(1-J27) | N29: ※ターゲット数の増加分が通常の増加分を超えないように調整する
A30: 企画投稿数 | D30: 0 | E30: 4 | F30: 4 | G30: 4 | H30: 4 | I30: 4 | J30: 4 | N30: ←基本本数が4本として設計する（ユーザー数と固定費で調整） | O30: CPFの単価設定
A31: 企画投稿からの流入 | D31: =+D30*D29*0.41*0.07 | E31: =+E29*E30*$P$24*$P$22*$P$23*$P$36 | F31: =+F29*F30*$P$24*$P$22*$P$23*$P$36 | G31: =+G29*G30*$P$24*$P$22*$P$23*$P$36 | H31: =+H29*H30*$P$24*$P$22*$P$23*$P$36*$Q$24 | I31: =+I29*I30*$P$24*$P$22*$P$23*$P$36*$Q$24 | J31: =+J29*J30*$P$24*$P$22*$P$23*$P$36*$Q$24
A32: ステップ配信本数 | D32: 0 | E32: 10 | F32: 10 | G32: 10 | H32: 10 | I32: 10 | J32: 10 | N32: ←基本本数が4本として設計する | O32: 特典の強さ | P32: TRUE | Q32: =+IF(P32=TRUE,1.1,0.95)
A33: ステップ配信からの流入 | D33: 0 | E33: =+E29*E32*$P$26*$P$27*$P$28*$P$36 | F33: =+F29*F32*$P$26*$P$27*$P$28*$P$36 | G33: =+G29*G32*$P$26*$P$27*$P$28*$P$36 | H33: =+H29*H32*$P$26*$P$27*$P$28*$P$36*$Q$28 | I33: =+I29*I32*$P$26*$P$27*$P$28*$P$36*$Q$28 | J33: =+J29*J32*$P$26*$P$27*$P$28*$P$36*$Q$28 | O33: クリエイティブ強さ | P33: TRUE | Q33: =+IF(P33=TRUE,1.1,0.95)
A34: 配信数 | D34: =+D29*D30 | E34: =+E29*E30*$P$24+E29*E32*$P$28 | F34: =+F29*F30*$P$24+F29*F32*$P$28 | G34: =+G29*G30*$P$24+G29*G32*$P$28 | H34: =+H29*H30*$P$24*$Q$24+H29*H32*$P$28*$Q$28 | I34: =+I29*I30*$P$24*$Q$24+I29*I32*$P$28*$Q$28 | J34: =+J29*J30*$P$24*$Q$24+J29*J32*$P$28*$Q$28 | O34: 知名度強さ | P34: TRUE | Q34: =+IF(P34=TRUE,1.1,0.95)
A35: 想定Click数 | D35: =+D31*1.02 | E35: =+E31+E33+1.05*(E31+E33)+E29*0.3*2 | F35: =+F31+F33+1.05*(F31+F33)+F29*0.3*2 | G35: =+G31+G33+1.05*(G31+G33)+G29*0.3*2 | H35: =+H31+H33+1.05*(H31+H33)+H29*0.3*2 | I35: =+I31+I33+1.05*(I31+I33)+I29*0.3*2 | J35: =+J31+J33+1.05*(J31+J33)+J29*0.3*2 | N35: ＋リッチメニューのタップ：有効な友だち×月に使う率30%×2回 | O35: 動線の強さ | P35: TRUE | Q35: =+IF(P35=TRUE,1.1,0.95)
A36: 新規CV | B36: =+C8 | D36: 0 | E36: 0 | F36: 1 | G36: 1 | H36: 1 | I36: 2 | J36: 3 | K36: =SUM(E36:J36) | N36: 新規向け_ | O36: 想定の係数（反応率） | P36: =1*(Q32*Q33*Q34*Q35)
B37: =+C9 | D37: 0 | E37: =ROUND(E29*0.3*2*0.015,0) | F37: =ROUND(F29*0.3*2*0.015,0) | G37: =ROUND(G29*0.3*2*0.015,0) | H37: =ROUND(H29*0.3*2*0.015,0) | I37: =ROUND(I29*0.3*2*0.015,0) | J37: =ROUND(J29*0.3*2*0.015,0) | K37: =SUM(E37:J37) | N37: リッチメニュー経由の応募：有効な友だち×月に使う率30%×2回検索×応募率1.5%
A38: リピートCV | B38: =+C10 | D38: 0 | E38: 0 | F38: 0 | G38: 0 | H38: 0 | I38: 0 | J38: 0 | K38: =SUM(E38:J38) | N38: 既存向け_休眠顧客向け | O38: ※①＞②で作成
B39: =+C11 | D39: 0 | E39: 0 | F39: 0 | G39: 0 | H39: 0 | I39: 0 | J39: 0 | K39: =SUM(E39:J39) | N39: 既存向け_休眠顧客向け | O39: ※③＞④で作成
A40: 合計CV | D40: =+SUM(D36:D39) | E40: =+SUM(E36:E39) | F40: =+SUM(F36:F39) | G40: =+SUM(G36:G39) | H40: =+SUM(H36:H39) | I40: =+SUM(I36:I39) | J40: =+SUM(J36:J39) | K40: =SUM(E40:J40)
B41: CVR | D41: =+IFERROR(D40/D35,0) | E41: =+IFERROR(E40/E35,0) | F41: =+IFERROR(F40/F35,0) | G41: =+IFERROR(G40/G35,0) | H41: =+IFERROR(H40/H35,0) | I41: =+IFERROR(I40/I35,0) | J41: =+IFERROR(J40/J35,0) | N41: CV/流入数で計算、0.3%〜1%とかで推移。
A43: ■成果報酬運営 | C43: 現状数値 | D43: 初期
A44: 従量課金 | D44: -- | E44: =+E75*E76 | F44: =+F75*F76 | G44: =+G75*G76 | H44: =+H75*H76 | I44: =+I75*I76 | J44: =+J75*J76
...

Sheet SIM2_比較
E1: →通数減らすように係数： | F1: 0.6
A3: 比較項目 | C3: DYM実装前 | D3: DYM実装後（③か月） | E3: DYM実装後（⑥か月）
A4: コスト想定 ※月額（成果報酬プラン） | C4: =+'SIM2_通知メッセ無'!D24 | D4: =+'SIM2_通知メッセ無'!G51 | E4: =+'SIM2_通知メッセ無'!J51
A5: コスト想定 ※月額（固定プラン） | C5: =+'SIM2_通知メッセ無'!D25 | D5: =+'SIM2_通知メッセ無'!G61 | E5: =+'SIM2_通知メッセ無'!J61
A6: 友だち数想定 | C6: =+'SIM2_通知メッセ無'!D28 | D6: =+'SIM2_通知メッセ無'!G28 | E6: =+'SIM2_通知メッセ無'!J28
A7: ブロック率想定 | C7: =+'SIM2_通知メッセ無'!D27 | D7: ='SIM2_通知メッセ無'!G27 | E7: ='SIM2_通知メッセ無'!J27
A8: 友だち数（アクティブ）想定 | C8: =+'SIM2_通知メッセ無'!D29 | D8: =+'SIM2_通知メッセ無'!G29 | E8: =+'SIM2_通知メッセ無'!J29
A10: メッセ通数 | C10: =+'SIM2_通知メッセ無'!D34 | D10: =+'SIM2_通知メッセ無'!G34 | E10: =+'SIM2_通知メッセ無'!J34
A11: サイト流入数（LINEから） | C11: =+'SIM2_通知メッセ無'!D35 | D11: =+'SIM2_通知メッセ無'!G35 | E11: =+'SIM2_通知メッセ無'!J35
A12: 想定CPC（LINEOA施策）_成果報酬プラン | C12: =+IFERROR(C5/C11,0) | D12: =+D4/D11 | E12: =+E4/E11
A13: 想定CPC（LINEOA施策）_固定運用プラン | C13: =+IFERROR(C6/C12,0) | D13: =+D5/D11 | E13: =+E5/E11
R14: ■従量計算式↓
A15: CV数（もともと） | C15: =+'SIM2_通知メッセ無'!D16 | D15: =+'SIM2_通知メッセ無'!E16 | E15: =+'SIM2_通知メッセ無'!F16 | R15: ■料金テーブル
A16: CV数（+LINEOA施策） | C16: =SUM(C17:C20) | D16: =SUM(D17:D20) | E16: =SUM(E17:E20) | R16: 課金対象配信総数 | V16: 費用 | Y16: 単価
A17: OA施策CV_内訳①_新規CV1 | C17: =+'SIM2_通知メッセ無'!D36 | D17: =+'SIM2_通知メッセ無'!G36 | E17: =+'SIM2_通知メッセ無'!J36 | R17: 0 | S17: - | T17: 200000 | V17: 0 | W17: - | X17: 600000 | Y17: 3
A18: OA施策CV_内訳②_新規CV2 | C18: =+'SIM2_通知メッセ無'!D37 | D18: =+'SIM2_通知メッセ無'!G37 | E18: =+'SIM2_通知メッセ無'!J37 | R18: 200000 | S18: - | T18: 15000000 | V18: 600000 | W18: - | X18: =+T18*2.5 | Y18: 2.5
A19: OA施策CV_内訳③_リピCV3 | C19: =+'SIM2_通知メッセ無'!D38 | D19: =+'SIM2_通知メッセ無'!G38 | E19: =+'SIM2_通知メッセ無'!J38
A20: OA施策CV_内訳④_リピCV4 | C20: =+'SIM2_通知メッセ無'!D39 | D20: =+'SIM2_通知メッセ無'!G39 | E20: =+'SIM2_通知メッセ無'!J39
A22: 成果報酬プラン_CPA（単純計算） | C22: =+IFERROR(C4/C16,"--") | D22: =+IFERROR(D4/D16,"--") | E22: =+IFERROR(E4/E16,"--")
A23: 固定費プラン_CPA（単純計算） | C23: =+IFERROR(C5/C16,"--") | D23: =+IFERROR(D5/D16,"--") | E23: =+IFERROR(E5/E16,"--")
A25: 備考_合計コスト(従量課金) ※アカウント費用 | C25: =15000+C29*C30 | D25: =15000+D29*D30 | E25: =15000+E29*E30
A29: 従量課金対象単価 | C29: =+IF(C10<=30000,0,C10-30000) | D29: =+IF(D10<=30000,0,D10-30000) | E29: =+IF(E10<=30000,0,E10-30000)
A30: 備考単価 | C30: =+IF(C29<=$T$17,$Y$17,IF(C29<=$T$18,$Y$18,IF(C29<=$T$19,$Y$19,IF(C29<=$T$20,$Y$20,IF(C29<=$T$21,$Y$21,IF(C29<=$T$22,$Y$22,IF(C29<=$T$23,$Y$23,IF(C29<=$T$24,$Y$24,IF(C29<=$T$25,$Y$25,IF(C29<=$T$26,$Y$26,IF(C29<=$T$27,$Y$27,IF(C29<=$T$28,$Y$28,IF(C29<=$T$29,$Y$29,0))))))))))))) | D30: =+IF(D29<=$T$17,$Y$17,IF(D29<=$T$18,$Y$18,IF(D29<=$T$19,$Y$19,IF(D29<=$T$20,$Y$20,IF(D29<=$T$21,$Y$21,IF(D29<=$T$22,$Y$22,IF(D29<=$T$23,$Y$23,IF(D29<=$T$24,$Y$24,IF(D29<=$T$25,$Y$25,IF(D29<=$T$26,$Y$26,IF(D29<=$T$27,$Y$27,IF(D29<=$T$28,$Y$28,IF(D29<=$T$29,$Y$29,0))))))))))))) | E30: =+IF(E29<=$T$17,$Y$17,IF(E29<=$T$18,$Y$18,IF(E29<=$T$19,$Y$19,IF(E29<=$T$20,$Y$20,IF(E29<=$T$21,$Y$21,IF(E29<=$T$22,$Y$22,IF(E29<=$T$23,$Y$23,IF(E29<=$T$24,$Y$24,IF(E29<=$T$25,$Y$25,IF(E29<=$T$26,$Y$26,IF(E29<=$T$27,$Y$27,IF(E29<=$T$28,$Y$28,IF(E29<=$T$29,$Y$29,0)))))))))))))
A35: 階層別 | C35: 母数 | D35: 誘導率 | E35: 想定CVR | F35: 想定CVR

Sheet SIM3_LINE登録2%
A2: Ver. | B2: 46269
A4: 株式会社チェングロウス御中_LINEOA施策提案【SIM】（通知メッセージ無・LINEで登録2.0%）
N5: ※これより→はPDFにするときに消すようにする（範囲外に）
A7: ■要件定義 | B7: 地点 | C7: 名称 | D7: 成果単価
A8: 新規CV | B8: ①_CV地点 | C8: 求人応募（LINE経由） | D8: 0 | G8: UU | H8: 6100 | J8: 想定顧客リスト | K8: 0 | N8: SimilarWeb等を参考に | O8: ※メルマガ、他SNS等でのリリースが出来るか
B9: ②_CV地点 | C9: 求人応募（リッチメニュー経由） | D9: 0 | G9: 広告・アフィUU | H9: 5000 | N9: 広告比率等を参考に | O9: LINEプレスリリースの可否 | P9: FALSE
A10: リピートCV | B10: ③_CV地点 | C10: - | D10: 0 | G10: サイト応募（広告経由） | H10: 45 | N10: CV聞けてれば→通知メッセ、サンクスLINE誘導
B11: ④_CV地点 | C11: - | D11: 0 | G11: CV（別施策）2 | H11: 0
O12: ↓調整可能です！
A13: 項目 | D13: ※↓現状数値 | E13: 1か月目（4月） | F13: 2か月目（5月） | G13: 3か月目（6月） | H13: 4か月目（7月） | I13: 5か月目（8月） | J13: 6か月目（9月） | K13: 半年合計 | L13: 単月平均（６ヶ月） | N13: 20%くらいの調整は可能です。 | O13: →DYM作業用
A14: WEBサイト | B14: UU全体 | D14: =+H8 | E14: 6207 | F14: 6112 | G14: 6066 | H14: 6179 | I14: 6005 | J14: 6243
B15: UU(うち広告) | D15: =+H9 | E15: 5088 | F15: 5010 | G15: 4972 | H15: 5065 | I15: 4922 | J15: 5118 | N15: （サイト固定リンク） | O15: AD以外のLINE誘導 | P15: 0.005 | S15: ■従量計算式↓
B16: CV（別施策） ※想定 | D16: =H10 | E16: 40 | F16: 41 | G16: 43 | H16: 45 | I16: 44 | J16: 47 | N16: （サイト固定リンク） | O16: ADでのLP/HP→LINE | P16: 0.0025 | S16: ■料金テーブル
A17: 施策 | B17: CPF | D17: FALSE | E17: FALSE | F17: FALSE | G17: FALSE | H17: FALSE | I17: FALSE | J17: FALSE | K17: -- | L17: -- | S17: 課金対象配信総数 | W17: 費用 | Z17: 単価
B18: 離脱防止 | D18: FALSE | E18: TRUE | F18: TRUE | G18: TRUE | H18: TRUE | I18: TRUE | J18: TRUE | K18: -- | L18: -- | N18: KaiU表示率 | O18: 離脱防止表示率（AD） | P18: 0.65 | S18: 0 | T18: - | U18: 200000 | W18: 0 | X18: - | Y18: 600000 | Z18: 3
B19: サンクスLINE誘導 | D19: FALSE | E19: TRUE | F19: TRUE | G19: TRUE | H19: TRUE | I19: TRUE | J19: TRUE | N19: KaiU表示率 | O19: 離脱防止表示率（SEO） | P19: 0.55 | S19: 200000 | T19: - | U19: 15000000 | W19: 600000 | X19: - | Y19: =+U19*2.5 | Z19: 2.5
B20: 通知メッセージ_CV | D20: FALSE | E20: FALSE | F20: FALSE | G20: FALSE | H20: FALSE | I20: FALSE | J20: FALSE
B21: 通知メッセージ_既存リスト | D21: FALSE | E21: FALSE | F21: FALSE | G21: FALSE | H21: FALSE | I21: FALSE | J21: FALSE | K21: -- | L21: -- | O21: ↓企画投稿
A22: 施策増分 ※友だち | B22: CPF | D22: -- | E22: =IF(E17=FALSE,0,IF(E65=0,0,IFERROR(E65/P30,"D63を記入してください"))) | F22: =E22*1.01 | G22: =F22*1.01 | H22: =G22*1.01 | I22: =H22*1.01 | J22: =I22*1.01 | N22: CPFコスト / CPFの単価設定 ※ブロック率が上がりやすい | O22: 開封率 | P22: 0.78
B23: 離脱防止 | D23: -- | E23: =IF(E18=FALSE,0,E14*0.4*0.125*0.125*0.62) | F23: =IF(F18=FALSE,0,F14*0.4*0.125*0.125*0.81) | G23: =IF(G18=FALSE,0,G14*0.4*0.125*0.125*0.93) | H23: =IF(H18=FALSE,0,H14*0.4*0.125*0.125*1.0) | I23: =IF(I18=FALSE,0,I14*0.4*0.125*0.125*1.03) | J23: =IF(J18=FALSE,0,J14*0.4*0.125*0.125*1.05) | N23: 離脱防止：UU×表示40%×クリック12.5%×追加12.5%×立ち上げ係数 | O23: クリック率 | P23: 0.1 | Q23: 4‐6か月後係数
B24: サンクスLINE誘導 | D24: -- | E24: =IF(E19=FALSE,0,E16*0.8*0.45*0.62) | F24: =IF(F19=FALSE,0,F16*0.8*0.45*0.81) | G24: =IF(G19=FALSE,0,G16*0.8*0.45*0.93) | H24: =IF(H19=FALSE,0,H16*0.8*0.45*1.0) | I24: =IF(I19=FALSE,0,I16*0.8*0.45*1.03) | J24: =IF(J19=FALSE,0,J16*0.8*0.45*1.05) | N24: 完了画面：サイト応募×遷移80%×追加45%×立ち上げ係数 | O24: audienceターゲ率 | P24: 0.8 | Q24: 0.8
B25: 通知メッセージ | D25: -- | E25: =IF(E20=FALSE,0,E16*(1-0.8*0.45*0.62)*0.7*0.3) | F25: =IF(F20=FALSE,0,F16*(1-0.8*0.45*0.81)*0.7*0.3) | G25: =IF(G20=FALSE,0,G16*(1-0.8*0.45*0.93)*0.7*0.3) | H25: =IF(H20=FALSE,0,H16*(1-0.8*0.45*1.0)*0.7*0.3) | I25: =IF(I20=FALSE,0,I16*(1-0.8*0.45*1.03)*0.7*0.3) | J25: =IF(J20=FALSE,0,J16*(1-0.8*0.45*1.05)*0.7*0.3) | N25: 通知メッセ：完了画面で追加しなかった応募者×情報一致70%×追加30% | O25: ↓ステップ配信
A26: 友だち数_増加数 | D26: -- | E26: =SUM(E22:E25)+E14*0.02*0.62 | F26: =SUM(F22:F25)+F14*0.02*0.81 | G26: =SUM(G22:G25)+G14*0.02*0.93 | H26: =SUM(H22:H25)+H14*0.02*1.0 | I26: =SUM(I22:I25)+I14*0.02*1.03 | J26: =SUM(J22:J25)+J14*0.02*1.05 | N26: ＋サイト内「LINEで登録」：UU×2.0%×立ち上げ係数（Profile+で入力ほぼゼロになる前提） | O26: 開封率 | P26: 0.725
A27: ブロック率 | D27: 0 | E27: 0.406 | F27: 0.391 | G27: 0.378 | H27: 0.362 | I27: 0.359 | J27: 0.344 | N27: ブロック率：40%前後から出し分け配信で徐々に低下（目標30%以内） | O27: クリック率 | P27: 0.12 | Q27: 4‐6か月後係数
A28: 友だち数 | D28: 0 | E28: =+D28+E26 | F28: =+E28+F26 | G28: =+F28+G26 | H28: =+G28+H26 | I28: =+H28+I26 | J28: =+I28+J26 | O28: audienceターゲ率 | P28: 0.2 | Q28: 0.8
A29: ターゲット数 | D29: 0 | E29: =+E28*(1-E27) | F29: =+F28*(1-F27) | G29: =+G28*(1-G27) | H29: =+H28*(1-H27) | I29: =+I28*(1-I27) | J29: =+J28*(1-J27) | N29: ※ターゲット数の増加分が通常の増加分を超えないように調整する
A30: 企画投稿数 | D30: 0 | E30: 4 | F30: 4 | G30: 4 | H30: 4 | I30: 4 | J30: 4 | N30: ←基本本数が4本として設計する（ユーザー数と固定費で調整） | O30: CPFの単価設定
A31: 企画投稿からの流入 | D31: =+D30*D29*0.41*0.07 | E31: =+E29*E30*$P$24*$P$22*$P$23*$P$36 | F31: =+F29*F30*$P$24*$P$22*$P$23*$P$36 | G31: =+G29*G30*$P$24*$P$22*$P$23*$P$36 | H31: =+H29*H30*$P$24*$P$22*$P$23*$P$36*$Q$24 | I31: =+I29*I30*$P$24*$P$22*$P$23*$P$36*$Q$24 | J31: =+J29*J30*$P$24*$P$22*$P$23*$P$36*$Q$24
A32: ステップ配信本数 | D32: 0 | E32: 10 | F32: 10 | G32: 10 | H32: 10 | I32: 10 | J32: 10 | N32: ←基本本数が4本として設計する | O32: 特典の強さ | P32: TRUE | Q32: =+IF(P32=TRUE,1.1,0.95)
A33: ステップ配信からの流入 | D33: 0 | E33: =+E29*E32*$P$26*$P$27*$P$28*$P$36 | F33: =+F29*F32*$P$26*$P$27*$P$28*$P$36 | G33: =+G29*G32*$P$26*$P$27*$P$28*$P$36 | H33: =+H29*H32*$P$26*$P$27*$P$28*$P$36*$Q$28 | I33: =+I29*I32*$P$26*$P$27*$P$28*$P$36*$Q$28 | J33: =+J29*J32*$P$26*$P$27*$P$28*$P$36*$Q$28 | O33: クリエイティブ強さ | P33: TRUE | Q33: =+IF(P33=TRUE,1.1,0.95)
A34: 配信数 | D34: =+D29*D30 | E34: =+E29*E30*$P$24+E29*E32*$P$28 | F34: =+F29*F30*$P$24+F29*F32*$P$28 | G34: =+G29*G30*$P$24+G29*G32*$P$28 | H34: =+H29*H30*$P$24*$Q$24+H29*H32*$P$28*$Q$28 | I34: =+I29*I30*$P$24*$Q$24+I29*I32*$P$28*$Q$28 | J34: =+J29*J30*$P$24*$Q$24+J29*J32*$P$28*$Q$28 | O34: 知名度強さ | P34: TRUE | Q34: =+IF(P34=TRUE,1.1,0.95)
A35: 想定Click数 | D35: =+D31*1.02 | E35: =+E31+E33+1.05*(E31+E33)+E29*0.3*2 | F35: =+F31+F33+1.05*(F31+F33)+F29*0.3*2 | G35: =+G31+G33+1.05*(G31+G33)+G29*0.3*2 | H35: =+H31+H33+1.05*(H31+H33)+H29*0.3*2 | I35: =+I31+I33+1.05*(I31+I33)+I29*0.3*2 | J35: =+J31+J33+1.05*(J31+J33)+J29*0.3*2 | N35: ＋リッチメニューのタップ：有効な友だち×月に使う率30%×2回 | O35: 動線の強さ | P35: TRUE | Q35: =+IF(P35=TRUE,1.1,0.95)
A36: 新規CV | B36: =+C8 | D36: 0 | E36: 1 | F36: 2 | G36: 3 | H36: 4 | I36: 5 | J36: 6 | K36: =SUM(E36:J36) | N36: 新規向け_ | O36: 想定の係数（反応率） | P36: =1*(Q32*Q33*Q34*Q35)
B37: =+C9 | D37: 0 | E37: =ROUND(E29*0.3*2*0.015,0) | F37: =ROUND(F29*0.3*2*0.015,0) | G37: =ROUND(G29*0.3*2*0.015,0) | H37: =ROUND(H29*0.3*2*0.015,0) | I37: =ROUND(I29*0.3*2*0.015,0) | J37: =ROUND(J29*0.3*2*0.015,0) | K37: =SUM(E37:J37) | N37: リッチメニュー経由の応募：有効な友だち×月に使う率30%×2回検索×応募率1.5%
A38: リピートCV | B38: =+C10 | D38: 0 | E38: 0 | F38: 0 | G38: 0 | H38: 0 | I38: 0 | J38: 0 | K38: =SUM(E38:J38) | N38: 既存向け_休眠顧客向け | O38: ※①＞②で作成
B39: =+C11 | D39: 0 | E39: 0 | F39: 0 | G39: 0 | H39: 0 | I39: 0 | J39: 0 | K39: =SUM(E39:J39) | N39: 既存向け_休眠顧客向け | O39: ※③＞④で作成
A40: 合計CV | D40: =+SUM(D36:D39) | E40: =+SUM(E36:E39) | F40: =+SUM(F36:F39) | G40: =+SUM(G36:G39) | H40: =+SUM(H36:H39) | I40: =+SUM(I36:I39) | J40: =+SUM(J36:J39) | K40: =SUM(E40:J40)
B41: CVR | D41: =+IFERROR(D40/D35,0) | E41: =+IFERROR(E40/E35,0) | F41: =+IFERROR(F40/F35,0) | G41: =+IFERROR(G40/G35,0) | H41: =+IFERROR(H40/H35,0) | I41: =+IFERROR(I40/I35,0) | J41: =+IFERROR(J40/J35,0) | N41: CV/流入数で計算、0.3%〜1%とかで推移。
A43: ■成果報酬運営 | C43: 現状数値 | D43: 初期
A44: 従量課金 | D44: -- | E44: =+E75*E76 | F44: =+F75*F76 | G44: =+G75*G76 | H44: =+H75*H76 | I44: =+I75*I76 | J44: =+J75*J76
...

Sheet SIM3_比較
E1: →通数減らすように係数： | F1: 0.6
A3: 比較項目 | C3: DYM実装前 | D3: DYM実装後（③か月） | E3: DYM実装後（⑥か月）
A4: コスト想定 ※月額（成果報酬プラン） | C4: =+'SIM3_LINE登録2%'!D24 | D4: =+'SIM3_LINE登録2%'!G51 | E4: =+'SIM3_LINE登録2%'!J51
A5: コスト想定 ※月額（固定プラン） | C5: =+'SIM3_LINE登録2%'!D25 | D5: =+'SIM3_LINE登録2%'!G61 | E5: =+'SIM3_LINE登録2%'!J61
A6: 友だち数想定 | C6: =+'SIM3_LINE登録2%'!D28 | D6: =+'SIM3_LINE登録2%'!G28 | E6: =+'SIM3_LINE登録2%'!J28
A7: ブロック率想定 | C7: =+'SIM3_LINE登録2%'!D27 | D7: ='SIM3_LINE登録2%'!G27 | E7: ='SIM3_LINE登録2%'!J27
A8: 友だち数（アクティブ）想定 | C8: =+'SIM3_LINE登録2%'!D29 | D8: =+'SIM3_LINE登録2%'!G29 | E8: =+'SIM3_LINE登録2%'!J29
A10: メッセ通数 | C10: =+'SIM3_LINE登録2%'!D34 | D10: =+'SIM3_LINE登録2%'!G34 | E10: =+'SIM3_LINE登録2%'!J34
A11: サイト流入数（LINEから） | C11: =+'SIM3_LINE登録2%'!D35 | D11: =+'SIM3_LINE登録2%'!G35 | E11: =+'SIM3_LINE登録2%'!J35
A12: 想定CPC（LINEOA施策）_成果報酬プラン | C12: =+IFERROR(C5/C11,0) | D12: =+D4/D11 | E12: =+E4/E11
A13: 想定CPC（LINEOA施策）_固定運用プラン | C13: =+IFERROR(C6/C12,0) | D13: =+D5/D11 | E13: =+E5/E11
R14: ■従量計算式↓
A15: CV数（もともと） | C15: =+'SIM3_LINE登録2%'!D16 | D15: =+'SIM3_LINE登録2%'!E16 | E15: =+'SIM3_LINE登録2%'!F16 | R15: ■料金テーブル
A16: CV数（+LINEOA施策） | C16: =SUM(C17:C20) | D16: =SUM(D17:D20) | E16: =SUM(E17:E20) | R16: 課金対象配信総数 | V16: 費用 | Y16: 単価
A17: OA施策CV_内訳①_新規CV1 | C17: =+'SIM3_LINE登録2%'!D36 | D17: =+'SIM3_LINE登録2%'!G36 | E17: =+'SIM3_LINE登録2%'!J36 | R17: 0 | S17: - | T17: 200000 | V17: 0 | W17: - | X17: 600000 | Y17: 3
A18: OA施策CV_内訳②_新規CV2 | C18: =+'SIM3_LINE登録2%'!D37 | D18: =+'SIM3_LINE登録2%'!G37 | E18: =+'SIM3_LINE登録2%'!J37 | R18: 200000 | S18: - | T18: 15000000 | V18: 600000 | W18: - | X18: =+T18*2.5 | Y18: 2.5
A19: OA施策CV_内訳③_リピCV3 | C19: =+'SIM3_LINE登録2%'!D38 | D19: =+'SIM3_LINE登録2%'!G38 | E19: =+'SIM3_LINE登録2%'!J38
A20: OA施策CV_内訳④_リピCV4 | C20: =+'SIM3_LINE登録2%'!D39 | D20: =+'SIM3_LINE登録2%'!G39 | E20: =+'SIM3_LINE登録2%'!J39
A22: 成果報酬プラン_CPA（単純計算） | C22: =+IFERROR(C4/C16,"--") | D22: =+IFERROR(D4/D16,"--") | E22: =+IFERROR(E4/E16,"--")
A23: 固定費プラン_CPA（単純計算） | C23: =+IFERROR(C5/C16,"--") | D23: =+IFERROR(D5/D16,"--") | E23: =+IFERROR(E5/E16,"--")
A25: 備考_合計コスト(従量課金) ※アカウント費用 | C25: =15000+C29*C30 | D25: =15000+D29*D30 | E25: =15000+E29*E30
A29: 従量課金対象単価 | C29: =+IF(C10<=30000,0,C10-30000) | D29: =+IF(D10<=30000,0,D10-30000) | E29: =+IF(E10<=30000,0,E10-30000)
A30: 備考単価 | C30: =+IF(C29<=$T$17,$Y$17,IF(C29<=$T$18,$Y$18,IF(C29<=$T$19,$Y$19,IF(C29<=$T$20,$Y$20,IF(C29<=$T$21,$Y$21,IF(C29<=$T$22,$Y$22,IF(C29<=$T$23,$Y$23,IF(C29<=$T$24,$Y$24,IF(C29<=$T$25,$Y$25,IF(C29<=$T$26,$Y$26,IF(C29<=$T$27,$Y$27,IF(C29<=$T$28,$Y$28,IF(C29<=$T$29,$Y$29,0))))))))))))) | D30: =+IF(D29<=$T$17,$Y$17,IF(D29<=$T$18,$Y$18,IF(D29<=$T$19,$Y$19,IF(D29<=$T$20,$Y$20,IF(D29<=$T$21,$Y$21,IF(D29<=$T$22,$Y$22,IF(D29<=$T$23,$Y$23,IF(D29<=$T$24,$Y$24,IF(D29<=$T$25,$Y$25,IF(D29<=$T$26,$Y$26,IF(D29<=$T$27,$Y$27,IF(D29<=$T$28,$Y$28,IF(D29<=$T$29,$Y$29,0))))))))))))) | E30: =+IF(E29<=$T$17,$Y$17,IF(E29<=$T$18,$Y$18,IF(E29<=$T$19,$Y$19,IF(E29<=$T$20,$Y$20,IF(E29<=$T$21,$Y$21,IF(E29<=$T$22,$Y$22,IF(E29<=$T$23,$Y$23,IF(E29<=$T$24,$Y$24,IF(E29<=$T$25,$Y$25,IF(E29<=$T$26,$Y$26,IF(E29<=$T$27,$Y$27,IF(E29<=$T$28,$Y$28,IF(E29<=$T$29,$Y$29,0)))))))))))))
A35: 階層別 | C35: 母数 | D35: 誘導率 | E35: 想定CVR | F35: 想定CVR

Sheet SIM考え方
A2: 友だち数_増加施策
A3: 離脱防止 ※
A4: 掲載率 | B4: ※サイト構成、要望により変動 | E4: 1000
A5: クリック率 | B5: 0.085
A6: 追加率 | B6: 0.08
E7: =+E4*B5*B6
A8: サイト→LINEの導線の改善 ※
A9: 掲載率 | B9: ※サイト構成、要望により変動 | E9: 1000
A10: クリック率 | B10: 0.005
A11: 追加率 | B11: 0.08
E12: =+E9*B10*B11
A13: サンクスページ誘導 ※ | D13: ただCVが増えるわけではない
A14: 掲載数 | B14: ※サイト構成、要望により変動 | E14: 1000
A15: クリック率 | B15: 0.9 | C15: ※カウントしない
A16: 追加率 | B16: 0.35
E17: =+E14*B15*B16
A18: 通知メッセの改善 ※ | D18: ただCVが増えるわけではない
A19: 掲載率 | B19: 0.7 | C19: ※サイト構成、要望により変動 | E19: 1000
A20: クリック率 | B20: 1
A21: 追加率 | B21: 0.2
E22: =+E19*B20*B21
A23: 配信効率改善施策 | C23: ※具体的なセグメントの仕方、企画により変動 | I23: 課金
A24: > 通常メッセ | I24: 1 | J24: 企画投稿（セグメントor一斉配信）
A25: 開封率 | B25: 0.8 | I25: 2 | J25: 追いメッセージ（ステップ、シナリオ）
A26: クリック率 | B26: 0.06 | I26: 3 | J26: VOOM投稿 ※同時進行の場合が多い
A27: CV率 | B27: 0.003 | I27: 4 | J27: 通知メッセージ（1通7円くらいの想定） ※機能導入が必要 ※ツール費：月8万～
A29: > 追いメッセ（ステップ、シナリオ） | I29: 非課金
A30: 開封率 | B30: 0.75 | I30: 1 | J30: 自動の即時応答
A31: クリック率 | B31: 0.08 | I31: 2 | J31: 個別チャット対応
A32: CV率 | B32: 0.006 | I32: 3 | J32: あいさつメッセージ
I33: 4 | J33: （リッチメニュー）
A34: > その他（リッチメニュー）
A35: 開封率 | B35: --
A36: クリック率 | B36: 0.02
A37: CV率 | B37: 0.004
A39: >挨拶メッセ | E39: >挨拶メッセ（アンケート回答率）
A40: 開封率 | B40: 1 | E40: 開封率 | F40: --
A41: クリック率 | B41: 0.035 | E41: 回答率 | F41: 0.25
A42: CV率 | B42: 0.006
