Workbook

Sheet SIM_離脱防止＋サンクスLINE
A2: Ver. | B2: 46311
A4: タナカホーム株式会社御中_LINEOA施策提案【SIM】（離脱防止＋サイトのボタン＋サンクスLINE）
N5: ※これより→はPDFにするときに消すようにする（範囲外に）
A7: ■要件定義 | B7: 地点 | C7: 名称 | D7: 成果単価
A8: 新規CV | B8: ①_CV地点 | C8: 来場予約（LINE経由） | D8: 0 | G8: UU | H8: 13228 | J8: 想定顧客リスト | K8: 0 | N8: サイトUU 13,228／友だち417人（2026-10-15〜16 殿村さん）。CVは来場予約（資料の軸＝資料請求の時点から来場・契約まで追う） | O8: ※メルマガ、他SNS等でのリリースが出来るか
B9: ②_CV地点 | C9: 資料請求（LINE経由・参考） | D9: 0 | G9: 広告・アフィUU | H9: 0 | N9: 資料請求（LINE経由）は参考。合計CV・CVR・CPAには入れない | O9: LINEプレスリリースの可否 | P9: FALSE
A10: リピートCV | B10: ③_CV地点 | C10: - | D10: 0 | G10: 来場予約（月） | H10: 35 | I10: リード（イメージ） | N10: 来場予約 月35件（議事録の現状35〜40件の下限）・資料請求 月8件（自社サイトは月一桁・仮に8件）＝サンクスLINEの母数
B11: ④_CV地点 | C11: - | D11: 0 | G11: 資料請求（月） | H11: 8 | I11: マネタイズ（イメージ）
O12: ↓調整可能です！
A13: 項目 | D13: ※↓現状数値 | E13: 1か月目 | F13: 2か月目 | G13: 3か月目 | H13: 4か月目 | I13: 5か月目 | J13: 6か月目 | K13: 半年合計 | L13: 単月平均（６ヶ月） | N13: 20%くらいの調整は可能です。 | O13: →DYM作業用
A14: WEBサイト | B14: UU全体 | D14: =+H8 -> 13228 | E14: =+D14 -> 13228 | F14: =+E14 -> 13228 | G14: =+F14 -> 13228 | H14: =+G14 -> 13228 | I14: =+H14 -> 13228 | J14: =+I14 -> 13228
B15: UU(うち広告) | D15: =+H9 -> 0 | E15: =+D15 -> 0 | F15: =+E15 -> 0 | G15: =+F15 -> 0 | H15: =+G15 -> 0 | I15: =+H15 -> 0 | J15: =+I15 -> 0 | N15: （サイト固定リンク） | O15: AD以外のLINE誘導 | P15: 0.005 | S15: ■従量計算式↓
B16: CV（別施策） ※想定 | D16: =H10 -> 35 | E16: =+D16 -> 35 | F16: =+E16 -> 35 | G16: =+F16 -> 35 | H16: =+G16 -> 35 | I16: =+H16 -> 35 | J16: =+I16 -> 35 | N16: （サイト固定リンク） | O16: ADでのLP/HP→LINE | P16: 0.0025 | S16: ■料金テーブル
A17: 施策 | B17: CPF | D17: FALSE | E17: FALSE | F17: FALSE | G17: FALSE | H17: FALSE | I17: FALSE | J17: FALSE | K17: -- | L17: -- | S17: 課金対象配信総数 | W17: 費用 | Z17: 単価
B18: 離脱防止 | D18: FALSE | E18: TRUE | F18: TRUE | G18: TRUE | H18: TRUE | I18: TRUE | J18: TRUE | K18: -- | L18: -- | N18: KaiU表示率 | O18: 離脱防止表示率（AD） | P18: 0.65 | S18: 0 | T18: - | U18: 200000 | W18: 0 | X18: - | Y18: 600000 | Z18: 3
B19: サンクスLINE誘導 | D19: FALSE | E19: TRUE | F19: TRUE | G19: TRUE | H19: TRUE | I19: TRUE | J19: TRUE | N19: KaiU表示率 | O19: 離脱防止表示率（SEO） | P19: 0.55 | S19: 200000 | T19: - | U19: 15000000 | W19: 600000 | X19: - | Y19: =+U19*2.5 -> 37500000 | Z19: 2.5
B20: 通知メッセージ_CV | D20: FALSE | E20: FALSE | F20: FALSE | G20: FALSE | H20: FALSE | I20: FALSE | J20: FALSE
B21: 通知メッセージ_既存リスト | D21: FALSE | E21: FALSE | F21: FALSE | G21: FALSE | H21: FALSE | I21: FALSE | J21: FALSE | K21: -- | L21: -- | O21: ↓企画投稿
A22: 施策増分 ※友だち | B22: CPF | D22: -- | E22: 0 | F22: 0 | G22: 0 | H22: 0 | I22: 0 | J22: 0 | N22: 友だち追加広告（CPF）は入れていない。友だちを月500人規模にするなら、LINE広告で月300人強（1人200円で月6〜7万円）が別に要る | O22: 開封率 | P22: 0.78
B23: 離脱防止 | D23: -- | E23: =IF(E18=FALSE,0,E15*$P$18*0.08*0.08+(E14-E15)*$P$19*0.12*0.12) -> 104.76576 | F23: =IF(F18=FALSE,0,F15*$P$18*0.08*0.08+(F14-F15)*$P$19*0.12*0.12) -> 104.76576 | G23: =F23*1.01 -> 105.81342 | H23: =G23*1.01 -> 106.87155 | I23: =H23*1.01 -> 107.94027 | J23: =I23*1.01 -> 109.01967 | N23: 離脱防止＝UU×表示55%×クリック12%×追加12%（FMTの式）＝月約105人。今の来場特典のポップアップに加えて、来場前の方向けに情報で追加してもらう案内に作り直す想定 | O23: クリック率 | P23: 0.1 | Q23: 4‐6か月後係数
B24: サンクスLINE誘導 | D24: -- | E24: =+IF(E19=FALSE,0,SUM(H10:H11)*0.15) -> 6.45 | F24: =E24*1.01 -> 6.5145 | G24: =F24*1.01 -> 6.579645 | H24: =G24*1.01 -> 6.6454414 | I24: =H24*1.01 -> 6.7118959 | J24: =I24*1.01 -> 6.7790148 | N24: サンクスLINE誘導＝（来場予約＋資料請求）×15%（FMTの式）＝月約6人。資料請求・来場予約の完了ページからLINEへ | O24: audienceターゲ率 | P24: 0.8 | Q24: 0.8
B25: 通知メッセージ | D25: -- | E25: =+IF(E20=FALSE,0,SUM($H$10:$H$11)*0.7*0.3)+IF($E$21=FALSE,0,$K$8*0.15*0.15) -> 0 | F25: =+IF(F20=FALSE,0,SUM($H$10:$H$11)*0.7*0.3)+IF($E$21=FALSE,0,$K$8*0.15*0.15) -> 0 | G25: =+IF(G20=FALSE,0,SUM($H$10:$H$11)*0.7*0.3)+IF($E$21=FALSE,0,$K$8*0.15*0.15) -> 0 | H25: =+IF(H20=FALSE,0,SUM($H$10:$H$11)*0.7*0.3)+IF($E$21=FALSE,0,$K$8*0.15*0.15) -> 0 | I25: =+IF(I20=FALSE,0,SUM($H$10:$H$11)*0.7*0.3)+IF($E$21=FALSE,0,$K$8*0.15*0.15) -> 0 | J25: =+IF(J20=FALSE,0,SUM($H$10:$H$11)*0.7*0.3)+IF($E$21=FALSE,0,$K$8*0.15*0.15) -> 0 | N25: サンクス到達*情報一致率(70%前後)*実追加率 | O25: ↓ステップ配信
A26: 友だち数_増加数 | D26: -- | E26: =+SUM(E22:E25)+$H$9*$P$16+($H$8-$H$9)*$P$15+IF(P9=FALSE,0,$K$8*0.15*0.08) -> 177.35576 | F26: =+SUM(F22:F25)+$H$9*$P$16+($H$8-$H$9)*$P$15 -> 177.42026 | G26: =+SUM(G22:G25)+$H$9*$P$16+($H$8-$H$9)*$P$15 -> 178.53306 | H26: =+SUM(H22:H25)+$H$9*$P$16+($H$8-$H$9)*$P$15 -> 179.65699 | I26: =+SUM(I22:I25)+$H$9*$P$16+($H$8-$H$9)*$P$15 -> 180.79216 | J26: =+SUM(J22:J25)+$H$9*$P$16+($H$8-$H$9)*$P$15 -> 181.93868 | N26: サイトのLINEボタン＝UU×0.5%（FMTのP15）＝月約66人。今はサイトにLINEの導線が無いので新しく置く | O26: 開封率 | P26: 0.725
A27: ブロック率 | D27: 0.28 | E27: 0.28 | F27: =ROUND(E27*1.02,3) -> 0.286 | G27: =ROUND(F27*1.02,3) -> 0.292 | H27: =ROUND(G27*1.02,3) -> 0.298 | I27: =ROUND(H27*1.02,3) -> 0.304 | J27: =ROUND(I27*1.02,3) -> 0.31 | N27: ブロック率：28%（殿村さんの表）から前月の1.02倍ずつ上昇 | O27: クリック率 | P27: 0.12 | Q27: 4‐6か月後係数
A28: 友だち数 | D28: 417 | E28: =+D28+E26 -> 594.35576 | F28: =+E28+F26 -> 771.77602 | G28: =+F28+G26 -> 950.30908 | H28: =+G28+H26 -> 1129.9661 | I28: =+H28+I26 -> 1310.7582 | J28: =+I28+J26 -> 1492.6969 | O28: audienceターゲ率 | P28: 0.2 | Q28: 0.8
A29: ターゲット数 | D29: =+D28*(1-D27) -> 300.24 | E29: =+E28*(1-E27) -> 427.93615 | F29: =+F28*(1-F27) -> 551.04808 | G29: =+G28*(1-G27) -> 672.81883 | H29: =+H28*(1-H27) -> 793.23619 | I29: =+I28*(1-I27) -> 912.28773 | J29: =+J28*(1-J27) -> 1029.9609 | N29: ※ターゲット数の増加分が通常の増加分を超えないように調整する
A30: 企画投稿数 | D30: 0 | E30: 4 | F30: 4 | G30: 4 | H30: 4 | I30: 4 | J30: 4 | N30: 企画配信 月4本（有効な友だち×80%。4か月目からは反応しない方を外してさらに8割） | O30: CPFの単価設定
A31: 企画投稿からの流入 | D31: =+D30*D29*0.41*0.07 -> 0 | E31: =+E29*E30*$P$24*$P$22*$P$23*$P$36 -> 156.38471 | F31: =+F29*F30*$P$24*$P$22*$P$23*$P$36 -> 201.37466 | G31: =+G29*G30*$P$24*$P$22*$P$23*$P$36 -> 245.87448 | H31: =+H29*H30*$P$24*$P$22*$P$23*$P$36*$Q$24 -> 231.90378 | I31: =+I29*I30*$P$24*$P$22*$P$23*$P$36*$Q$24 -> 266.70868 | J31: =+J29*J30*$P$24*$P$22*$P$23*$P$36*$Q$24 -> 301.1106
A32: ステップ配信本数 | D32: 0 | E32: 5 | F32: 5 | G32: 5 | H32: 5 | I32: 5 | J32: 5 | N32: ステップ配信5通（会社の特長→費用・住宅ローン→断熱性能・間取り→ルームツアー→見学会・来場予約）。対象＝その月の新しい友だち | O32: 特典の強さ | P32: TRUE | Q32: =+IF(P32=TRUE,1.1,0.95) -> 1.1
A33: ステップ配信からの流入 | D33: 0 | E33: =+E26*E32*$P$26*$P$27*$P$36 -> 112.95496 | F33: =+F26*F32*$P$26*$P$27*$P$36 -> 112.99604 | G33: =+G26*G32*$P$26*$P$27*$P$36 -> 113.70476 | H33: =+H26*H32*$P$26*$P$27*$P$36 -> 114.42057 | I33: =+I26*I32*$P$26*$P$27*$P$36 -> 115.14355 | J33: =+J26*J32*$P$26*$P$27*$P$36 -> 115.87375 | O33: クリエイティブ強さ | P33: TRUE | Q33: =+IF(P33=TRUE,1.1,0.95) -> 1.1
A34: 配信数 | D34: =+D29*D30 -> 0 | E34: =+E29*E30*$P$24+E26*E32 -> 2256.1745 | F34: =+F29*F30*$P$24+F26*F32 -> 2650.4552 | G34: =+G29*G30*$P$24+G26*G32 -> 3045.6856 | H34: =+H29*H30*$P$24*$Q$24+H26*H32 -> 2928.9696 | I34: =+I29*I30*$P$24*$Q$24+I26*I32 -> 3239.4174 | J34: =+J29*J30*$P$24*$Q$24+J26*J32 -> 3546.3933 | O34: 知名度強さ | P34: TRUE | Q34: =+IF(P34=TRUE,1.1,0.95) -> 1.1
A35: 想定Click数 | D35: =+D31*1.02 -> 0 | E35: =+E31+E33+1.05*(E31+E33) -> 552.14632 | F35: =+F31+F33+1.05*(F31+F33) -> 644.45992 | G35: =+G31+G33+1.05*(G31+G33) -> 737.13745 | H35: =+H31+H33+1.05*(H31+H33) -> 709.96493 | I35: =+I31+I33+1.05*(I31+I33) -> 782.79706 | J35: =+J31+J33+1.05*(J31+J33) -> 854.8179 | O35: 動線の強さ | P35: TRUE | Q35: =+IF(P35=TRUE,1.1,0.95) -> 1.1
A36: 新規CV | B36: =+C8 -> 来場予約（LINE経由） | D36: 0 | E36: 5 | F36: 7 | G36: 10 | H36: 11 | I36: 14 | J36: 16 | K36: =SUM(E36:J36) -> 63 | N36: 来場予約＝クリック×0.4〜0.8%（運用が育つ想定で月ごとに上げる） | O36: 想定の係数（反応率） | P36: =1*(Q32*Q33*Q34*Q35) -> 1.4641
B37: =+C9 -> 資料請求（LINE経由・参考） | D37: 0 | E37: 2 | F37: 4 | G37: 5 | H37: 6 | I37: =ROUND(I35*0.01,0) -> 8 | J37: 9 | K37: =SUM(E37:J37) -> 34 | N37: 資料請求＝クリック×0.6〜1.0%（参考）
A38: リピートCV | B38: =+C10 -> - | D38: 0 | E38: 0 | F38: 0 | G38: 0 | H38: 0 | I38: 0 | J38: 0 | K38: =SUM(E38:J38) -> 0 | N38: 既存向け_休眠顧客向け | O38: ※①＞②で作成
B39: =+C11 -> - | D39: 0 | E39: 0 | F39: 0 | G39: 0 | H39: 0 | I39: 0 | J39: 0 | K39: =SUM(E39:J39) -> 0 | N39: 既存向け_休眠顧客向け | O39: ※③＞④で作成
A40: 合計CV | D40: =SUM(D36:D39) -> 0 | E40: =SUM(E36:E39) -> 7 | F40: =SUM(F36:F39) -> 11 | G40: =SUM(G36:G39) -> 15 | H40: =SUM(H36:H39) -> 17 | I40: =SUM(I36:I39) -> 22 | J40: =SUM(J36:J39) -> 25 | K40: =SUM(E40:J40) -> 97
B41: CVR | D41: =+IFERROR(D40/D35,0) -> 0 | E41: =IFERROR(E40/E35,0) -> 0.012677799 | F41: =IFERROR(F40/F35,0) -> 0.017068556 | G41: =IFERROR(G40/G35,0) -> 0.020348986 | H41: =IFERROR(H40/H35,0) -> 0.023944845 | I41: =IFERROR(I40/I35,0) -> 0.028104347 | J41: =IFERROR(J40/J35,0) -> 0.029245995 | N41: CV/流入数で計算、0.3%〜1%とかで推移。
A43: ■成果報酬運営 | C43: 現状数値 | D43: 初期
A44: 従量課金 | D44: -- | E44: =+E75*E76 -> 0 | F44: =+F75*F76 -> 0 | G44: =+G75*G76 -> 0 | H44: =+H75*H76 -> 0 | I44: =+I75*I76 -> 0 | J44: =+J75*J76 -> 0
...

Sheet SIM_比較
E1: →通数減らすように係数： | F1: 0.6
A3: 比較項目 | C3: DYM実装前 | D3: DYM実装後（③か月） | E3: DYM実装後（⑥か月）
A4: コスト想定 ※月額（成果報酬プラン） | C4: =+'SIM_離脱防止＋サンクスLINE'!D24 -> -- | D4: =+'SIM_離脱防止＋サンクスLINE'!G51 -> 265000 | E4: =+'SIM_離脱防止＋サンクスLINE'!J51 -> 265000
A5: コスト想定 ※月額（固定プラン） | C5: =+'SIM_離脱防止＋サンクスLINE'!D25 -> -- | D5: =+'SIM_離脱防止＋サンクスLINE'!G61 -> 265000 | E5: =+'SIM_離脱防止＋サンクスLINE'!J61 -> 265000
A6: 友だち数想定 | C6: =+'SIM_離脱防止＋サンクスLINE'!D28 -> 417 | D6: =+'SIM_離脱防止＋サンクスLINE'!G28 -> 950.30908 | E6: =+'SIM_離脱防止＋サンクスLINE'!J28 -> 1492.6969
A7: ブロック率想定 | C7: =+'SIM_離脱防止＋サンクスLINE'!D27 -> 0.28 | D7: =+'SIM_離脱防止＋サンクスLINE'!G27 -> 0.292 | E7: =+'SIM_離脱防止＋サンクスLINE'!J27 -> 0.31
A8: 友だち数（アクティブ）想定 | C8: =+'SIM_離脱防止＋サンクスLINE'!D29 -> 300.24 | D8: =+'SIM_離脱防止＋サンクスLINE'!G29 -> 672.81883 | E8: =+'SIM_離脱防止＋サンクスLINE'!J29 -> 1029.9609
A10: メッセ通数 | C10: =+'SIM_離脱防止＋サンクスLINE'!D34 -> 0 | D10: =+'SIM_離脱防止＋サンクスLINE'!G34 -> 3045.6856 | E10: =+'SIM_離脱防止＋サンクスLINE'!J34 -> 3546.3933
A11: サイト流入数（LINEから） | C11: =+'SIM_離脱防止＋サンクスLINE'!D35 -> 0 | D11: =+'SIM_離脱防止＋サンクスLINE'!G35 -> 737.13745 | E11: =+'SIM_離脱防止＋サンクスLINE'!J35 -> 854.8179
A12: 想定CPC（LINEOA施策）_成果報酬プラン | C12: =+IFERROR(C5/C11,0) -> 0 | D12: =+D4/D11 -> 359.49876 | E12: =+E4/E11 -> 310.00755
A13: 想定CPC（LINEOA施策）_固定運用プラン | C13: =+IFERROR(C6/C12,0) -> 0 | D13: =+D5/D11 -> 359.49876 | E13: =+E5/E11 -> 310.00755
R14: ■従量計算式↓
A15: 来場予約（もともと・月） | C15: =+'SIM_離脱防止＋サンクスLINE'!D16 -> 35 | D15: =+'SIM_離脱防止＋サンクスLINE'!G16 -> 35 | E15: =+'SIM_離脱防止＋サンクスLINE'!J16 -> 35 | R15: ■料金テーブル
A16: 来場予約（+LINEOA施策） | C16: =+C17 -> 0 | D16: =+D17 -> 10 | E16: =+E17 -> 16 | R16: 課金対象配信総数 | V16: 費用 | Y16: 単価
A17: CV①_来場予約（LINE経由） | C17: =+'SIM_離脱防止＋サンクスLINE'!D36 -> 0 | D17: =+'SIM_離脱防止＋サンクスLINE'!G36 -> 10 | E17: =+'SIM_離脱防止＋サンクスLINE'!J36 -> 16 | R17: 0 | S17: - | T17: 200000 | V17: 0 | W17: - | X17: 600000 | Y17: 3
A18: 参考_資料請求（LINE経由） | C18: =+'SIM_離脱防止＋サンクスLINE'!D37 -> 0 | D18: =+'SIM_離脱防止＋サンクスLINE'!G37 -> 5 | E18: =+'SIM_離脱防止＋サンクスLINE'!J37 -> 9 | R18: 200000 | S18: - | T18: 15000000 | V18: 600000 | W18: - | X18: =+T18*2.5 -> 37500000 | Y18: 2.5
A19: - | C19: =+'SIM_離脱防止＋サンクスLINE'!D38 -> 0 | D19: =+'SIM_離脱防止＋サンクスLINE'!G38 -> 0 | E19: =+'SIM_離脱防止＋サンクスLINE'!J38 -> 0
A20: - | C20: =+'SIM_離脱防止＋サンクスLINE'!D39 -> 0 | D20: =+'SIM_離脱防止＋サンクスLINE'!G39 -> 0 | E20: =+'SIM_離脱防止＋サンクスLINE'!J39 -> 0
A22: 成果報酬プラン_CPA（単純計算） | C22: =+IFERROR(C4/C16,"--") -> -- | D22: =+IFERROR(D4/D16,"--") -> 26500 | E22: =+IFERROR(E4/E16,"--") -> 16562.5
A23: 固定費プラン_CPA（単純計算） | C23: =+IFERROR(C5/C16,"--") -> -- | D23: =+IFERROR(D5/D16,"--") -> 26500 | E23: =+IFERROR(E5/E16,"--") -> 16562.5
A25: 備考_合計コスト(従量課金) ※アカウント費用 | C25: =+'SIM_離脱防止＋サンクスLINE'!E68+C29*C30 -> 5000 | D25: =+'SIM_離脱防止＋サンクスLINE'!G68+D29*D30 -> 5000 | E25: =+'SIM_離脱防止＋サンクスLINE'!J68+E29*E30 -> 5000
A29: 従量課金対象単価 | C29: =+IF(C10<=30000,0,C10-30000) -> 0 | D29: =+IF(D10<=30000,0,D10-30000) -> 0 | E29: =+IF(E10<=30000,0,E10-30000) -> 0
A30: 備考単価 | C30: =+IF(C29<=$T$17,$Y$17,IF(C29<=$T$18,$Y$18,IF(C29<=$T$19,$Y$19,IF(C29<=$T$20,$Y$20,IF(C29<=$T$21,$Y$21,IF(C29<=$T$22,$Y$22,IF(C29<=$T$23,$Y$23,IF(C29<=$T$24,$Y$24,IF(C29<=$T$25,$Y$25,IF(C29<=$T$26,$Y$26,IF(C29<=$T$27,$Y$27,IF(C29<=$T$28,$Y$28,IF(C29<=$T$29,$Y$29,0))))))))))))) -> 3 | D30: =+IF(D29<=$T$17,$Y$17,IF(D29<=$T$18,$Y$18,IF(D29<=$T$19,$Y$19,IF(D29<=$T$20,$Y$20,IF(D29<=$T$21,$Y$21,IF(D29<=$T$22,$Y$22,IF(D29<=$T$23,$Y$23,IF(D29<=$T$24,$Y$24,IF(D29<=$T$25,$Y$25,IF(D29<=$T$26,$Y$26,IF(D29<=$T$27,$Y$27,IF(D29<=$T$28,$Y$28,IF(D29<=$T$29,$Y$29,0))))))))))))) -> 3 | E30: =+IF(E29<=$T$17,$Y$17,IF(E29<=$T$18,$Y$18,IF(E29<=$T$19,$Y$19,IF(E29<=$T$20,$Y$20,IF(E29<=$T$21,$Y$21,IF(E29<=$T$22,$Y$22,IF(E29<=$T$23,$Y$23,IF(E29<=$T$24,$Y$24,IF(E29<=$T$25,$Y$25,IF(E29<=$T$26,$Y$26,IF(E29<=$T$27,$Y$27,IF(E29<=$T$28,$Y$28,IF(E29<=$T$29,$Y$29,0))))))))))))) -> 3
A35: 階層別 | C35: 母数 | D35: 誘導率 | E35: 想定CVR | F35: 想定CVR

Sheet SIM考え方
A2: 友だち数_増加施策
A3: 離脱防止 ※
A4: 掲載率 | B4: ※サイト構成、要望により変動 | E4: 1000
A5: クリック率 | B5: 0.085
A6: 追加率 | B6: 0.08
E7: =+E4*B5*B6 -> 6.8
A8: サイト→LINEの導線の改善 ※
A9: 掲載率 | B9: ※サイト構成、要望により変動 | E9: 1000
A10: クリック率 | B10: 0.005
A11: 追加率 | B11: 0.08
E12: =+E9*B10*B11 -> 0.4
A13: サンクスページ誘導 ※ | D13: ただCVが増えるわけではない
A14: 掲載数 | B14: ※サイト構成、要望により変動 | E14: 1000
A15: クリック率 | B15: 0.9 | C15: ※カウントしない
A16: 追加率 | B16: 0.35
E17: =+E14*B15*B16 -> 315
A18: 通知メッセの改善 ※ | D18: ただCVが増えるわけではない
A19: 掲載率 | B19: 0.7 | C19: ※サイト構成、要望により変動 | E19: 1000
A20: クリック率 | B20: 1
A21: 追加率 | B21: 0.2
E22: =+E19*B20*B21 -> 200
A23: 配信効率改善施策 | C23: ※具体的なセグメントの仕方、企画により変動 | I23: 課金
A24: > 通常メッセ | I24: 1 | J24: 企画投稿（セグメントor一斉配信）
A25: 開封率 | B25: 0.8 | I25: 2 | J25: 追いメッセージ（ステップ、シナリオ）
A26: クリック率 | B26: 0.06 | I26: 3 | J26: VOOM投稿 ※同時進行の場合が多い
A27: CV率 | B27: 0.003 | I27: 4 | J27: 通知メッセージ（1通7円くらいの想定） ※機能導入が必要 ※ツール費：月8万～
A29: > 追いメッセ（ステップ、シナリオ） | I29: 非課金
A30: 開封率 | B30: 0.75 | I30: 1 | J30: 自動の即時応答
A31: クリック率 | B31: 0.08 | I31: 2 | J31: 個別チャット対応
A32: CV率 | B32: 0.006 | I32: 3 | J32: あいさつメッセージ
I33: 4 | J33: （リッチメニュー）
A34: > その他（リッチメニュー）
A35: 開封率 | B35: --
A36: クリック率 | B36: 0.02
A37: CV率 | B37: 0.004
A39: >挨拶メッセ | E39: >挨拶メッセ（アンケート回答率）
A40: 開封率 | B40: 1 | E40: 開封率 | F40: --
A41: クリック率 | B41: 0.035 | E41: 回答率 | F41: 0.25
A42: CV率 | B42: 0.006
