Workbook

Sheet SIM①
A2: 株式会社テン・エンタープライズ御中_LINEOA施策提案【SIM】
A5: ■要件定義 | B5: 地点 | C5: 名称 | D5: 成果単価
A6: 新規CV | B6: ①_CV地点 | C6: セミナー予約 | D6: 20000 | G6: UU | H6: 20000 | J6: 想定顧客リスト | K6: 0
B7: ②_CV地点 | C7: EC購入 | D7: 2000 | G7: 広告・アフィUU | H7: 19000
A8: リピートCV | D8: 0 | G8: CV（別施策）1 | H8: 50 | I8: (広告申し込み_セミナー)
D9: 0 | G9: CV（別施策）2 | H9: 90 | I9: (EC月間購入件数)
E10: [ | O10: ↓調整可能です！
A11: 項目 | D11: ※↓現状数値 | E11: 1か月目(9月) | F11: 2か月目(10月) | G11: 3か月目(11月) | H11: 4か月目(12月) | I11: 5か月目(1月) | J11: 6か月目(2月) | K11: 半年合計 | L11: 単月平均（６ヶ月） | N11: 20%くらいの調整は可能です。 | O11: →DYM作業用
A12: WEBサイト | B12: UU全体 | D12: =+H6 | E12: =+D12 | F12: =+E12 | G12: =+F12 | H12: =+G12 | I12: =+H12 | J12: =+I12 | K12: =SUM(E12:J12) | N12: SimilarWeb等を参考に
B13: UU(うち広告) | D13: =+H7 | E13: =+D13 | F13: =+E13 | G13: =+F13 | H13: =+G13 | I13: =+H13 | J13: =+I13 | K13: =SUM(E13:J13) | N13: 広告比率等を参考に | O13: AD以外のLINE誘導 | P13: 0.00125 | S13: ■従量計算式↓
B14: CV（別施策） ※想定 | D14: =+H8 | E14: =+D14 | F14: =+E14 | G14: =+F14 | H14: =+G14 | I14: =+H14 | J14: =+I14 | K14: =SUM(E14:J14) | N14: CV聞けてれば→通知メッセ、サンクスLINE誘導 | O14: ADでのLP/HP→LINE | P14: 0.00325 | S14: ■料金テーブル
A15: 施策 | B15: CPF | D15: FALSE | E15: FALSE | F15: FALSE | G15: FALSE | H15: FALSE | I15: FALSE | J15: FALSE | K15: =SUM(E15:J15) | L15: -- | P15: o.oo125 | S15: 課金対象配信総数 | W15: 費用 | Z15: 単価
B16: 離脱防止 | D16: FALSE | E16: TRUE | F16: TRUE | G16: TRUE | H16: TRUE | I16: TRUE | J16: TRUE | K16: =SUM(E16:J16) | L16: -- | O16: 離脱防止表示率（AD） | P16: 0.5 | S16: 0 | T16: - | U16: 50000 | W16: 0 | X16: - | Y16: 150000 | Z16: 3
B17: サンクスLINE誘導 | D17: FALSE | E17: TRUE | F17: TRUE | G17: TRUE | H17: TRUE | I17: TRUE | J17: TRUE | K17: =SUM(E17:J17) | O17: 離脱防止表示率（SEO） | P17: 0.3 | S17: 50000 | T17: - | U17: 100000 | W17: 150000 | X17: - | Y17: 290000 | Z17: 2.8
B18: 通知メッセージ_CV | D18: FALSE | E18: FALSE | F18: FALSE | G18: FALSE | H18: FALSE | I18: FALSE | J18: FALSE | K18: =SUM(E18:J18) | S18: 100000 | T18: - | U18: 200000 | W18: 290000 | X18: - | Y18: 550000 | Z18: 2.6
B19: 通知メッセージ_既存リスト | D19: FALSE | E19: FALSE | F19: FALSE | G19: FALSE | H19: FALSE | I19: FALSE | J19: FALSE | K19: =SUM(E19:J19) | L19: -- | O19: ↓企画投稿 | S19: 200000 | T19: - | U19: 300000 | W19: 550000 | X19: - | Y19: 790000 | Z19: 2.4
A20: 施策増分 ※友だち | B20: CPF | D20: -- | E20: =IF(E15=FALSE,0,IF(E63=0,0,IFERROR(E63/P28,"D63を記入してください"))) | F20: =E20*1.01 | G20: =F20*1.01 | H20: =G20*1.01 | I20: =H20*1.01 | J20: =I20*1.01 | K20: =SUM(E20:J20) | N20: CPFコスト / CPFの単価設定 ※ブロック率が上がりやすい | O20: 開封率 | P20: 0.78 | S20: 300000 | T20: - | U20: 400000 | W20: 790000 | X20: - | Y20: 1010000 | Z20: 2.2
B21: 離脱防止 | D21: -- | E21: =IF(E16=FALSE,0,E13*P16*0.08*0.08+(E12-E13)*P17*0.06*0.06) | F21: =IF(F16=FALSE,0,F13*$P$16*0.08*0.08+(F12-F13)*$P$17*0.06*0.06) | G21: =IF(G16=FALSE,0,G13*$P$16*0.08*0.08+(G12-G13)*$P$17*0.06*0.06) | H21: =IF(H16=FALSE,0,H13*$P$16*0.08*0.08+(H12-H13)*$P$17*0.06*0.06) | I21: =IF(I16=FALSE,0,I13*$P$16*0.08*0.08+(I12-I13)*$P$17*0.06*0.06) | J21: =IF(J16=FALSE,0,J13*$P$16*0.08*0.08+(J12-J13)*$P$17*0.06*0.06) | K21: =SUM(E21:J21) | N21: 離脱防止表示率×UU×クリック率×実追加率 | O21: クリック率 | P21: 0.1 | Q21: 4‐6か月後係数 | S21: 400000 | T21: - | U21: 500000 | W21: 1010000 | X21: - | Y21: 1210000 | Z21: 2
B22: サンクスLINE誘導 | D22: -- | E22: =+IF(E17=FALSE,0,SUM(H8:H9)*0.9*0.25) | F22: =E22*1.01 | G22: =F22*1.01 | H22: =G22*1.01 | I22: =H22*1.01 | J22: =I22*1.01 | K22: =SUM(E22:J22) | N22: CV(別施策)*誘導成功率*実追加率 | O22: audienceターゲ率 | P22: 0.8 | Q22: 0.8 | S22: 500000 | T22: - | U22: 600000 | W22: 1210000 | X22: - | Y22: 1400000 | Z22: 1.9
B23: 通知メッセージ | D23: -- | E23: =+IF(E18=FALSE,0,SUM($H$8:$H$9)*0.7*0.3+$K$6*0.1*0.15) | F23: =+IF(F18=FALSE,0,SUM($H$8:$H$9)*0.7*0.3+$K$6*0.1*0.15)*0.8 | G23: =+IF(G18=FALSE,0,SUM($H$8:$H$9)*0.7*0.3+$K$6*0.1*0.15)*0.8 | H23: =+IF(H18=FALSE,0,SUM($H$8:$H$9)*0.7*0.3+$K$6*0.1*0.15)*0.8 | I23: =+IF(I18=FALSE,0,SUM($H$8:$H$9)*0.7*0.3+$K$6*0.1*0.15)*0.8 | J23: =+IF(J18=FALSE,0,SUM($H$8:$H$9)*0.7*0.3+$K$6*0.1*0.15)*0.8 | K23: =SUM(E23:J23) | N23: サンクス到達*情報一致率(70%前後)*実追加率 | O23: ↓ステップ配信 | S23: 600000 | T23: - | U23: 700000 | W23: 1400000 | X23: - | Y23: 1580000 | Z23: 1.8
A24: 友だち数_増加数 | D24: -- | E24: =+SUM(E20:E23)+$H$7*$P$14+($H$6-$H$7)*$P$13 | F24: =+SUM(F20:F23)+$H$7*$P$14+($H$6-$H$7)*$P$13 | G24: =+SUM(G20:G23)+$H$7*$P$14+($H$6-$H$7)*$P$13 | H24: =+SUM(H20:H23)+$H$7*$P$14+($H$6-$H$7)*$P$13 | I24: =+SUM(I20:I23)+$H$7*$P$14+($H$6-$H$7)*$P$13 | J24: =+SUM(J20:J23)+$H$7*$P$14+($H$6-$H$7)*$P$13 | K24: =SUM(E24:J24) | N24: ※上記記載に追加して、LP、HPからのLINE誘導を加味する | O24: 開封率 | P24: 0.725 | S24: 700000 | T24: - | U24: 800000 | W24: 1580000 | X24: - | Y24: 1750000 | Z24: 1.7
A25: ブロック率 | D25: 0.344 | E25: 0.349 | F25: =+E25*1.015 | G25: =+F25*1.015 | H25: =+G25*1.015 | I25: =+H25*1.015 | J25: =+I25*1.015 | K25: =SUM(E25:J25) | O25: クリック率 | P25: 0.12 | Q25: 4‐6か月後係数 | S25: 800000 | T25: - | U25: 900000 | W25: 1750000 | X25: - | Y25: 1910000 | Z25: 1.6
A26: 友だち数 | D26: 12000 | E26: =+D26+E24 | F26: =+E26+F24 | G26: =+F26+G24 | H26: =+G26+H24 | I26: =+H26+I24 | J26: =+I26+J24 | K26: =SUM(E26:J26) | O26: audienceターゲ率 | P26: 0.8 | Q26: 0.8 | S26: 900000 | T26: - | U26: 1000000 | W26: 1910000 | X26: - | Y26: 2060000 | Z26: 1.5
A27: ターゲット数 | D27: 0 | E27: =+E26*(1-E25) | F27: =+F26*(1-F25) | G27: =+G26*(1-G25) | H27: =+H26*(1-H25) | I27: =+I26*(1-I25) | J27: =+J26*(1-J25) | K27: =SUM(E27:J27) | N27: ※ターゲット数の増加分が通常の増加分を超えないように調整する | S27: 1000000 | T27: - | U27: 3000000 | W27: 2060000 | X27: - | Y27: 4860000 | Z27: 1.4
A28: 企画投稿数 | D28: 0 | E28: 4 | F28: 4 | G28: 4 | H28: 4 | I28: 4 | J28: 4 | K28: =SUM(E28:J28) | N28: ←基本本数が4本として設計する（ユーザー数と固定費で調整） | O28: CPFの単価設定 | P28: 150 | S28: 3000000 | T28: - | U28: 5000000 | W28: 4860000 | X28: - | Y28: 7460000 | Z28: 1.3
A29: 企画投稿からの流入 | D29: =+D28*D27*0.41*0.07 | E29: =+E27*E28*$P$22*$P$20*$P$21*$P$34 | F29: =+F27*F28*$P$22*$P$20*$P$21*$P$34 | G29: =+G27*G28*$P$22*$P$20*$P$21*$P$34 | H29: =+H27*H28*$P$22*$P$20*$P$21*$P$34*$Q$22 | I29: =+I27*I28*$P$22*$P$20*$P$21*$P$34*$Q$22 | J29: =+J27*J28*$P$22*$P$20*$P$21*$P$34*$Q$22 | K29: =SUM(E29:J29) | S29: 5000000 | T29: - | U29: 7000000 | W29: 7460000 | X29: - | Y29: 9860000 | Z29: 1.2
A30: ステップ配信本数 | D30: 0 | E30: 10 | F30: 10 | G30: 10 | H30: 10 | I30: 10 | J30: 10 | K30: =SUM(E30:J30) | N30: ←基本本数が4本として設計する | O30: 特典の強さ | P30: TRUE | Q30: =+IF(P30=TRUE,1.1,0.95) | S30: 7000000 | T30: - | U30: 10000000 | W30: 9860000 | X30: - | Y30: #REF!
A31: ステップ配信からの流入 | D31: 0 | E31: =+(E24*(1-E25))*E30*$P$24*$P$25*$P$26*$P$34 | F31: =+(F24*(1-F25))*F30*$P$24*$P$25*$P$26*$P$34 | G31: =+(G24*(1-G25))*G30*$P$24*$P$25*$P$26*$P$34 | H31: =+(H24*(1-H25))*H30*$P$24*$P$25*$P$26*$P$34*$Q$26 | I31: =+(I24*(1-I25))*I30*$P$24*$P$25*$P$26*$P$34*$Q$26 | J31: =+(J24*(1-J25))*J30*$P$24*$P$25*$P$26*$P$34*$Q$26 | K31: =SUM(E31:J31) | O31: クリエイティブ強さ | P31: TRUE | Q31: =+IF(P31=TRUE,1.1,0.95)
A32: 配信数 | D32: =+D27*D28 | E32: =+E27*E28*$P$22+(E24*(1-E25))*E30*$P$26 | F32: =+F27*F28*$P$22+(F24*(1-F25))*F30*$P$26 | G32: =+G27*G28*$P$22+(G24*(1-G25))*G30*$P$26 | H32: =+H27*H28*$P$22*$Q$22+(H24*(1-H25))*H30*$P$26*$Q$26 | I32: =+I27*I28*$P$22*$Q$22+(I24*(1-I25))*I30*$P$26*$Q$26 | J32: =+J27*J28*$P$22*$Q$22+(J24*(1-J25))*J30*$P$26*$Q$26 | K32: =SUM(E32:J32) | O32: 知名度強さ | P32: FALSE | Q32: =+IF(P32=TRUE,1.1,0.95)
A33: 想定Click数 | D33: =+D29*1.02 | E33: =+E29+E31+1.05*(E29+E31) | F33: =+F29+F31+1.05*(F29+F31) | G33: =+G29+G31+1.05*(G29+G31) | H33: =+H29+H31+1.05*(H29+H31) | I33: =+I29+I31+1.05*(I29+I31) | J33: =+J29+J31+1.05*(J29+J31) | K33: =SUM(E33:J33) | O33: 動線の強さ | P33: TRUE | Q33: =+IF(P33=TRUE,1.1,0.95)
A34: 新規CV | B34: =+C6 | D34: 0 | E34: 8 | F34: 10 | G34: 12 | H34: 14 | I34: 16 | J34: 18 | K34: =SUM(E34:J34) | N34: 新規向け_ | O34: 想定の係数（反応率） | P34: =1*(Q30*Q31*Q32*Q33)
B35: =+C7 | D35: 0 | E35: 10 | F35: 12 | G35: 14 | H35: 16 | I35: 18 | J35: 20 | K35: =SUM(E35:J35) | N35: 新規向け_
A36: リピートCV | B36: =+C8 | D36: 0 | E36: 0 | F36: 0 | G36: 0 | H36: 0 | I36: 0 | J36: 0 | K36: =SUM(E36:J36) | N36: 既存向け_休眠顧客向け | O36: ※①＞②で作成
B37: =+C9 | D37: 0 | E37: 0 | F37: 0 | G37: 0 | H37: 0 | I37: 0 | J37: 0 | K37: =SUM(E37:J37) | N37: 既存向け_休眠顧客向け | O37: ※③＞④で作成
A38: 合計CV | D38: =+SUM(D34:D37) | E38: =+SUM(E34:E37) | F38: =+SUM(F34:F37) | G38: =+SUM(G34:G37) | H38: =+SUM(H34:H37) | I38: =+SUM(I34:I37) | J38: =+SUM(J34:J37) | K38: =SUM(E38:J38)
B39: CVR | D39: =+IFERROR(D38/D33,0) | E39: =+IFERROR(E38/E33,0) | F39: =+IFERROR(F38/F33,0) | G39: =+IFERROR(G38/G33,0) | H39: =+IFERROR(H38/H33,0) | I39: =+IFERROR(I38/I33,0) | J39: =+IFERROR(J38/J33,0) | N39: CV/流入数で計算、0.3%〜1%とかで推移。
A41: ■成果報酬運営 | C41: 現状数値 | D41: 初期
A42: 従量課金 | D42: -- | E42: =+E73*E74 | F42: =+F73*F74 | G42: =+G73*G74 | H42: =+H73*H74 | I42: =+I73*I74 | J42: =+J73*J74
A43: コスト想定(固定費) | C43: =+SUM(C63:C70) | D43: =+SUM(D63:D70) | E43: =SUM(E63:E67)+SUM(E69:E70) | F43: =SUM(F63:F67)+SUM(F69:F70) | G43: =SUM(G63:G67)+SUM(G69:G70) | H43: =SUM(H63:H67)+SUM(H69:H70) | I43: =SUM(I63:I67)+SUM(I69:I70) | J43: =SUM(J63:J67)+SUM(J69:J70)
A44: 友だち獲得単価 | D44: -- | E44: =+SUM(E63:E65)/(E26-D26) | F44: =+SUM(F63:F65)/(F26-E26) | G44: =+SUM(G63:G65)/(G26-F26) | H44: =+SUM(H63:H65)/(H26-G26) | I44: =+SUM(I63:I65)/(I26-H26) | J44: =+SUM(J63:J65)/(J26-I26)
...

Sheet SIM①_比較
E1: →通数減らすように係数： | F1: 0.6
A3: 比較項目 | C3: DYM実装前 | D3: DYM実装後（③か月） | E3: DYM実装後（⑥か月） | F3: DYM実装後（⑫か月）
A4: コスト想定 ※月額（成果報酬プラン） | C4: =+SIM①!D22 | D4: =+SIM①!G49 | E4: =+SIM①!J49 | F4: =E4*(F16/E16)
A5: コスト想定 ※月額（固定プラン） | C5: =+SIM①!D23 | D5: =+SIM①!G59 | E5: =+SIM①!J59 | F5: =+E5+(F25-E25)
A6: 友だち数想定 | C6: =+SIM①!D26 | D6: =+SIM①!G26 | E6: =+SIM①!J26 | F6: =+E6*(E6/D6*0.95)+E6*(E6/D6*0.9)
A7: ブロック率想定 | C7: =+SIM①!D25 | D7: =+D8/D6 | E7: =+E8/E6 | F7: =+F8/F6
A8: 友だち数（アクティブ）想定 | C8: =+SIM①!D27 | D8: =+SIM①!G27 | E8: =+SIM①!J27 | F8: =+E8*(E8/D8*0.95)+E8*(E8/D8*0.9)
A10: メッセ通数 | C10: =+SIM①!D32 | D10: =+SIM①!G32 | E10: =+SIM①!J32 | F10: =IF(E10<=30000,E10*(E10/D10*0.75)+E10*(E10/D10*0.7),F1*(E10*(E10/D10*0.75)+E10*(E10/D10*0.7)))
A11: サイト流入数（LINEから） | C11: =+SIM①!D33 | D11: =+SIM①!G33 | E11: =+SIM①!J33 | F11: =+E11*(E11/D11*0.775)+E11*(E11/D11*0.725)
A12: 想定CPC（LINEOA施策）_成果報酬プラン | C12: =+IFERROR(C5/C11,0) | D12: =+D4/D11 | E12: =+E4/E11 | F12: =+F4/F11
A13: 想定CPC（LINEOA施策）_固定運用プラン | C13: =+IFERROR(C6/C12,0) | D13: =+D5/D11 | E13: =+E5/E11 | F13: =+F5/F11
R14: ■従量計算式↓
A15: CV数（もともと） | C15: =+SIM①!D14 | D15: =+SIM①!E14 | E15: =+SIM①!F14 | F15: =+SIM①!G14 | R15: ■料金テーブル
A16: CV数（+LINEOA施策） | C16: =SUM(C17:C20) | D16: =SUM(D17:D20) | E16: =SUM(E17:E20) | F16: =SUM(F17:F20) | R16: 課金対象配信総数 | V16: 費用 | Y16: 単価
A17: OA施策CV_内訳①_新規CV1 | C17: =+SIM①!D34 | D17: =+SIM①!G34 | E17: =+SIM①!J34 | F17: =+IF($E$10<=30000,IFERROR(E17*(E17/D17*0.95)+E17*(E17/D17*0.9),0),IFERROR(E17*(E17/D17*0.95)+E17*(E17/D17*0.9),0)*$F$1*1.2) | R17: 0 | S17: - | T17: 50000 | V17: 0 | W17: - | X17: 150000 | Y17: 3
A18: OA施策CV_内訳②_新規CV2 | C18: =+SIM①!D35 | D18: =+SIM①!G35 | E18: =+SIM①!J35 | F18: =+IFERROR(E18*(E18/D18*0.95)+E18*(E18/D18*0.9),0) | R18: 50000 | S18: - | T18: 100000 | V18: 150000 | W18: - | X18: 290000 | Y18: 2.8
A19: OA施策CV_内訳③_リピCV3 | C19: =+SIM①!D36 | D19: =+SIM①!G36 | E19: =+SIM①!J36 | F19: =+IF($E$10<=30000,IFERROR(E19*(E19/D19*0.95)+E19*(E19/D19*0.9),0),IFERROR(E19*(E19/D19*0.95)+E19*(E19/D19*0.9),0)*$F$1*1.2) | R19: 100000 | S19: - | T19: 200000 | V19: 290000 | W19: - | X19: 550000 | Y19: 2.6
A20: OA施策CV_内訳④_リピCV4 | C20: =+SIM①!D37 | D20: =+SIM①!G37 | E20: =+SIM①!J37 | F20: =+IFERROR(E20*(E20/D20*0.95)+E20*(E20/D20*0.9),0) | R20: 200000 | S20: - | T20: 300000 | V20: 550000 | W20: - | X20: 790000 | Y20: 2.4
R21: 300000 | S21: - | T21: 400000 | V21: 790000 | W21: - | X21: 1010000 | Y21: 2.2
A22: 成果報酬プラン_CPA（単純計算） | C22: =+IFERROR(C4/C16,"--") | D22: =+IFERROR(D4/D16,"--") | E22: =+IFERROR(E4/E16,"--") | F22: =+IFERROR(F4/F16,"--")*0.95 | R22: 400000 | S22: - | T22: 500000 | V22: 1010000 | W22: - | X22: 1210000 | Y22: 2
A23: 固定費プラン_CPA（単純計算） | C23: =+IFERROR(C5/C16,"--") | D23: =+IFERROR(D5/D16,"--") | E23: =+IFERROR(E5/E16,"--") | F23: =+IFERROR(F5/F16,"--") | R23: 500000 | S23: - | T23: 600000 | V23: 1210000 | W23: - | X23: 1400000 | Y23: 1.9
R24: 600000 | S24: - | T24: 700000 | V24: 1400000 | W24: - | X24: 1580000 | Y24: 1.8
A25: 備考_合計コスト(従量課金) ※アカウント費用 | C25: =15000+C29*C30 | D25: =15000+D29*D30 | E25: =15000+E29*E30 | F25: =15000+F29*F30 | R25: 700000 | S25: - | T25: 800000 | V25: 1580000 | W25: - | X25: 1750000 | Y25: 1.7
R26: 800000 | S26: - | T26: 900000 | V26: 1750000 | W26: - | X26: 1910000 | Y26: 1.6
R27: 900000 | S27: - | T27: 1000000 | V27: 1910000 | W27: - | X27: 2060000 | Y27: 1.5
R28: 1000000 | S28: - | T28: 3000000 | V28: 2060000 | W28: - | X28: 4860000 | Y28: 1.4
A29: 従量課金対象単価 | C29: =+IF(C10<=30000,0,C10-30000) | D29: =+IF(D10<=30000,0,D10-30000) | E29: =+IF(E10<=30000,0,E10-30000) | F29: =+IF(F10<=30000,0,F10-30000) | R29: 3000000 | S29: - | T29: 5000000 | V29: 4860000 | W29: - | X29: 7460000 | Y29: 1.3
A30: 備考単価 | C30: =+IF(C29<=$T$17,$Y$17,IF(C29<=$T$18,$Y$18,IF(C29<=$T$19,$Y$19,IF(C29<=$T$20,$Y$20,IF(C29<=$T$21,$Y$21,IF(C29<=$T$22,$Y$22,IF(C29<=$T$23,$Y$23,IF(C29<=$T$24,$Y$24,IF(C29<=$T$25,$Y$25,IF(C29<=$T$26,$Y$26,IF(C29<=$T$27,$Y$27,IF(C29<=$T$28,$Y$28,IF(C29<=$T$29,$Y$29,0))))))))))))) | D30: =+IF(D29<=$T$17,$Y$17,IF(D29<=$T$18,$Y$18,IF(D29<=$T$19,$Y$19,IF(D29<=$T$20,$Y$20,IF(D29<=$T$21,$Y$21,IF(D29<=$T$22,$Y$22,IF(D29<=$T$23,$Y$23,IF(D29<=$T$24,$Y$24,IF(D29<=$T$25,$Y$25,IF(D29<=$T$26,$Y$26,IF(D29<=$T$27,$Y$27,IF(D29<=$T$28,$Y$28,IF(D29<=$T$29,$Y$29,0))))))))))))) | E30: =+IF(E29<=$T$17,$Y$17,IF(E29<=$T$18,$Y$18,IF(E29<=$T$19,$Y$19,IF(E29<=$T$20,$Y$20,IF(E29<=$T$21,$Y$21,IF(E29<=$T$22,$Y$22,IF(E29<=$T$23,$Y$23,IF(E29<=$T$24,$Y$24,IF(E29<=$T$25,$Y$25,IF(E29<=$T$26,$Y$26,IF(E29<=$T$27,$Y$27,IF(E29<=$T$28,$Y$28,IF(E29<=$T$29,$Y$29,0))))))))))))) | F30: =+IF(F29<=$T$17,$Y$17,IF(F29<=$T$18,$Y$18,IF(F29<=$T$19,$Y$19,IF(F29<=$T$20,$Y$20,IF(F29<=$T$21,$Y$21,IF(F29<=$T$22,$Y$22,IF(F29<=$T$23,$Y$23,IF(F29<=$T$24,$Y$24,IF(F29<=$T$25,$Y$25,IF(F29<=$T$26,$Y$26,IF(F29<=$T$27,$Y$27,IF(F29<=$T$28,$Y$28,IF(F29<=$T$29,$Y$29,0))))))))))))) | R30: 5000000 | S30: - | T30: 7000000 | V30: 7460000 | W30: - | X30: 9860000 | Y30: 1.2
R31: 7000000 | S31: - | T31: 10000000 | V31: 9860000 | W31: - | X31: #REF!
A35: 階層別 | C35: 母数 | D35: 誘導率 | E35: 想定CVR | F35: 想定CVR

Sheet SIM考え方
A2: 友だち数_増加施策
A3: 離脱防止 ※
A4: 掲載率 | B4: ※サイト構成、要望により変動 | E4: 1000
A5: クリック率 | B5: 0.085
A6: 追加率 | B6: 0.08
E7: =+E4*B5*B6
A8: サイト→LINEの導線の改善 ※
A9: 掲載率 | B9: ※サイト構成、要望により変動 | E9: 1000
A10: クリック率 | B10: 0.005
A11: 追加率 | B11: 0.08
E12: =+E9*B10*B11
A13: サンクスページ誘導 ※ | D13: ただCVが増えるわけではない
A14: 掲載数 | B14: ※サイト構成、要望により変動 | E14: 1000
A15: クリック率 | B15: 0.9 | C15: ※カウントしない
A16: 追加率 | B16: 0.35
E17: =+E14*B15*B16
A18: 通知メッセの改善 ※ | D18: ただCVが増えるわけではない
A19: 掲載率 | B19: 0.7 | C19: ※サイト構成、要望により変動 | E19: 1000
A20: クリック率 | B20: 1
A21: 追加率 | B21: 0.2
E22: =+E19*B20*B21
A23: 配信効率改善施策 | C23: ※具体的なセグメントの仕方、企画により変動 | I23: 課金
A24: > 通常メッセ | I24: 1 | J24: 企画投稿（セグメントor一斉配信）
A25: 開封率 | B25: 0.8 | I25: 2 | J25: 追いメッセージ（ステップ、シナリオ）
A26: クリック率 | B26: 0.06 | I26: 3 | J26: VOOM投稿 ※同時進行の場合が多い
A27: CV率 | B27: 0.003 | I27: 4 | J27: 通知メッセージ（1通7円くらいの想定） ※機能導入が必要 ※ツール費：月8万～
A29: > 追いメッセ（ステップ、シナリオ） | I29: 非課金
A30: 開封率 | B30: 0.75 | I30: 1 | J30: 自動の即時応答
A31: クリック率 | B31: 0.08 | I31: 2 | J31: 個別チャット対応
A32: CV率 | B32: 0.006 | I32: 3 | J32: あいさつメッセージ
I33: 4 | J33: （リッチメニュー）
A34: > その他（リッチメニュー）
A35: 開封率 | B35: --
A36: クリック率 | B36: 0.02
A37: CV率 | B37: 0.004
A39: >挨拶メッセ | E39: >挨拶メッセ（アンケート回答率）
A40: 開封率 | B40: 1 | E40: 開封率 | F40: --
A41: クリック率 | B41: 0.035 | E41: 回答率 | F41: 0.25
A42: CV率 | B42: 0.006
