Workbook

Sheet SIM_ポップアップ＋サンクスLINE
A2: Ver. | B2: 46314
A4: 株式会社すなおコンサルティング御中_LINEOA施策提案【SIM】ver1.3（ポップアップツール＋サンクスLINE誘導）
N5: ※これより→はPDFにするときに消すようにする（範囲外に）
A7: ■要件定義 | B7: 地点 | C7: 名称 | D7: 成果単価
A8: 新規CV | B8: ①_CV地点 | C8: セミナー予約 | D8: 12000 | G8: LP UU（イベント月） | H8: 3000 | J8: 想定顧客リスト | K8: 4000 | N8: CV①セミナー予約（成果単価 1.2万円）。LINEのリンク経由だけ。サンクスLINEで友だちになった方（予約済み）は数えない | O8: ※メルマガ、他SNS等でのリリースが出来るか
B9: ②_CV地点 | C9: サロン入会 | D9: 0 | G9: うち広告 | H9: 3000 | N9: CV②サロン入会：成果報酬の対象外（入会はLINEから計測できないため。成果単価0円）。資料内のCVとしては数える | O9: LINEプレスリリースの可否 | P9: FALSE
A10: リピートCV | B10: ③_CV地点 | C10: セミナー予約 | D10: 12000 | G10: セミナー予約（イベント月） | H10: 80 | I10: リード（イメージ） | N10: イベント月（1・4か月目）：LP UU 仮に3,000（広告クリック 約2,760＋自社のSNS等が少し）・セミナー予約 80件（前回1回分の実績）。広告費はADの予算なので入れていない
B11: ④_CV地点 | C11: - | D11: 0 | G11: - | H11: 0 | I11: マネタイズ（イメージ）
E12: イベント期 | F12: 平常期 | G12: 平常期 | H12: イベント期 | I12: 平常期 | J12: 平常期 | O12: ↓調整可能です！
A13: 項目 | D13: ※↓現状数値 | E13: 1か月目 | F13: 2か月目 | G13: 3か月目 | H13: 4か月目 | I13: 5か月目 | J13: 6か月目 | K13: 半年合計 | L13: 単月平均（６ヶ月） | N13: 20%くらいの調整は可能です。 | O13: →DYM作業用
A14: WEBサイト | B14: UU全体 | D14: =+H8 -> 3000 | E14: =+$H$8 -> 3000 | F14: 300 | G14: 300 | H14: =+$H$8 -> 3000 | I14: 300 | J14: 300 | N14: 平常期も少量の広告が続いている → LP UU 仮に月130（広告 月10万円÷クリック単価765円）
B15: UU(うち広告) | D15: =+H9 -> 3000 | E15: =+$H$9 -> 3000 | F15: 300 | G15: 300 | H15: =+$H$9 -> 3000 | I15: 300 | J15: 300 | N15: （サイト固定リンク） | O15: AD以外のLINE誘導 | P15: 0.005 | S15: ■従量計算式↓
B16: CV（別施策） ※想定 | D16: =+H10 -> 80 | E16: =+$H$10 -> 80 | F16: 0 | G16: 0 | H16: =+$H$10 -> 80 | I16: 0 | J16: 0 | N16: （サイト固定リンク） | O16: ADでのLP/HP→LINE | P16: 0.0025 | S16: ■料金テーブル
A17: 施策 | B17: CPF | D17: FALSE | E17: FALSE | F17: FALSE | G17: FALSE | H17: FALSE | I17: FALSE | J17: FALSE | K17: -- | L17: -- | S17: 課金対象配信総数 | W17: 費用 | Z17: 単価
B18: ポップアップツール | D18: FALSE | E18: TRUE | F18: TRUE | G18: TRUE | H18: TRUE | I18: TRUE | J18: TRUE | K18: -- | L18: -- | N18: KaiU表示率 | O18: 離脱防止表示率（AD） | P18: 0.65 | S18: 0 | T18: - | U18: 200000 | W18: 0 | X18: - | Y18: 600000 | Z18: 3
B19: サンクスLINE誘導 | D19: FALSE | E19: TRUE | F19: TRUE | G19: TRUE | H19: TRUE | I19: TRUE | J19: TRUE | N19: KaiU表示率 | O19: 離脱防止表示率（SEO） | P19: 0.55 | S19: 200000 | T19: - | U19: 15000000 | W19: 600000 | X19: - | Y19: =+U19*2.5 -> 37500000 | Z19: 2.5
B20: 通知メッセージ_CV | D20: FALSE | E20: FALSE | F20: FALSE | G20: FALSE | H20: FALSE | I20: FALSE | J20: FALSE
B21: 通知メッセージ_既存リスト | D21: FALSE | E21: FALSE | F21: FALSE | G21: FALSE | H21: FALSE | I21: FALSE | J21: FALSE | K21: -- | L21: -- | O21: ↓企画投稿
A22: 施策増分 ※友だち | B22: CPF | D22: -- | E22: 0 | F22: 0 | G22: 0 | H22: 0 | I22: 0 | J22: 0 | N22: 友だち追加広告（CPF）は入れていない | O22: 開封率 | P22: 0.78
B23: ポップアップツール | D23: -- | E23: =IF(E18=FALSE,0,E15*$P$18*0.125*0.125+(E14-E15)*$P$19*0.12*0.1) -> 30.46875 | F23: =IF(F18=FALSE,0,F15*$P$18*0.125*0.125+(F14-F15)*$P$19*0.12*0.1) -> 3.046875 | G23: =IF(G18=FALSE,0,G15*$P$18*0.125*0.125+(G14-G15)*$P$19*0.12*0.1) -> 3.046875 | H23: =IF(H18=FALSE,0,H15*$P$18*0.125*0.125+(H14-H15)*$P$19*0.12*0.1) -> 30.46875 | I23: =IF(I18=FALSE,0,I15*$P$18*0.125*0.125+(I14-I15)*$P$19*0.12*0.1) -> 3.046875 | J23: =IF(J18=FALSE,0,J15*$P$18*0.125*0.125+(J14-J15)*$P$19*0.12*0.1) -> 3.046875 | N23: ポップアップツール＝LP UU×表示65%×クリック12.5%×追加12.5%（定義テキストの係数） | O23: クリック率 | P23: 0.1 | Q23: 4‐6か月後係数
B24: サンクスLINE誘導 | D24: -- | E24: =IF(E19=FALSE,0,E16*0.8*0.45) -> 28.8 | F24: =IF(F19=FALSE,0,F16*0.8*0.45) -> 0 | G24: =IF(G19=FALSE,0,G16*0.8*0.45) -> 0 | H24: =IF(H19=FALSE,0,H16*0.8*0.45) -> 28.8 | I24: =IF(I19=FALSE,0,I16*0.8*0.45) -> 0 | J24: =IF(J19=FALSE,0,J16*0.8*0.45) -> 0 | N24: サンクスLINE誘導＝セミナー予約×遷移80%×追加45%（定義テキストの係数）。平常期は予約が無いので0 | O24: audienceターゲ率 | P24: 0.8 | Q24: 0.8
B25: 通知メッセージ | D25: -- | E25: =+IF(E20=FALSE,0,SUM($H$10:$H$11)*0.7*0.3)+IF($E$21=FALSE,0,$K$8*0.15*0.15) -> 0 | F25: =+IF(F20=FALSE,0,SUM($H$10:$H$11)*0.7*0.3)+IF($E$21=FALSE,0,$K$8*0.15*0.15) -> 0 | G25: =+IF(G20=FALSE,0,SUM($H$10:$H$11)*0.7*0.3)+IF($E$21=FALSE,0,$K$8*0.15*0.15) -> 0 | H25: =+IF(H20=FALSE,0,SUM($H$10:$H$11)*0.7*0.3)+IF($E$21=FALSE,0,$K$8*0.15*0.15) -> 0 | I25: =+IF(I20=FALSE,0,SUM($H$10:$H$11)*0.7*0.3)+IF($E$21=FALSE,0,$K$8*0.15*0.15) -> 0 | J25: =+IF(J20=FALSE,0,SUM($H$10:$H$11)*0.7*0.3)+IF($E$21=FALSE,0,$K$8*0.15*0.15) -> 0 | N25: サンクス到達*情報一致率(70%前後)*実追加率 | O25: ↓ステップ配信
A26: 友だち数_増加数 | D26: -- | E26: =+SUM(E22:E25) -> 59.26875 | F26: =+SUM(F22:F25) -> 3.046875 | G26: =+SUM(G22:G25) -> 3.046875 | H26: =+SUM(H22:H25) -> 59.26875 | I26: =+SUM(I22:I25) -> 3.046875 | J26: =+SUM(J22:J25) -> 3.046875 | N26: 友だちの入口はポップアップツール＋サンクスLINE誘導だけ（資料の「友だちの入口」と同じ） | O26: 開封率 | P26: 0.725
A27: ブロック率 | D27: 0 | E27: 0.28 | F27: 0.29 | G27: 0.295 | H27: 0.3 | I27: 0.305 | J27: 0.31 | N27: ブロック率：殿村さんの表（28.0%→31.0%） | O27: クリック率 | P27: 0.12 | Q27: 4‐6か月後係数
A28: 友だち数 | D28: 0 | E28: =+D28+E26 -> 59.26875 | F28: =+E28+F26 -> 62.315625 | G28: =+F28+G26 -> 65.3625 | H28: =+G28+H26 -> 124.63125 | I28: =+H28+I26 -> 127.67812 | J28: =+I28+J26 -> 130.725 | O28: audienceターゲ率 | P28: 0.2 | Q28: 0.8
A29: ターゲット数 | D29: =+D28*(1-D27) -> 0 | E29: =+E28*(1-E27) -> 42.6735 | F29: =+F28*(1-F27) -> 44.244094 | G29: =+G28*(1-G27) -> 46.080562 | H29: =+H28*(1-H27) -> 87.241875 | I29: =+I28*(1-I27) -> 88.736297 | J29: =+J28*(1-J27) -> 90.20025 | N29: ※ターゲット数の増加分が通常の増加分を超えないように調整する
A30: 企画投稿数 | D30: 0 | E30: 4 | F30: 2 | G30: 2 | H30: 4 | I30: 2 | J30: 2 | N30: 企画配信：イベント期 月4回／平常期 月2回（資料の料金 プラン②と同じ） | O30: CPFの単価設定
A31: 企画投稿からの流入 | D31: =+D30*D29*0.41*0.07 -> 0 | E31: =+E29*E30*$P$24*$P$22*$P$23*$P$36 -> 15.594577 | F31: =+F29*F30*$P$24*$P$22*$P$23*$P$36 -> 8.0842667 | G31: =+G29*G30*$P$24*$P$22*$P$23*$P$36 -> 8.4198256 | H31: =+H29*H30*$P$24*$P$22*$P$23*$P$36*$Q$24 -> 25.505292 | I31: =+I29*I30*$P$24*$P$22*$P$23*$P$36*$Q$24 -> 12.971094 | J31: =+J29*J30*$P$24*$P$22*$P$23*$P$36*$Q$24 -> 13.185089
A32: ステップ配信本数 | D32: 0 | E32: 5 | F32: 5 | G32: 5 | H32: 5 | I32: 5 | J32: 5 | N32: ステップ配信5通（その月の新しい友だち。セミナーの見どころ→参加特典→予約の案内） | O32: 特典の強さ | P32: TRUE | Q32: =+IF(P32=TRUE,1.1,0.95) -> 1.1
A33: ステップ配信からの流入 | D33: 0 | E33: =+E26*E32*$P$26*$P$27*$P$36 -> 37.747289 | F33: =+F26*F32*$P$26*$P$27*$P$36 -> 1.9405044 | G33: =+G26*G32*$P$26*$P$27*$P$36 -> 1.9405044 | H33: =+H26*H32*$P$26*$P$27*$P$36 -> 37.747289 | I33: =+I26*I32*$P$26*$P$27*$P$36 -> 1.9405044 | J33: =+J26*J32*$P$26*$P$27*$P$36 -> 1.9405044 | O33: クリエイティブ強さ | P33: TRUE | Q33: =+IF(P33=TRUE,1.1,0.95) -> 1.1
A34: 配信数 | D34: =+D29*D30 -> 0 | E34: =+E29*E30*$P$24+E26*E32 -> 432.89895 | F34: =+F29*F30*$P$24+F26*F32 -> 86.024925 | G34: =+G29*G30*$P$24+G26*G32 -> 88.963275 | H34: =+H29*H30*$P$24*$Q$24+H26*H32 -> 519.68295 | I34: =+I29*I30*$P$24*$Q$24+I26*I32 -> 128.81684 | J34: =+J29*J30*$P$24*$Q$24+J26*J32 -> 130.6907 | O34: 知名度強さ | P34: TRUE | Q34: =+IF(P34=TRUE,1.1,0.95) -> 1.1
A35: 想定Click数 | D35: =+D31*1.02 -> 0 | E35: =+E31+E33+1.05*(E31+E33) -> 109.35082 | F35: =+F31+F33+1.05*(F31+F33) -> 20.550781 | G35: =+G31+G33+1.05*(G31+G33) -> 21.238677 | H35: =+H31+H33+1.05*(H31+H33) -> 129.66779 | I35: =+I31+I33+1.05*(I31+I33) -> 30.568777 | J35: =+J31+J33+1.05*(J31+J33) -> 31.007466 | O35: 動線の強さ | P35: TRUE | Q35: =+IF(P35=TRUE,1.1,0.95) -> 1.1
A36: 新規CV | B36: =+C8 -> セミナー予約 | D36: 0 | E36: 3 | F36: 0 | G36: 1 | H36: 4 | I36: 0 | J36: 1 | K36: =SUM(E36:J36) -> 9 | N36: セミナー予約＝クリックの0.3〜1.0%前後（目安。細かい件数は殿村さん） | O36: 想定の係数（反応率） | P36: =1*(Q32*Q33*Q34*Q35) -> 1.4641
B37: =+C9 -> サロン入会 | D37: 0 | E37: 1 | F37: 1 | G37: 0 | H37: 1 | I37: 1 | J37: 0 | K37: =SUM(E37:J37) -> 4 | N37: サロン入会＝資料内のCVとして数える（成果報酬の対象外）
A38: リピートCV | B38: =+C10 -> セミナー予約 | D38: 0 | E38: 0 | F38: 0 | G38: 0 | H38: 2 | I38: 0 | J38: 0 | K38: =SUM(E38:J38) -> 2 | N38: リピート予約＝2回目以降のイベントのセミナー予約（LINEのリンク経由・過去に予約がある方）。成果単価1.2万円 | O38: ※①＞②で作成
B39: =+C11 -> - | D39: 0 | E39: 0 | F39: 0 | G39: 0 | H39: 0 | I39: 0 | J39: 0 | K39: =SUM(E39:J39) -> 0 | N39: 既存向け_休眠顧客向け | O39: ※③＞④で作成
A40: 合計CV | D40: =+SUM(D36:D39) -> 0 | E40: =+SUM(E36:E39) -> 4 | F40: =+SUM(F36:F39) -> 1 | G40: =+SUM(G36:G39) -> 1 | H40: =+SUM(H36:H39) -> 7 | I40: =+SUM(I36:I39) -> 1 | J40: =+SUM(J36:J39) -> 1 | K40: =SUM(E40:J40) -> 15
B41: CVR | D41: =+IFERROR(D40/D35,0) -> 0 | E41: =+IFERROR(E40/E35,0) -> 0.036579514 | F41: =+IFERROR(F40/F35,0) -> 0.048659952 | G41: =+IFERROR(G40/G35,0) -> 0.047083913 | H41: =+IFERROR(H40/H35,0) -> 0.053984108 | I41: =+IFERROR(I40/I35,0) -> 0.032713117 | J41: =+IFERROR(J40/J35,0) -> 0.032250298 | N41: CV/流入数で計算、0.3%〜1%とかで推移。
A43: ■成果報酬運営 | C43: 現状数値 | D43: 初期
A44: 従量課金 | D44: -- | E44: =+E75*E76 -> 0 | F44: =+F75*F76 -> 0 | G44: =+G75*G76 -> 0 | H44: =+H75*H76 -> 0 | I44: =+I75*I76 -> 0 | J44: =+J75*J76 -> 0
...

Sheet SIM_比較
E1: →通数減らすように係数： | F1: 0.6
A3: 比較項目 | C3: DYM実装前 | D3: DYM実装後（③か月） | E3: DYM実装後（⑥か月）
A4: コスト想定 ※月額（成果報酬プラン） | C4: =+'SIM_ポップアップ＋サンクスLINE'!D24 -> -- | D4: =+'SIM_ポップアップ＋サンクスLINE'!G51 -> 177000 | E4: =+'SIM_ポップアップ＋サンクスLINE'!J51 -> 177000
A5: コスト想定 ※月額（固定プラン） | C5: =+'SIM_ポップアップ＋サンクスLINE'!D25 -> -- | D5: =+'SIM_ポップアップ＋サンクスLINE'!G61 -> 165000 | E5: =+'SIM_ポップアップ＋サンクスLINE'!J61 -> 165000
A6: 友だち数想定 | C6: =+'SIM_ポップアップ＋サンクスLINE'!D28 -> 0 | D6: =+'SIM_ポップアップ＋サンクスLINE'!G28 -> 65.3625 | E6: =+'SIM_ポップアップ＋サンクスLINE'!J28 -> 130.725
A7: ブロック率想定 | C7: =+'SIM_ポップアップ＋サンクスLINE'!D27 -> 0 | D7: =+'SIM_ポップアップ＋サンクスLINE'!G27 -> 0.295 | E7: =+'SIM_ポップアップ＋サンクスLINE'!J27 -> 0.31
A8: 友だち数（アクティブ）想定 | C8: =+'SIM_ポップアップ＋サンクスLINE'!D29 -> 0 | D8: =+'SIM_ポップアップ＋サンクスLINE'!G29 -> 46.080562 | E8: =+'SIM_ポップアップ＋サンクスLINE'!J29 -> 90.20025
A10: メッセ通数 | C10: =+'SIM_ポップアップ＋サンクスLINE'!D34 -> 0 | D10: =+'SIM_ポップアップ＋サンクスLINE'!G34 -> 88.963275 | E10: =+'SIM_ポップアップ＋サンクスLINE'!J34 -> 130.6907
A11: サイト流入数（LINEから） | C11: =+'SIM_ポップアップ＋サンクスLINE'!D35 -> 0 | D11: =+'SIM_ポップアップ＋サンクスLINE'!G35 -> 21.238677 | E11: =+'SIM_ポップアップ＋サンクスLINE'!J35 -> 31.007466
A12: 想定CPC（LINEOA施策）_成果報酬プラン | C12: =+IFERROR(C5/C11,0) -> 0 | D12: =+D4/D11 -> 8333.8526 | E12: =+E4/E11 -> 5708.3027
A13: 想定CPC（LINEOA施策）_固定運用プラン | C13: =+IFERROR(C6/C12,0) -> 0 | D13: =+D5/D11 -> 7768.8456 | E13: =+E5/E11 -> 5321.2991
R14: ■従量計算式↓
A15: セミナー予約（広告・イベント1回あたり） | C15: =+'SIM_ポップアップ＋サンクスLINE'!$H$10 -> 80 | D15: =+'SIM_ポップアップ＋サンクスLINE'!$H$10 -> 80 | E15: =+'SIM_ポップアップ＋サンクスLINE'!$H$10 -> 80 | R15: ■料金テーブル
A16: CV数（+LINEOA施策） | C16: =SUM(C17:C20) -> 0 | D16: =SUM(D17:D20) -> 1 | E16: =SUM(E17:E20) -> 1 | R16: 課金対象配信総数 | V16: 費用 | Y16: 単価
A17: CV①_セミナー予約 | C17: =+'SIM_ポップアップ＋サンクスLINE'!D36 -> 0 | D17: =+'SIM_ポップアップ＋サンクスLINE'!G36 -> 1 | E17: =+'SIM_ポップアップ＋サンクスLINE'!J36 -> 1 | R17: 0 | S17: - | T17: 200000 | V17: 0 | W17: - | X17: 600000 | Y17: 3
A18: CV②_サロン入会 | C18: =+'SIM_ポップアップ＋サンクスLINE'!D37 -> 0 | D18: =+'SIM_ポップアップ＋サンクスLINE'!G37 -> 0 | E18: =+'SIM_ポップアップ＋サンクスLINE'!J37 -> 0 | R18: 200000 | S18: - | T18: 15000000 | V18: 600000 | W18: - | X18: =+T18*2.5 -> 37500000 | Y18: 2.5
A19: CV③_セミナー予約（リピート） | C19: =+'SIM_ポップアップ＋サンクスLINE'!D38 -> 0 | D19: =+'SIM_ポップアップ＋サンクスLINE'!G38 -> 0 | E19: =+'SIM_ポップアップ＋サンクスLINE'!J38 -> 0
A20: - | C20: =+'SIM_ポップアップ＋サンクスLINE'!D39 -> 0 | D20: =+'SIM_ポップアップ＋サンクスLINE'!G39 -> 0 | E20: =+'SIM_ポップアップ＋サンクスLINE'!J39 -> 0
A22: 成果報酬プラン_CPA（単純計算） | C22: =+IFERROR(C4/C16,"--") -> -- | D22: =+IFERROR(D4/D16,"--") -> 177000 | E22: =+IFERROR(E4/E16,"--") -> 177000
A23: 固定費プラン_CPA（単純計算） | C23: =+IFERROR(C5/C16,"--") -> -- | D23: =+IFERROR(D5/D16,"--") -> 165000 | E23: =+IFERROR(E5/E16,"--") -> 165000
A25: 備考_合計コスト(従量課金) ※アカウント費用 | C25: =+'SIM_ポップアップ＋サンクスLINE'!E68+C29*C30 -> 5000 | D25: =+'SIM_ポップアップ＋サンクスLINE'!G68+D29*D30 -> 5000 | E25: =+'SIM_ポップアップ＋サンクスLINE'!J68+E29*E30 -> 5000
A29: 従量課金対象単価 | C29: =+IF(C10<=30000,0,C10-30000) -> 0 | D29: =+IF(D10<=30000,0,D10-30000) -> 0 | E29: =+IF(E10<=30000,0,E10-30000) -> 0
A30: 備考単価 | C30: =+IF(C29<=$T$17,$Y$17,IF(C29<=$T$18,$Y$18,IF(C29<=$T$19,$Y$19,IF(C29<=$T$20,$Y$20,IF(C29<=$T$21,$Y$21,IF(C29<=$T$22,$Y$22,IF(C29<=$T$23,$Y$23,IF(C29<=$T$24,$Y$24,IF(C29<=$T$25,$Y$25,IF(C29<=$T$26,$Y$26,IF(C29<=$T$27,$Y$27,IF(C29<=$T$28,$Y$28,IF(C29<=$T$29,$Y$29,0))))))))))))) -> 3 | D30: =+IF(D29<=$T$17,$Y$17,IF(D29<=$T$18,$Y$18,IF(D29<=$T$19,$Y$19,IF(D29<=$T$20,$Y$20,IF(D29<=$T$21,$Y$21,IF(D29<=$T$22,$Y$22,IF(D29<=$T$23,$Y$23,IF(D29<=$T$24,$Y$24,IF(D29<=$T$25,$Y$25,IF(D29<=$T$26,$Y$26,IF(D29<=$T$27,$Y$27,IF(D29<=$T$28,$Y$28,IF(D29<=$T$29,$Y$29,0))))))))))))) -> 3 | E30: =+IF(E29<=$T$17,$Y$17,IF(E29<=$T$18,$Y$18,IF(E29<=$T$19,$Y$19,IF(E29<=$T$20,$Y$20,IF(E29<=$T$21,$Y$21,IF(E29<=$T$22,$Y$22,IF(E29<=$T$23,$Y$23,IF(E29<=$T$24,$Y$24,IF(E29<=$T$25,$Y$25,IF(E29<=$T$26,$Y$26,IF(E29<=$T$27,$Y$27,IF(E29<=$T$28,$Y$28,IF(E29<=$T$29,$Y$29,0))))))))))))) -> 3
A35: 階層別 | C35: 母数 | D35: 誘導率 | E35: 想定CVR | F35: 想定CVR

Sheet SIM考え方
A2: 友だち数_増加施策
A3: 離脱防止 ※
A4: 掲載率 | B4: ※サイト構成、要望により変動 | E4: 1000
A5: クリック率 | B5: 0.085
A6: 追加率 | B6: 0.08
E7: =+E4*B5*B6 -> 6.8
A8: サイト→LINEの導線の改善 ※
A9: 掲載率 | B9: ※サイト構成、要望により変動 | E9: 1000
A10: クリック率 | B10: 0.005
A11: 追加率 | B11: 0.08
E12: =+E9*B10*B11 -> 0.4
A13: サンクスページ誘導 ※ | D13: ただCVが増えるわけではない
A14: 掲載数 | B14: ※サイト構成、要望により変動 | E14: 1000
A15: クリック率 | B15: 0.9 | C15: ※カウントしない
A16: 追加率 | B16: 0.35
E17: =+E14*B15*B16 -> 315
A18: 通知メッセの改善 ※ | D18: ただCVが増えるわけではない
A19: 掲載率 | B19: 0.7 | C19: ※サイト構成、要望により変動 | E19: 1000
A20: クリック率 | B20: 1
A21: 追加率 | B21: 0.2
E22: =+E19*B20*B21 -> 200
A23: 配信効率改善施策 | C23: ※具体的なセグメントの仕方、企画により変動 | I23: 課金
A24: > 通常メッセ | I24: 1 | J24: 企画投稿（セグメントor一斉配信）
A25: 開封率 | B25: 0.8 | I25: 2 | J25: 追いメッセージ（ステップ、シナリオ）
A26: クリック率 | B26: 0.06 | I26: 3 | J26: VOOM投稿 ※同時進行の場合が多い
A27: CV率 | B27: 0.003 | I27: 4 | J27: 通知メッセージ（1通7円くらいの想定） ※機能導入が必要 ※ツール費：月8万～
A29: > 追いメッセ（ステップ、シナリオ） | I29: 非課金
A30: 開封率 | B30: 0.75 | I30: 1 | J30: 自動の即時応答
A31: クリック率 | B31: 0.08 | I31: 2 | J31: 個別チャット対応
A32: CV率 | B32: 0.006 | I32: 3 | J32: あいさつメッセージ
I33: 4 | J33: （リッチメニュー）
A34: > その他（リッチメニュー）
A35: 開封率 | B35: --
A36: クリック率 | B36: 0.02
A37: CV率 | B37: 0.004
A39: >挨拶メッセ | E39: >挨拶メッセ（アンケート回答率）
A40: 開封率 | B40: 1 | E40: 開封率 | F40: --
A41: クリック率 | B41: 0.035 | E41: 回答率 | F41: 0.25
A42: CV率 | B42: 0.006
