Workbook

Sheet SIM①_月3投稿
A2: Ver. | B2: 46321
A4: 株式会社ワクトリ御中_LINEOA施策提案【SIM】プラン①（月3投稿）：ポップアップ
N5: ※これより→はPDFにするときに消すようにする（範囲外に）
A7: ■要件定義 | B7: 地点 | C7: 名称 | D7: 成果単価
A8: 新規CV | B8: ①_CV地点 | C8: 応募 | D8: 0 | G8: UU | H8: 85887 | J8: 想定顧客リスト | K8: 0 | N8: CV＝応募（サイトの「ENTRY」と求人ページの「応募」は同じ登録フォーム）。LINE経由は計測用のフォームで数える。成果報酬型の単価 4,000円（仮） | O8: ※メルマガ、他SNS等でのリリースが出来るか
B9: ②_CV地点 | C9: - | D9: 0 | G9: 広告・アフィUU | H9: 0 | N9: 広告比率等を参考に | O9: LINEプレスリリースの可否 | P9: FALSE
A10: リピートCV | B10: ③_CV地点 | C10: - | D10: 0 | G10: 応募（月） | H10: 400 | I10: リード（イメージ） | N10: サイトからの応募は与件に無いので、仮に月400件（広告費 月約250万円÷1件あたり約6,000円の目安）＝サンクスLINEの母数
B11: ④_CV地点 | C11: - | D11: 0 | G11: - | H11: 0 | I11: マネタイズ（イメージ）
O12: ↓調整可能です！
A13: 項目 | D13: ※↓現状数値 | E13: 1か月目 | F13: 2か月目 | G13: 3か月目 | H13: 4か月目 | I13: 5か月目 | J13: 6か月目 | K13: 半年合計 | L13: 単月平均（６ヶ月） | N13: 20%くらいの調整は可能です。 | O13: →DYM作業用
A14: WEBサイト | B14: UU全体 | D14: =+H8 -> 85887 | E14: =+D14 -> 85887 | F14: =+E14 -> 85887 | G14: =+F14 -> 85887 | H14: =+G14 -> 85887 | I14: =+H14 -> 85887 | J14: =+I14 -> 85887
B15: UU(うち広告) | D15: =+H9 -> 0 | E15: =+D15 -> 0 | F15: =+E15 -> 0 | G15: =+F15 -> 0 | H15: =+G15 -> 0 | I15: =+H15 -> 0 | J15: =+I15 -> 0 | N15: 広告UUは不明なので0（UU全体をサイトのLINEボタン0.5%・ポップアップの式で計算） | O15: AD以外のLINE誘導 | P15: 0.005 | S15: ■従量計算式↓
B16: CV（別施策） ※想定 | D16: =H10 -> 400 | E16: =+D16 -> 400 | F16: =+E16 -> 400 | G16: =+F16 -> 400 | H16: =+G16 -> 400 | I16: =+H16 -> 400 | J16: =+I16 -> 400 | N16: （サイト固定リンク） | O16: ADでのLP/HP→LINE | P16: 0.0025 | S16: ■料金テーブル
A17: 施策 | B17: CPF | D17: FALSE | E17: FALSE | F17: FALSE | G17: FALSE | H17: FALSE | I17: FALSE | J17: FALSE | K17: -- | L17: -- | S17: 課金対象配信総数 | W17: 費用 | Z17: 単価
B18: 離脱防止 | D18: FALSE | E18: TRUE | F18: TRUE | G18: TRUE | H18: TRUE | I18: TRUE | J18: TRUE | K18: -- | L18: -- | N18: ポップアップ＝UU×表示55%×クリック12%×追加12%（FMTの式） | O18: 離脱防止表示率（AD） | P18: 0.65 | S18: 0 | T18: - | U18: 200000 | W18: 0 | X18: - | Y18: 600000 | Z18: 3
B19: サンクスLINE誘導 | D19: FALSE | E19: FALSE | F19: FALSE | G19: FALSE | H19: FALSE | I19: FALSE | J19: FALSE | N19: KaiU表示率 | O19: 離脱防止表示率（SEO） | P19: 0.55 | S19: 200000 | T19: - | U19: 15000000 | W19: 600000 | X19: - | Y19: =+U19*2.5 -> 37500000 | Z19: 2.5
B20: 通知メッセージ_CV | D20: FALSE | E20: FALSE | F20: FALSE | G20: FALSE | H20: FALSE | I20: FALSE | J20: FALSE
B21: 通知メッセージ_既存リスト | D21: FALSE | E21: FALSE | F21: FALSE | G21: FALSE | H21: FALSE | I21: FALSE | J21: FALSE | K21: -- | L21: -- | O21: ↓企画投稿
A22: 施策増分 ※友だち | B22: CPF | D22: -- | E22: 0 | F22: 0 | G22: 0 | H22: 0 | I22: 0 | J22: 0 | N22: 友だち追加広告（CPF）は入れていない | O22: 開封率 | P22: 0.78
B23: 離脱防止 | D23: -- | E23: =IF(E18=FALSE,0,E15*$P$18*0.08*0.08+(E14-E15)*$P$19*0.12*0.12) -> 680.22504 | F23: =IF(F18=FALSE,0,F15*$P$18*0.08*0.08+(F14-F15)*$P$19*0.12*0.12) -> 680.22504 | G23: =F23*1.01 -> 687.02729 | H23: =G23*1.01 -> 693.89756 | I23: =H23*1.01 -> 700.83654 | J23: =I23*1.01 -> 707.8449 | N23: 離脱防止表示率×UU×クリック率×実追加率 | O23: クリック率 | P23: 0.1 | Q23: 4‐6か月後係数
B24: サンクスLINE誘導 | D24: -- | E24: =IF(E19=FALSE,0,$H$10*0.8*0.45) -> 0 | F24: =IF(F19=FALSE,0,$H$10*0.8*0.45) -> 0 | G24: =IF(G19=FALSE,0,$H$10*0.8*0.45) -> 0 | H24: =IF(H19=FALSE,0,$H$10*0.8*0.45) -> 0 | I24: =IF(I19=FALSE,0,$H$10*0.8*0.45) -> 0 | J24: =IF(J19=FALSE,0,$H$10*0.8*0.45) -> 0 | N24: サンクスLINE誘導＝応募×遷移80%×追加45%。マイページ登録（応募）の完了画面からLINEへ | O24: audienceターゲ率 | P24: 0.8 | Q24: 0.8
B25: 通知メッセージ | D25: -- | E25: =+IF(E20=FALSE,0,SUM($H$10:$H$11)*0.7*0.3)+IF($E$21=FALSE,0,$K$8*0.15*0.15) -> 0 | F25: =+IF(F20=FALSE,0,SUM($H$10:$H$11)*0.7*0.3)+IF($E$21=FALSE,0,$K$8*0.15*0.15) -> 0 | G25: =+IF(G20=FALSE,0,SUM($H$10:$H$11)*0.7*0.3)+IF($E$21=FALSE,0,$K$8*0.15*0.15) -> 0 | H25: =+IF(H20=FALSE,0,SUM($H$10:$H$11)*0.7*0.3)+IF($E$21=FALSE,0,$K$8*0.15*0.15) -> 0 | I25: =+IF(I20=FALSE,0,SUM($H$10:$H$11)*0.7*0.3)+IF($E$21=FALSE,0,$K$8*0.15*0.15) -> 0 | J25: =+IF(J20=FALSE,0,SUM($H$10:$H$11)*0.7*0.3)+IF($E$21=FALSE,0,$K$8*0.15*0.15) -> 0 | N25: サンクス到達*情報一致率(70%前後)*実追加率 | O25: ↓ステップ配信
A26: 友だち数_増加数 | D26: -- | E26: =+SUM(E22:E25)+$H$9*$P$16+($H$8-$H$9)*$P$15+IF(P9=FALSE,0,$K$8*0.15*0.08) -> 1109.66 | F26: =+SUM(F22:F25)+$H$9*$P$16+($H$8-$H$9)*$P$15 -> 1109.66 | G26: =+SUM(G22:G25)+$H$9*$P$16+($H$8-$H$9)*$P$15 -> 1116.4623 | H26: =+SUM(H22:H25)+$H$9*$P$16+($H$8-$H$9)*$P$15 -> 1123.3326 | I26: =+SUM(I22:I25)+$H$9*$P$16+($H$8-$H$9)*$P$15 -> 1130.2715 | J26: =+SUM(J22:J25)+$H$9*$P$16+($H$8-$H$9)*$P$15 -> 1137.2799 | N26: サイトのLINEボタン（UU×0.5%・FMTのP15）＋ポップアップ＋サンクスLINE | O26: 開封率 | P26: 0.725
A27: ブロック率 | D27: 0.421 | E27: 0.421 | F27: =ROUND(E27*1.02,3) -> 0.429 | G27: =ROUND(F27*1.02,3) -> 0.438 | H27: =ROUND(G27*1.02,3) -> 0.447 | I27: =ROUND(H27*1.02,3) -> 0.456 | J27: =ROUND(I27*1.02,3) -> 0.465 | N27: ブロック率：今は不明なので仮に40%。その後は前の月×1.02 | O27: クリック率 | P27: 0.12 | Q27: 4‐6か月後係数
A28: 友だち数 | D28: 79904 | E28: =+D28+E26 -> 81013.66 | F28: =+E28+F26 -> 82123.32 | G28: =+F28+G26 -> 83239.782 | H28: =+G28+H26 -> 84363.115 | I28: =+H28+I26 -> 85493.386 | J28: =+I28+J26 -> 86630.666 | N28: 今の友だち 79,904人（プロフィールの表示・2026年10月） | O28: audienceターゲ率 | P28: 0.2 | Q28: 0.8
A29: ターゲット数 | D29: =+D28*(1-D27) -> 46264.416 | E29: =+E28*(1-E27) -> 46906.909 | F29: =+F28*(1-F27) -> 46892.416 | G29: =+G28*(1-G27) -> 46780.758 | H29: =+H28*(1-H27) -> 46652.803 | I29: =+I28*(1-I27) -> 46508.402 | J29: =+J28*(1-J27) -> 46347.407 | N29: ※ターゲット数の増加分が通常の増加分を超えないように調整する
A30: 企画投稿数 | D30: 4 | E30: 3 | F30: 3 | G30: 3 | H30: 3 | I30: 3 | J30: 3 | N30: 企画配信 月3本（開始時期・エリア別に出し分け。対象は有効な友だちの80%、4か月目から反応しない方を外してさらに8割）。今は週1回（月4本） | O30: CPFの単価設定
A31: 企画投稿からの流入 | D31: =+D30*D29*0.75*0.41*0.07 | E31: =+E29*E30*$P$24*$P$22*$P$23*$P$36 -> 12856.223 | F31: =+F29*F30*$P$24*$P$22*$P$23*$P$36 -> 12852.251 | G31: =+G29*G30*$P$24*$P$22*$P$23*$P$36 -> 12821.648 | H31: =+H29*H30*$P$24*$P$22*$P$23*$P$36*$Q$24 -> 10229.262 | I31: =+I29*I30*$P$24*$P$22*$P$23*$P$36*$Q$24 -> 10197.6 | J31: =+J29*J30*$P$24*$P$22*$P$23*$P$36*$Q$24 -> 10162.3
A32: ステップ配信本数 | D32: 0 | E32: 5 | F32: 5 | G32: 5 | H32: 5 | I32: 5 | J32: 5 | N32: ステップ配信5通（友だち追加から15日以内）。対象＝その月の新しい友だち（サンクスLINEで追加した応募済みの方は除く） | O32: 特典の強さ | P32: TRUE | Q32: =+IF(P32=TRUE,1.1,0.95) -> 1.1
A33: ステップ配信からの流入 | D33: 0 | E33: =+(E26-E24)*E32*$P$26*$P$27*$P$36 -> 706.72417 | F33: =+(F26-F24)*F32*$P$26*$P$27*$P$36 -> 706.72417 | G33: =+(G26-G24)*G32*$P$26*$P$27*$P$36 -> 711.05641 | H33: =+(H26-H24)*H32*$P$26*$P$27*$P$36 -> 715.43197 | I33: =+(I26-I24)*I32*$P$26*$P$27*$P$36 -> 719.85129 | J33: =+(J26-J24)*J32*$P$26*$P$27*$P$36 -> 724.31481 | O33: クリエイティブ強さ | P33: TRUE | Q33: =+IF(P33=TRUE,1.1,0.95) -> 1.1
A34: 配信数 | D34: =+D29*D30*0.75 | E34: =+E29*E30*$P$24+E26*E32 -> 118124.88 | F34: =+F29*F30*$P$24+F26*F32 -> 118090.1 | G34: =+G29*G30*$P$24+G26*G32 -> 117856.13 | H34: =+H29*H30*$P$24*$Q$24+H26*H32 -> 95190.044 | I34: =+I29*I30*$P$24*$Q$24+I26*I32 -> 94947.49 | J34: =+J29*J30*$P$24*$Q$24+J26*J32 -> 94673.42 | O34: 知名度強さ | P34: TRUE | Q34: =+IF(P34=TRUE,1.1,0.95) -> 1.1
A35: 想定Click数 | D35: =+D31*1.02 -> 5417.3781 | E35: =+E31+E33+1.05*(E31+E33) -> 27804.042 | F35: =+F31+F33+1.05*(F31+F33) -> 27795.899 | G35: =+G31+G33+1.05*(G31+G33) -> 27742.043 | H35: =+H31+H33+1.05*(H31+H33) -> 22436.623 | I35: =+I31+I33+1.05*(I31+I33) -> 22380.776 | J35: =+J31+J33+1.05*(J31+J33) -> 22317.56 | O35: 動線の強さ | P35: TRUE | Q35: =+IF(P35=TRUE,1.1,0.95) -> 1.1
A36: 新規CV | B36: =+C8 -> 応募 | D36: 0 | E36: =ROUND(E35*0.004,0) -> 111 | F36: =ROUND(F35*0.0045,0) -> 125 | G36: =ROUND(G35*0.0055,0) -> 153 | H36: =ROUND(H35*0.0065,0) -> 146 | I36: =ROUND(I35*0.0075,0) -> 168 | J36: =ROUND(J35*0.009,0) -> 201 | K36: =SUM(E36:J36) -> 904 | N36: 応募＝想定クリック×0.3〜0.6%（運用が育つ想定で月ごとに上げる）。サンクスLINEで追加した方は応募済みなので数えない | O36: 想定の係数（反応率） | P36: =1*(Q32*Q33*Q34*Q35) -> 1.4641
B37: =+C9 -> - | D37: 0 | E37: 0 | F37: 0 | G37: 0 | H37: 0 | I37: 0 | J37: 0 | K37: =SUM(E37:J37) -> 0 | N37: 新規向け_
A38: リピートCV | B38: =+C10 -> - | D38: 0 | E38: 0 | F38: 0 | G38: 0 | H38: 0 | I38: 0 | J38: 0 | K38: =SUM(E38:J38) -> 0 | N38: 既存向け_休眠顧客向け | O38: ※①＞②で作成
B39: =+C11 -> - | D39: 0 | E39: 0 | F39: 0 | G39: 0 | H39: 0 | I39: 0 | J39: 0 | K39: =SUM(E39:J39) -> 0 | N39: 既存向け_休眠顧客向け | O39: ※③＞④で作成
A40: 合計CV | D40: =+SUM(D36:D39) -> 0 | E40: =+SUM(E36:E39) -> 111 | F40: =+SUM(F36:F39) -> 125 | G40: =+SUM(G36:G39) -> 153 | H40: =+SUM(H36:H39) -> 146 | I40: =+SUM(I36:I39) -> 168 | J40: =+SUM(J36:J39) -> 201 | K40: =SUM(E40:J40) -> 904
B41: CVR | D41: =+IFERROR(D40/D35,0) -> 0 | E41: =+IFERROR(E40/E35,0) -> 0.0039922253 | F41: =+IFERROR(F40/F35,0) -> 0.0044970663 | G41: =+IFERROR(G40/G35,0) -> 0.0055150949 | H41: =+IFERROR(H40/H35,0) -> 0.0065072181 | I41: =+IFERROR(I40/I35,0) -> 0.0075064421 | J41: =+IFERROR(J40/J35,0) -> 0.0090063608 | N41: CV/流入数で計算、0.3%〜1%とかで推移。
A43: ■成果報酬運営 | C43: 現状数値 | D43: 初期
A44: 従量課金 | D44: -- | E44: =+E75*E76 -> 264374.65 | F44: =+F75*F76 -> 264270.29 | G44: =+G75*G76 -> 263568.39 | H44: =+H75*H76 -> 195570.13 | I44: =+I75*I76 -> 194842.47 | J44: =+J75*J76 -> 194020.26
...

Sheet SIM①_比較
E1: →通数減らすように係数： | F1: 0.6
A3: 比較項目 | C3: DYM実装前 | D3: DYM実装後（③か月） | E3: DYM実装後（⑥か月）
A4: コスト想定 ※月額（成果報酬プラン） | C4: =+SIM①_月3投稿!D24 -> -- | D4: =+SIM①_月3投稿!G51 -> 308568.39 | E4: =+SIM①_月3投稿!J51 -> 239020.26
A5: コスト想定 ※月額（固定プラン） | C5: =+SIM①_月3投稿!D25 -> -- | D5: =+SIM①_月3投稿!G61 -> 608568.39 | E5: =+SIM①_月3投稿!J61 -> 539020.26
A6: 友だち数想定 | C6: =+SIM①_月3投稿!D28 -> 79904 | D6: =+SIM①_月3投稿!G28 -> 83239.782 | E6: =+SIM①_月3投稿!J28 -> 86630.666
A7: ブロック率想定 | C7: =+SIM①_月3投稿!D27 -> 0.421 | D7: =+SIM①_月3投稿!G27 -> 0.438 | E7: =+SIM①_月3投稿!J27 -> 0.465
A8: 友だち数（アクティブ）想定 | C8: =+SIM①_月3投稿!D29 -> 46264.416 | D8: =+SIM①_月3投稿!G29 -> 46780.758 | E8: =+SIM①_月3投稿!J29 -> 46347.407
A10: メッセ通数 | C10: =+SIM①_月3投稿!D34 -> 185057.66 | D10: =+SIM①_月3投稿!G34 -> 117856.13 | E10: =+SIM①_月3投稿!J34 -> 94673.42
A11: サイト流入数（LINEから） | C11: =+SIM①_月3投稿!D35 -> 5417.3781 | D11: =+SIM①_月3投稿!G35 -> 27742.043 | E11: =+SIM①_月3投稿!J35 -> 22317.56
A12: 想定CPC（LINEOA施策）_成果報酬プラン | C12: =+IFERROR(C5/C11,0) -> 0 | D12: =+D4/D11 -> 11.122771 | E12: =+E4/E11 -> 10.709964
A13: 想定CPC（LINEOA施策）_固定運用プラン | C13: =+IFERROR(C6/C12,0) -> 0 | D13: =+D5/D11 -> 21.936682 | E13: =+E5/E11 -> 24.152293
R14: ■従量計算式↓
A15: 応募（サイト全体・月） | C15: =+SIM①_月3投稿!D16 -> 400 | D15: =+SIM①_月3投稿!G16 -> 400 | E15: =+SIM①_月3投稿!J16 -> 400 | R15: ■料金テーブル
A16: 応募（+LINEOA施策） | C16: =+C17 -> 0 | D16: =+D17 -> 153 | E16: =+E17 -> 201 | R16: 課金対象配信総数 | V16: 費用 | Y16: 単価
A17: CV①_応募（LINE経由） | C17: =+SIM①_月3投稿!D36 -> 0 | D17: =+SIM①_月3投稿!G36 -> 153 | E17: =+SIM①_月3投稿!J36 -> 201 | R17: 0 | S17: - | T17: 200000 | V17: 0 | W17: - | X17: 600000 | Y17: 3
A18: - | C18: =+SIM①_月3投稿!D37 -> 0 | D18: =+SIM①_月3投稿!G37 -> 0 | E18: =+SIM①_月3投稿!J37 -> 0 | R18: 200000 | S18: - | T18: 15000000 | V18: 600000 | W18: - | X18: =+T18*2.5 -> 37500000 | Y18: 2.5
A19: - | C19: =+SIM①_月3投稿!D38 -> 0 | D19: =+SIM①_月3投稿!G38 -> 0 | E19: =+SIM①_月3投稿!J38 -> 0
A20: - | C20: =+SIM①_月3投稿!D39 -> 0 | D20: =+SIM①_月3投稿!G39 -> 0 | E20: =+SIM①_月3投稿!J39 -> 0
A22: 成果報酬プラン_CPA（単純計算） | C22: =+IFERROR(C4/C16,"--") -> -- | D22: =+IFERROR(D4/D16,"--") -> 2016.7869 | E22: =+IFERROR(E4/E16,"--") -> 1189.1555
A23: 固定費プラン_CPA（単純計算） | C23: =+IFERROR(C5/C16,"--") -> -- | D23: =+IFERROR(D5/D16,"--") -> 3977.5712 | E23: =+IFERROR(E5/E16,"--") -> 2681.6928
A25: 備考_合計コスト(従量課金) ※アカウント費用 | C25: =+SIM①_月3投稿!E68+C29*C30 -> 480172.99 | D25: =+SIM①_月3投稿!G68+D29*D30 -> 278568.39 | E25: =+SIM①_月3投稿!J68+E29*E30 -> 209020.26
A29: 従量課金対象単価 | C29: =+IF(C10<=30000,0,C10-30000) -> 155057.66 | D29: =+IF(D10<=30000,0,D10-30000) -> 87856.13 | E29: =+IF(E10<=30000,0,E10-30000) -> 64673.42
A30: 備考単価 | C30: =+IF(C29<=$T$17,$Y$17,IF(C29<=$T$18,$Y$18,IF(C29<=$T$19,$Y$19,IF(C29<=$T$20,$Y$20,IF(C29<=$T$21,$Y$21,IF(C29<=$T$22,$Y$22,IF(C29<=$T$23,$Y$23,IF(C29<=$T$24,$Y$24,IF(C29<=$T$25,$Y$25,IF(C29<=$T$26,$Y$26,IF(C29<=$T$27,$Y$27,IF(C29<=$T$28,$Y$28,IF(C29<=$T$29,$Y$29,0))))))))))))) -> 3 | D30: =+IF(D29<=$T$17,$Y$17,IF(D29<=$T$18,$Y$18,IF(D29<=$T$19,$Y$19,IF(D29<=$T$20,$Y$20,IF(D29<=$T$21,$Y$21,IF(D29<=$T$22,$Y$22,IF(D29<=$T$23,$Y$23,IF(D29<=$T$24,$Y$24,IF(D29<=$T$25,$Y$25,IF(D29<=$T$26,$Y$26,IF(D29<=$T$27,$Y$27,IF(D29<=$T$28,$Y$28,IF(D29<=$T$29,$Y$29,0))))))))))))) -> 3 | E30: =+IF(E29<=$T$17,$Y$17,IF(E29<=$T$18,$Y$18,IF(E29<=$T$19,$Y$19,IF(E29<=$T$20,$Y$20,IF(E29<=$T$21,$Y$21,IF(E29<=$T$22,$Y$22,IF(E29<=$T$23,$Y$23,IF(E29<=$T$24,$Y$24,IF(E29<=$T$25,$Y$25,IF(E29<=$T$26,$Y$26,IF(E29<=$T$27,$Y$27,IF(E29<=$T$28,$Y$28,IF(E29<=$T$29,$Y$29,0))))))))))))) -> 3
A35: 階層別 | C35: 母数 | D35: 誘導率 | E35: 想定CVR | F35: 想定CVR

Sheet SIM②_月5投稿
A2: Ver. | B2: 46321
A4: 株式会社ワクトリ御中_LINEOA施策提案【SIM】プラン②（月5投稿）：ポップアップ
N5: ※これより→はPDFにするときに消すようにする（範囲外に）
A7: ■要件定義 | B7: 地点 | C7: 名称 | D7: 成果単価
A8: 新規CV | B8: ①_CV地点 | C8: 応募 | D8: 0 | G8: UU | H8: 85887 | J8: 想定顧客リスト | K8: 0 | N8: CV＝応募（サイトの「ENTRY」と求人ページの「応募」は同じ登録フォーム）。LINE経由は計測用のフォームで数える。成果報酬型の単価 4,000円（仮） | O8: ※メルマガ、他SNS等でのリリースが出来るか
B9: ②_CV地点 | C9: - | D9: 0 | G9: 広告・アフィUU | H9: 0 | N9: 広告比率等を参考に | O9: LINEプレスリリースの可否 | P9: FALSE
A10: リピートCV | B10: ③_CV地点 | C10: - | D10: 0 | G10: 応募（月） | H10: 400 | I10: リード（イメージ） | N10: サイトからの応募は与件に無いので、仮に月400件（広告費 月約250万円÷1件あたり約6,000円の目安）＝サンクスLINEの母数
B11: ④_CV地点 | C11: - | D11: 0 | G11: - | H11: 0 | I11: マネタイズ（イメージ）
O12: ↓調整可能です！
A13: 項目 | D13: ※↓現状数値 | E13: 1か月目 | F13: 2か月目 | G13: 3か月目 | H13: 4か月目 | I13: 5か月目 | J13: 6か月目 | K13: 半年合計 | L13: 単月平均（６ヶ月） | N13: 20%くらいの調整は可能です。 | O13: →DYM作業用
A14: WEBサイト | B14: UU全体 | D14: =+H8 -> 85887 | E14: =+D14 -> 85887 | F14: =+E14 -> 85887 | G14: =+F14 -> 85887 | H14: =+G14 -> 85887 | I14: =+H14 -> 85887 | J14: =+I14 -> 85887
B15: UU(うち広告) | D15: =+H9 -> 0 | E15: =+D15 -> 0 | F15: =+E15 -> 0 | G15: =+F15 -> 0 | H15: =+G15 -> 0 | I15: =+H15 -> 0 | J15: =+I15 -> 0 | N15: 広告UUは不明なので0（UU全体をサイトのLINEボタン0.5%・ポップアップの式で計算） | O15: AD以外のLINE誘導 | P15: 0.005 | S15: ■従量計算式↓
B16: CV（別施策） ※想定 | D16: =H10 -> 400 | E16: =+D16 -> 400 | F16: =+E16 -> 400 | G16: =+F16 -> 400 | H16: =+G16 -> 400 | I16: =+H16 -> 400 | J16: =+I16 -> 400 | N16: （サイト固定リンク） | O16: ADでのLP/HP→LINE | P16: 0.0025 | S16: ■料金テーブル
A17: 施策 | B17: CPF | D17: FALSE | E17: FALSE | F17: FALSE | G17: FALSE | H17: FALSE | I17: FALSE | J17: FALSE | K17: -- | L17: -- | S17: 課金対象配信総数 | W17: 費用 | Z17: 単価
B18: 離脱防止 | D18: FALSE | E18: TRUE | F18: TRUE | G18: TRUE | H18: TRUE | I18: TRUE | J18: TRUE | K18: -- | L18: -- | N18: ポップアップ＝UU×表示55%×クリック12%×追加12%（FMTの式） | O18: 離脱防止表示率（AD） | P18: 0.65 | S18: 0 | T18: - | U18: 200000 | W18: 0 | X18: - | Y18: 600000 | Z18: 3
B19: サンクスLINE誘導 | D19: FALSE | E19: FALSE | F19: FALSE | G19: FALSE | H19: FALSE | I19: FALSE | J19: FALSE | N19: KaiU表示率 | O19: 離脱防止表示率（SEO） | P19: 0.55 | S19: 200000 | T19: - | U19: 15000000 | W19: 600000 | X19: - | Y19: =+U19*2.5 -> 37500000 | Z19: 2.5
B20: 通知メッセージ_CV | D20: FALSE | E20: FALSE | F20: FALSE | G20: FALSE | H20: FALSE | I20: FALSE | J20: FALSE
B21: 通知メッセージ_既存リスト | D21: FALSE | E21: FALSE | F21: FALSE | G21: FALSE | H21: FALSE | I21: FALSE | J21: FALSE | K21: -- | L21: -- | O21: ↓企画投稿
A22: 施策増分 ※友だち | B22: CPF | D22: -- | E22: 0 | F22: 0 | G22: 0 | H22: 0 | I22: 0 | J22: 0 | N22: 友だち追加広告（CPF）は入れていない | O22: 開封率 | P22: 0.78
B23: 離脱防止 | D23: -- | E23: =IF(E18=FALSE,0,E15*$P$18*0.08*0.08+(E14-E15)*$P$19*0.12*0.12) -> 680.22504 | F23: =IF(F18=FALSE,0,F15*$P$18*0.08*0.08+(F14-F15)*$P$19*0.12*0.12) -> 680.22504 | G23: =F23*1.01 -> 687.02729 | H23: =G23*1.01 -> 693.89756 | I23: =H23*1.01 -> 700.83654 | J23: =I23*1.01 -> 707.8449 | N23: 離脱防止表示率×UU×クリック率×実追加率 | O23: クリック率 | P23: 0.1 | Q23: 4‐6か月後係数
B24: サンクスLINE誘導 | D24: -- | E24: =IF(E19=FALSE,0,$H$10*0.8*0.45) -> 0 | F24: =IF(F19=FALSE,0,$H$10*0.8*0.45) -> 0 | G24: =IF(G19=FALSE,0,$H$10*0.8*0.45) -> 0 | H24: =IF(H19=FALSE,0,$H$10*0.8*0.45) -> 0 | I24: =IF(I19=FALSE,0,$H$10*0.8*0.45) -> 0 | J24: =IF(J19=FALSE,0,$H$10*0.8*0.45) -> 0 | N24: サンクスLINE誘導はオプション（このプランのSIMには入れていない） | O24: audienceターゲ率 | P24: 0.8 | Q24: 0.8
B25: 通知メッセージ | D25: -- | E25: =+IF(E20=FALSE,0,SUM($H$10:$H$11)*0.7*0.3)+IF($E$21=FALSE,0,$K$8*0.15*0.15) -> 0 | F25: =+IF(F20=FALSE,0,SUM($H$10:$H$11)*0.7*0.3)+IF($E$21=FALSE,0,$K$8*0.15*0.15) -> 0 | G25: =+IF(G20=FALSE,0,SUM($H$10:$H$11)*0.7*0.3)+IF($E$21=FALSE,0,$K$8*0.15*0.15) -> 0 | H25: =+IF(H20=FALSE,0,SUM($H$10:$H$11)*0.7*0.3)+IF($E$21=FALSE,0,$K$8*0.15*0.15) -> 0 | I25: =+IF(I20=FALSE,0,SUM($H$10:$H$11)*0.7*0.3)+IF($E$21=FALSE,0,$K$8*0.15*0.15) -> 0 | J25: =+IF(J20=FALSE,0,SUM($H$10:$H$11)*0.7*0.3)+IF($E$21=FALSE,0,$K$8*0.15*0.15) -> 0 | N25: サンクス到達*情報一致率(70%前後)*実追加率 | O25: ↓ステップ配信
A26: 友だち数_増加数 | D26: -- | E26: =+SUM(E22:E25)+$H$9*$P$16+($H$8-$H$9)*$P$15+IF(P9=FALSE,0,$K$8*0.15*0.08) -> 1109.66 | F26: =+SUM(F22:F25)+$H$9*$P$16+($H$8-$H$9)*$P$15 -> 1109.66 | G26: =+SUM(G22:G25)+$H$9*$P$16+($H$8-$H$9)*$P$15 -> 1116.4623 | H26: =+SUM(H22:H25)+$H$9*$P$16+($H$8-$H$9)*$P$15 -> 1123.3326 | I26: =+SUM(I22:I25)+$H$9*$P$16+($H$8-$H$9)*$P$15 -> 1130.2715 | J26: =+SUM(J22:J25)+$H$9*$P$16+($H$8-$H$9)*$P$15 -> 1137.2799 | N26: サイトのLINEボタン（UU×0.5%・FMTのP15）＋ポップアップ＋サンクスLINE | O26: 開封率 | P26: 0.725
A27: ブロック率 | D27: 0.421 | E27: 0.421 | F27: =ROUND(E27*1.02,3) -> 0.429 | G27: =ROUND(F27*1.02,3) -> 0.438 | H27: =ROUND(G27*1.02,3) -> 0.447 | I27: =ROUND(H27*1.02,3) -> 0.456 | J27: =ROUND(I27*1.02,3) -> 0.465 | N27: ブロック率：今は不明なので仮に40%。その後は前の月×1.02 | O27: クリック率 | P27: 0.12 | Q27: 4‐6か月後係数
A28: 友だち数 | D28: 79904 | E28: =+D28+E26 -> 81013.66 | F28: =+E28+F26 -> 82123.32 | G28: =+F28+G26 -> 83239.782 | H28: =+G28+H26 -> 84363.115 | I28: =+H28+I26 -> 85493.386 | J28: =+I28+J26 -> 86630.666 | N28: 今の友だち 79,904人（プロフィールの表示・2026年10月） | O28: audienceターゲ率 | P28: 0.2 | Q28: 0.8
A29: ターゲット数 | D29: =+D28*(1-D27) -> 46264.416 | E29: =+E28*(1-E27) -> 46906.909 | F29: =+F28*(1-F27) -> 46892.416 | G29: =+G28*(1-G27) -> 46780.758 | H29: =+H28*(1-H27) -> 46652.803 | I29: =+I28*(1-I27) -> 46508.402 | J29: =+J28*(1-J27) -> 46347.407 | N29: ※ターゲット数の増加分が通常の増加分を超えないように調整する
A30: 企画投稿数 | D30: 4 | E30: 5 | F30: 5 | G30: 5 | H30: 5 | I30: 5 | J30: 5 | N30: 企画配信 月5本（開始時期・エリア別に出し分け。対象は有効な友だちの80%、4か月目から反応しない方を外してさらに8割）。今は週1回（月4本） | O30: CPFの単価設定
A31: 企画投稿からの流入 | D31: =+D30*D29*0.75*0.41*0.07 | E31: =+E29*E30*$P$24*$P$22*$P$23*$P$36 -> 21427.039 | F31: =+F29*F30*$P$24*$P$22*$P$23*$P$36 -> 21420.418 | G31: =+G29*G30*$P$24*$P$22*$P$23*$P$36 -> 21369.413 | H31: =+H29*H30*$P$24*$P$22*$P$23*$P$36*$Q$24 -> 17048.77 | I31: =+I29*I30*$P$24*$P$22*$P$23*$P$36*$Q$24 -> 16996.001 | J31: =+J29*J30*$P$24*$P$22*$P$23*$P$36*$Q$24 -> 16937.167
A32: ステップ配信本数 | D32: 0 | E32: 5 | F32: 5 | G32: 5 | H32: 5 | I32: 5 | J32: 5 | N32: ステップ配信5通（友だち追加から15日以内）。対象＝その月の新しい友だち（サンクスLINEで追加した応募済みの方は除く） | O32: 特典の強さ | P32: TRUE | Q32: =+IF(P32=TRUE,1.1,0.95) -> 1.1
A33: ステップ配信からの流入 | D33: 0 | E33: =+(E26-E24)*E32*$P$26*$P$27*$P$36 -> 706.72417 | F33: =+(F26-F24)*F32*$P$26*$P$27*$P$36 -> 706.72417 | G33: =+(G26-G24)*G32*$P$26*$P$27*$P$36 -> 711.05641 | H33: =+(H26-H24)*H32*$P$26*$P$27*$P$36 -> 715.43197 | I33: =+(I26-I24)*I32*$P$26*$P$27*$P$36 -> 719.85129 | J33: =+(J26-J24)*J32*$P$26*$P$27*$P$36 -> 724.31481 | O33: クリエイティブ強さ | P33: TRUE | Q33: =+IF(P33=TRUE,1.1,0.95) -> 1.1
A34: 配信数 | D34: =+D29*D30*0.75 | E34: =+E29*E30*$P$24+E26*E32 -> 193175.94 | F34: =+F29*F30*$P$24+F26*F32 -> 193117.96 | G34: =+G29*G30*$P$24+G26*G32 -> 192705.34 | H34: =+H29*H30*$P$24*$Q$24+H26*H32 -> 154905.63 | I34: =+I29*I30*$P$24*$Q$24+I26*I32 -> 154478.24 | J34: =+J29*J30*$P$24*$Q$24+J26*J32 -> 153998.1 | O34: 知名度強さ | P34: TRUE | Q34: =+IF(P34=TRUE,1.1,0.95) -> 1.1
A35: 想定Click数 | D35: =+D31*1.02 -> 5417.3781 | E35: =+E31+E33+1.05*(E31+E33) -> 45374.214 | F35: =+F31+F33+1.05*(F31+F33) -> 45360.641 | G35: =+G31+G33+1.05*(G31+G33) -> 45264.962 | H35: =+H31+H33+1.05*(H31+H33) -> 36416.615 | I35: =+I31+I33+1.05*(I31+I33) -> 36317.497 | J35: =+J31+J33+1.05*(J31+J33) -> 36206.037 | O35: 動線の強さ | P35: TRUE | Q35: =+IF(P35=TRUE,1.1,0.95) -> 1.1
A36: 新規CV | B36: =+C8 -> 応募 | D36: 0 | E36: =ROUND(E35*0.004,0) -> 181 | F36: =ROUND(F35*0.0045,0) -> 204 | G36: =ROUND(G35*0.0055,0) -> 249 | H36: =ROUND(H35*0.0065,0) -> 237 | I36: =ROUND(I35*0.0075,0) -> 272 | J36: =ROUND(J35*0.009,0) -> 326 | K36: =SUM(E36:J36) -> 1469 | N36: 応募＝想定クリック×0.3〜0.6%（運用が育つ想定で月ごとに上げる）。サンクスLINEで追加した方は応募済みなので数えない | O36: 想定の係数（反応率） | P36: =1*(Q32*Q33*Q34*Q35) -> 1.4641
B37: =+C9 -> - | D37: 0 | E37: 0 | F37: 0 | G37: 0 | H37: 0 | I37: 0 | J37: 0 | K37: =SUM(E37:J37) -> 0 | N37: 新規向け_
A38: リピートCV | B38: =+C10 -> - | D38: 0 | E38: 0 | F38: 0 | G38: 0 | H38: 0 | I38: 0 | J38: 0 | K38: =SUM(E38:J38) -> 0 | N38: 既存向け_休眠顧客向け | O38: ※①＞②で作成
B39: =+C11 -> - | D39: 0 | E39: 0 | F39: 0 | G39: 0 | H39: 0 | I39: 0 | J39: 0 | K39: =SUM(E39:J39) -> 0 | N39: 既存向け_休眠顧客向け | O39: ※③＞④で作成
A40: 合計CV | D40: =+SUM(D36:D39) -> 0 | E40: =+SUM(E36:E39) -> 181 | F40: =+SUM(F36:F39) -> 204 | G40: =+SUM(G36:G39) -> 249 | H40: =+SUM(H36:H39) -> 237 | I40: =+SUM(I36:I39) -> 272 | J40: =+SUM(J36:J39) -> 326 | K40: =SUM(E40:J40) -> 1469
B41: CVR | D41: =+IFERROR(D40/D35,0) -> 0 | E41: =+IFERROR(E40/E35,0) -> 0.0039890498 | F41: =+IFERROR(F40/F35,0) -> 0.0044972909 | G41: =+IFERROR(G40/G35,0) -> 0.0055009436 | H41: =+IFERROR(H40/H35,0) -> 0.0065080184 | I41: =+IFERROR(I40/I35,0) -> 0.007489503 | J41: =+IFERROR(J40/J35,0) -> 0.0090040233 | N41: CV/流入数で計算、0.3%〜1%とかで推移。
A43: ■成果報酬運営 | C43: 現状数値 | D43: 初期
A44: 従量課金 | D44: -- | E44: =+E75*E76 -> 489527.81 | F44: =+F75*F76 -> 489353.89 | G44: =+G75*G76 -> 488116.03 | H44: =+H75*H76 -> 374716.89 | I44: =+I75*I76 -> 373434.73 | J44: =+J75*J76 -> 371994.3
...

Sheet SIM②_比較
E1: →通数減らすように係数： | F1: 0.6
A3: 比較項目 | C3: DYM実装前 | D3: DYM実装後（③か月） | E3: DYM実装後（⑥か月）
A4: コスト想定 ※月額（成果報酬プラン） | C4: =+SIM②_月5投稿!D24 -> -- | D4: =+SIM②_月5投稿!G51 -> 533116.03 | E4: =+SIM②_月5投稿!J51 -> 416994.3
A5: コスト想定 ※月額（固定プラン） | C5: =+SIM②_月5投稿!D25 -> -- | D5: =+SIM②_月5投稿!G61 -> 883116.03 | E5: =+SIM②_月5投稿!J61 -> 766994.3
A6: 友だち数想定 | C6: =+SIM②_月5投稿!D28 -> 79904 | D6: =+SIM②_月5投稿!G28 -> 83239.782 | E6: =+SIM②_月5投稿!J28 -> 86630.666
A7: ブロック率想定 | C7: =+SIM②_月5投稿!D27 -> 0.421 | D7: =+SIM②_月5投稿!G27 -> 0.438 | E7: =+SIM②_月5投稿!J27 -> 0.465
A8: 友だち数（アクティブ）想定 | C8: =+SIM②_月5投稿!D29 -> 46264.416 | D8: =+SIM②_月5投稿!G29 -> 46780.758 | E8: =+SIM②_月5投稿!J29 -> 46347.407
A10: メッセ通数 | C10: =+SIM②_月5投稿!D34 -> 185057.66 | D10: =+SIM②_月5投稿!G34 -> 192705.34 | E10: =+SIM②_月5投稿!J34 -> 153998.1
A11: サイト流入数（LINEから） | C11: =+SIM②_月5投稿!D35 -> 5417.3781 | D11: =+SIM②_月5投稿!G35 -> 45264.962 | E11: =+SIM②_月5投稿!J35 -> 36206.037
A12: 想定CPC（LINEOA施策）_成果報酬プラン | C12: =+IFERROR(C5/C11,0) -> 0 | D12: =+D4/D11 -> 11.777675 | E12: =+E4/E11 -> 11.517259
A13: 想定CPC（LINEOA施策）_固定運用プラン | C13: =+IFERROR(C6/C12,0) -> 0 | D13: =+D5/D11 -> 19.509925 | E13: =+E5/E11 -> 21.184155
R14: ■従量計算式↓
A15: 応募（サイト全体・月） | C15: =+SIM②_月5投稿!D16 -> 400 | D15: =+SIM②_月5投稿!G16 -> 400 | E15: =+SIM②_月5投稿!J16 -> 400 | R15: ■料金テーブル
A16: 応募（+LINEOA施策） | C16: =+C17 -> 0 | D16: =+D17 -> 249 | E16: =+E17 -> 326 | R16: 課金対象配信総数 | V16: 費用 | Y16: 単価
A17: CV①_応募（LINE経由） | C17: =+SIM②_月5投稿!D36 -> 0 | D17: =+SIM②_月5投稿!G36 -> 249 | E17: =+SIM②_月5投稿!J36 -> 326 | R17: 0 | S17: - | T17: 200000 | V17: 0 | W17: - | X17: 600000 | Y17: 3
A18: - | C18: =+SIM②_月5投稿!D37 -> 0 | D18: =+SIM②_月5投稿!G37 -> 0 | E18: =+SIM②_月5投稿!J37 -> 0 | R18: 200000 | S18: - | T18: 15000000 | V18: 600000 | W18: - | X18: =+T18*2.5 -> 37500000 | Y18: 2.5
A19: - | C19: =+SIM②_月5投稿!D38 -> 0 | D19: =+SIM②_月5投稿!G38 -> 0 | E19: =+SIM②_月5投稿!J38 -> 0
A20: - | C20: =+SIM②_月5投稿!D39 -> 0 | D20: =+SIM②_月5投稿!G39 -> 0 | E20: =+SIM②_月5投稿!J39 -> 0
A22: 成果報酬プラン_CPA（単純計算） | C22: =+IFERROR(C4/C16,"--") -> -- | D22: =+IFERROR(D4/D16,"--") -> 2141.0282 | E22: =+IFERROR(E4/E16,"--") -> 1279.1236
A23: 固定費プラン_CPA（単純計算） | C23: =+IFERROR(C5/C16,"--") -> -- | D23: =+IFERROR(D5/D16,"--") -> 3546.6507 | E23: =+IFERROR(E5/E16,"--") -> 2352.7433
A25: 備考_合計コスト(従量課金) ※アカウント費用 | C25: =+SIM②_月5投稿!E68+C29*C30 -> 480172.99 | D25: =+SIM②_月5投稿!G68+D29*D30 -> 503116.03 | E25: =+SIM②_月5投稿!J68+E29*E30 -> 386994.3
A29: 従量課金対象単価 | C29: =+IF(C10<=30000,0,C10-30000) -> 155057.66 | D29: =+IF(D10<=30000,0,D10-30000) -> 162705.34 | E29: =+IF(E10<=30000,0,E10-30000) -> 123998.1
A30: 備考単価 | C30: =+IF(C29<=$T$17,$Y$17,IF(C29<=$T$18,$Y$18,IF(C29<=$T$19,$Y$19,IF(C29<=$T$20,$Y$20,IF(C29<=$T$21,$Y$21,IF(C29<=$T$22,$Y$22,IF(C29<=$T$23,$Y$23,IF(C29<=$T$24,$Y$24,IF(C29<=$T$25,$Y$25,IF(C29<=$T$26,$Y$26,IF(C29<=$T$27,$Y$27,IF(C29<=$T$28,$Y$28,IF(C29<=$T$29,$Y$29,0))))))))))))) -> 3 | D30: =+IF(D29<=$T$17,$Y$17,IF(D29<=$T$18,$Y$18,IF(D29<=$T$19,$Y$19,IF(D29<=$T$20,$Y$20,IF(D29<=$T$21,$Y$21,IF(D29<=$T$22,$Y$22,IF(D29<=$T$23,$Y$23,IF(D29<=$T$24,$Y$24,IF(D29<=$T$25,$Y$25,IF(D29<=$T$26,$Y$26,IF(D29<=$T$27,$Y$27,IF(D29<=$T$28,$Y$28,IF(D29<=$T$29,$Y$29,0))))))))))))) -> 3 | E30: =+IF(E29<=$T$17,$Y$17,IF(E29<=$T$18,$Y$18,IF(E29<=$T$19,$Y$19,IF(E29<=$T$20,$Y$20,IF(E29<=$T$21,$Y$21,IF(E29<=$T$22,$Y$22,IF(E29<=$T$23,$Y$23,IF(E29<=$T$24,$Y$24,IF(E29<=$T$25,$Y$25,IF(E29<=$T$26,$Y$26,IF(E29<=$T$27,$Y$27,IF(E29<=$T$28,$Y$28,IF(E29<=$T$29,$Y$29,0))))))))))))) -> 3
A35: 階層別 | C35: 母数 | D35: 誘導率 | E35: 想定CVR | F35: 想定CVR

Sheet SIM考え方
A2: 友だち数_増加施策
A3: 離脱防止 ※
A4: 掲載率 | B4: ※サイト構成、要望により変動 | E4: 1000
A5: クリック率 | B5: 0.085
A6: 追加率 | B6: 0.08
E7: =+E4*B5*B6 -> 6.8
A8: サイト→LINEの導線の改善 ※
A9: 掲載率 | B9: ※サイト構成、要望により変動 | E9: 1000
A10: クリック率 | B10: 0.005
A11: 追加率 | B11: 0.08
E12: =+E9*B10*B11 -> 0.4
A13: サンクスページ誘導 ※ | D13: ただCVが増えるわけではない
A14: 掲載数 | B14: ※サイト構成、要望により変動 | E14: 1000
A15: クリック率 | B15: 0.9 | C15: ※カウントしない
A16: 追加率 | B16: 0.35
E17: =+E14*B15*B16 -> 315
A18: 通知メッセの改善 ※ | D18: ただCVが増えるわけではない
A19: 掲載率 | B19: 0.7 | C19: ※サイト構成、要望により変動 | E19: 1000
A20: クリック率 | B20: 1
A21: 追加率 | B21: 0.2
E22: =+E19*B20*B21 -> 200
A23: 配信効率改善施策 | C23: ※具体的なセグメントの仕方、企画により変動 | I23: 課金
A24: > 通常メッセ | I24: 1 | J24: 企画投稿（セグメントor一斉配信）
A25: 開封率 | B25: 0.8 | I25: 2 | J25: 追いメッセージ（ステップ、シナリオ）
A26: クリック率 | B26: 0.06 | I26: 3 | J26: VOOM投稿 ※同時進行の場合が多い
A27: CV率 | B27: 0.003 | I27: 4 | J27: 通知メッセージ（1通7円くらいの想定） ※機能導入が必要 ※ツール費：月8万～
A29: > 追いメッセ（ステップ、シナリオ） | I29: 非課金
A30: 開封率 | B30: 0.75 | I30: 1 | J30: 自動の即時応答
A31: クリック率 | B31: 0.08 | I31: 2 | J31: 個別チャット対応
A32: CV率 | B32: 0.006 | I32: 3 | J32: あいさつメッセージ
I33: 4 | J33: （リッチメニュー）
A34: > その他（リッチメニュー）
A35: 開封率 | B35: --
A36: クリック率 | B36: 0.02
A37: CV率 | B37: 0.004
A39: >挨拶メッセ | E39: >挨拶メッセ（アンケート回答率）
A40: 開封率 | B40: 1 | E40: 開封率 | F40: --
A41: クリック率 | B41: 0.035 | E41: 回答率 | F41: 0.25
A42: CV率 | B42: 0.006
