Workbook

Sheet SIM①_コンサル
A2: Ver. | B2: 46315
A4: 株式会社横浜シミズ御中_LINEOA施策提案【SIM】コンサル（サイトのLINEボタン＋離脱防止＋サンクスLINE誘導）
N5: ※これより→はPDFにするときに消すようにする（範囲外に）
A7: ■要件定義 | B7: 地点 | C7: 名称 | D7: 成果単価
A8: 新規CV | B8: ①_CV地点 | C8: 新規応募 | D8: 0 | G8: サイトUU | H8: 8947 | J8: 想定顧客リスト | K8: 0 | N8: CV①新規応募：サイトのLINEボタン・離脱防止で友だちになった方（応募前）が、配信から応募した数。サンクスLINE誘導で友だちになった方は応募済みなので、新規応募には数えない | O8: ※メルマガ、他SNS等でのリリースが出来るか
B9: ②_CV地点 | C9: - | D9: 0 | G9: うち広告 | H9: 0 | N9: 広告比率等を参考に | O9: LINEプレスリリースの可否 | P9: FALSE
A10: リピートCV | B10: ③_CV地点 | C10: 再応募 | D10: 0 | G10: 応募（サイト・仮に） | H10: 150 | I10: リード（イメージ） | N10: サイトからの応募は、仮に月150件（新規登録は月約300人＝マイナビの求人10件×1件30人×4週ごと。そのうち自社サイトからの応募を半分と置いた。マイナビ経由はマイナビの完了画面で終わるので、サンクスLINE誘導の母数に入れない）
B11: ④_CV地点 | C11: - | D11: 0 | G11: CV（別施策）2 | H11: 0 | I11: マネタイズ（イメージ）
O12: ↓調整可能です！
A13: 項目 | D13: ※↓現状数値 | E13: 1か月目 | F13: 2か月目 | G13: 3か月目 | H13: 4か月目 | I13: 5か月目 | J13: 6か月目 | K13: 半年合計 | L13: 単月平均（６ヶ月） | N13: 20%くらいの調整は可能です。 | O13: →DYM作業用
A14: WEBサイト | B14: UU全体 | D14: =+H8 | E14: =+D14 | F14: =+E14 | G14: =+F14 | H14: =+G14 | I14: =+H14 | J14: =+I14 | N14: 求人サイトの月間UU 8,947（与件）。6か月同じ
B15: UU(うち広告) | D15: =+H9 | E15: =+D15 | F15: =+E15 | G15: =+F15 | H15: =+G15 | I15: =+H15 | J15: =+I15 | N15: （サイト固定リンク） | O15: AD以外のLINE誘導 | P15: 0.005 | S15: ■従量計算式↓
B16: CV（別施策） ※想定 | D16: =H10 | E16: =+D16 | F16: =+E16 | G16: =+F16 | H16: =+G16 | I16: =+H16 | J16: =+I16 | N16: （サイト固定リンク） | O16: ADでのLP/HP→LINE | P16: 0.0025 | S16: ■料金テーブル
A17: 施策 | B17: CPF | D17: FALSE | E17: FALSE | F17: FALSE | G17: FALSE | H17: FALSE | I17: FALSE | J17: FALSE | K17: -- | L17: -- | S17: 課金対象配信総数 | W17: 費用 | Z17: 単価
B18: 離脱防止ポップアップ | D18: FALSE | E18: TRUE | F18: TRUE | G18: TRUE | H18: TRUE | I18: TRUE | J18: TRUE | K18: -- | L18: -- | N18: KaiU表示率 | O18: 離脱防止表示率（AD） | P18: 0.65 | S18: 0 | T18: - | U18: 200000 | W18: 0 | X18: - | Y18: 600000 | Z18: 3
B19: サンクスLINE誘導 | D19: FALSE | E19: TRUE | F19: TRUE | G19: TRUE | H19: TRUE | I19: TRUE | J19: TRUE | N19: KaiU表示率 | O19: 離脱防止表示率（SEO） | P19: 0.55 | S19: 200000 | T19: - | U19: 15000000 | W19: 600000 | X19: - | Y19: =+U19*2.5 | Z19: 2.5
B20: 通知メッセージ_CV | D20: FALSE | E20: FALSE | F20: FALSE | G20: FALSE | H20: FALSE | I20: FALSE | J20: FALSE
B21: 通知メッセージ_既存リスト | D21: FALSE | E21: FALSE | F21: FALSE | G21: FALSE | H21: FALSE | I21: FALSE | J21: FALSE | K21: -- | L21: -- | O21: ↓企画投稿
A22: 施策増分 ※友だち | B22: CPF | D22: -- | E22: 0 | F22: 0 | G22: 0 | H22: 0 | I22: 0 | J22: 0 | N22: CPFコスト / CPFの単価設定 ※ブロック率が上がりやすい | O22: 開封率 | P22: 0.78
B23: 離脱防止ポップアップ | D23: -- | E23: =IF(E18=FALSE,0,E14*$P$18*0.125*0.125) | F23: =IF(F18=FALSE,0,F14*$P$18*0.125*0.125) | G23: =IF(G18=FALSE,0,G14*$P$18*0.125*0.125) | H23: =IF(H18=FALSE,0,H14*$P$18*0.125*0.125) | I23: =IF(I18=FALSE,0,I14*$P$18*0.125*0.125) | J23: =IF(J18=FALSE,0,J14*$P$18*0.125*0.125) | N23: 離脱防止ポップアップ＝UU×表示65%×クリック12.5%×追加12.5%（定義テキストの係数） | O23: クリック率 | P23: 0.1 | Q23: 4‐6か月後係数
B24: サンクスLINE誘導 | D24: -- | E24: =IF(E19=FALSE,0,E16*0.8*0.4) | F24: =IF(F19=FALSE,0,F16*0.8*0.4) | G24: =IF(G19=FALSE,0,G16*0.8*0.4) | H24: =IF(H19=FALSE,0,H16*0.8*0.4) | I24: =IF(I19=FALSE,0,I16*0.8*0.4) | J24: =IF(J19=FALSE,0,J16*0.8*0.4) | N24: サンクスLINE誘導＝応募×遷移80%×追加40%（資料と同じ・定義テキストの係数） | O24: audienceターゲ率 | P24: 0.8 | Q24: 0.8
B25: 通知メッセージ | D25: -- | E25: =+IF(E20=FALSE,0,SUM($H$10:$H$11)*0.7*0.3)+IF($E$21=FALSE,0,$K$8*0.15*0.15) | F25: =+IF(F20=FALSE,0,SUM($H$10:$H$11)*0.7*0.3)+IF($E$21=FALSE,0,$K$8*0.15*0.15) | G25: =+IF(G20=FALSE,0,SUM($H$10:$H$11)*0.7*0.3)+IF($E$21=FALSE,0,$K$8*0.15*0.15) | H25: =+IF(H20=FALSE,0,SUM($H$10:$H$11)*0.7*0.3)+IF($E$21=FALSE,0,$K$8*0.15*0.15) | I25: =+IF(I20=FALSE,0,SUM($H$10:$H$11)*0.7*0.3)+IF($E$21=FALSE,0,$K$8*0.15*0.15) | J25: =+IF(J20=FALSE,0,SUM($H$10:$H$11)*0.7*0.3)+IF($E$21=FALSE,0,$K$8*0.15*0.15) | N25: サンクス到達*情報一致率(70%前後)*実追加率 | O25: ↓ステップ配信
A26: 友だち数_増加数 | D26: -- | E26: =+SUM(E22:E25)+$H$9*$P$16+($H$8-$H$9)*$P$15+IF(P9=FALSE,0,$K$8*0.15*0.08) | F26: =+SUM(F22:F25)+$H$9*$P$16+($H$8-$H$9)*$P$15 | G26: =+SUM(G22:G25)+$H$9*$P$16+($H$8-$H$9)*$P$15 | H26: =+SUM(H22:H25)+$H$9*$P$16+($H$8-$H$9)*$P$15 | I26: =+SUM(I22:I25)+$H$9*$P$16+($H$8-$H$9)*$P$15 | J26: =+SUM(J22:J25)+$H$9*$P$16+($H$8-$H$9)*$P$15 | N26: サイトのLINEボタン（UUの0.5%・FMTの係数）＋離脱防止ポップアップ＋サンクスLINE誘導 | O26: 開封率 | P26: 0.725
A27: ブロック率 | D27: 0 | E27: 0.32 | F27: =+E$27*1.025 | G27: =+F$27*1.025 | H27: =+G$27*1.025 | I27: =+H$27*1.025 | J27: =+I$27*1.025 | N27: ブロック率：1か月目（E27）から、2か月目以降は前の月×1.025（式） | O27: クリック率 | P27: 0.12 | Q27: 4‐6か月後係数
A28: 友だち数 | D28: 0 | E28: =+D28+E26 | F28: =+E28+F26 | G28: =+F28+G26 | H28: =+G28+H26 | I28: =+H28+I26 | J28: =+I28+J26 | O28: audienceターゲ率 | P28: 0.2 | Q28: 0.8
A29: ターゲット数 | D29: =+D28*(1-D27) | E29: =+E28*(1-E27) | F29: =+F28*(1-F27) | G29: =+G28*(1-G27) | H29: =+H28*(1-H27) | I29: =+I28*(1-I27) | J29: =+J28*(1-J27) | N29: ※ターゲット数の増加分が通常の増加分を超えないように調整する
A30: 企画投稿数 | D30: 0 | E30: 4 | F30: 4 | G30: 4 | H30: 4 | I30: 4 | J30: 4 | N30: 企画配信 月4回（週1回。次回イベントの募集・会場の案内） | O30: CPFの単価設定
A31: 企画投稿からの流入 | D31: =+D30*D29*0.41*0.07 | E31: =+E29*E30*$P$24*$P$22*$P$23*$P$36 | F31: =+F29*F30*$P$24*$P$22*$P$23*$P$36 | G31: =+G29*G30*$P$24*$P$22*$P$23*$P$36 | H31: =+H29*H30*$P$24*$P$22*$P$23*$P$36*$Q$24 | I31: =+I29*I30*$P$24*$P$22*$P$23*$P$36*$Q$24 | J31: =+J29*J30*$P$24*$P$22*$P$23*$P$36*$Q$24
A32: ステップ配信本数 | D32: 0 | E32: 4 | F32: 4 | G32: 4 | H32: 4 | I32: 4 | J32: 4 | N32: ステップ配信 4通（あいさつメッセージの後、友だち追加から14日以内） | O32: 特典の強さ | P32: TRUE | Q32: =+IF(P32=TRUE,1.1,0.95)
A33: ステップ配信からの流入 | D33: 0 | E33: =+E29*E32*$P$26*$P$27*$P$28*$P$36 | F33: =+F29*F32*$P$26*$P$27*$P$28*$P$36 | G33: =+G29*G32*$P$26*$P$27*$P$28*$P$36 | H33: =+H29*H32*$P$26*$P$27*$P$28*$P$36*$Q$28 | I33: =+I29*I32*$P$26*$P$27*$P$28*$P$36*$Q$28 | J33: =+J29*J32*$P$26*$P$27*$P$28*$P$36*$Q$28 | O33: クリエイティブ強さ | P33: TRUE | Q33: =+IF(P33=TRUE,1.1,0.95)
A34: 配信数 | D34: =+D29*D30 | E34: =+E29*E30*$P$24+E29*E32*$P$28 | F34: =+F29*F30*$P$24+F29*F32*$P$28 | G34: =+G29*G30*$P$24+G29*G32*$P$28 | H34: =+H29*H30*$P$24*$Q$24+H29*H32*$P$28*$Q$28 | I34: =+I29*I30*$P$24*$Q$24+I29*I32*$P$28*$Q$28 | J34: =+J29*J30*$P$24*$Q$24+J29*J32*$P$28*$Q$28 | O34: 知名度強さ | P34: TRUE | Q34: =+IF(P34=TRUE,1.1,0.95)
A35: 想定Click数 | D35: =+D31*1.02 | E35: =+E31+E33+1.05*(E31+E33) | F35: =+F31+F33+1.05*(F31+F33) | G35: =+G31+G33+1.05*(G31+G33) | H35: =+H31+H33+1.05*(H31+H33) | I35: =+I31+I33+1.05*(I31+I33) | J35: =+J31+J33+1.05*(J31+J33) | O35: 動線の強さ | P35: TRUE | Q35: =+IF(P35=TRUE,1.1,0.95)
A36: 新規CV | B36: =+C8 | D36: 0 | E36: 2 | F36: 2 | G36: 4 | H36: 5 | I36: 5 | J36: 6 | K36: =SUM(E36:J36) | N36: 新規応募：サイトのLINEボタン・離脱防止で友だちになった方が、企画配信・ステップ配信から応募した数 | O36: 想定の係数（反応率） | P36: =1*(Q32*Q33*Q34*Q35)
B37: =+C9 | D37: 0 | E37: 0 | F37: 0 | G37: 0 | H37: 0 | I37: 0 | J37: 0 | K37: =SUM(E37:J37) | N37: 新規向け_
A38: リピートCV | B38: =+C10 | D38: 0 | E38: 0 | F38: 0 | G38: 1 | H38: 2 | I38: 3 | J38: 3 | K38: =SUM(E38:J38) | N38: 再応募：一度勤務した方が、次回イベントの募集から勤務希望を出した数（応募→勤務を経てからなので3か月目から） | O38: ※①＞②で作成
B39: =+C11 | D39: 0 | E39: 0 | F39: 0 | G39: 0 | H39: 0 | I39: 0 | J39: 0 | K39: =SUM(E39:J39) | N39: 既存向け_休眠顧客向け | O39: ※③＞④で作成
A40: 合計CV | D40: =+SUM(D36:D39) | E40: =+SUM(E36:E39) | F40: =+SUM(F36:F39) | G40: =+SUM(G36:G39) | H40: =+SUM(H36:H39) | I40: =+SUM(I36:I39) | J40: =+SUM(J36:J39) | K40: =SUM(E40:J40)
B41: CVR | D41: =+IFERROR(D40/D35,0) | E41: =+IFERROR(E40/E35,0) | F41: =+IFERROR(F40/F35,0) | G41: =+IFERROR(G40/G35,0) | H41: =+IFERROR(H40/H35,0) | I41: =+IFERROR(I40/I35,0) | J41: =+IFERROR(J40/J35,0) | N41: CV/流入数で計算、0.3%〜1%とかで推移。
A43: ■成果報酬運営 | C43: 現状数値 | D43: 初期
A44: 従量課金 | D44: -- | E44: =+E75*E76 | F44: =+F75*F76 | G44: =+G75*G76 | H44: =+H75*H76 | I44: =+I75*I76 | J44: =+J75*J76
...

Sheet SIM①_比較
E1: →通数減らすように係数： | F1: 0.6
A3: 比較項目 | C3: DYM実装前 | D3: DYM実装後（③か月） | E3: DYM実装後（⑥か月）
A4: コスト想定 ※月額（成果報酬プラン） | C4: =+'SIM①_コンサル'!D24 | D4: =+'SIM①_コンサル'!G51 | E4: =+'SIM①_コンサル'!J51
A5: コスト想定 ※月額（固定プラン） | C5: =+'SIM①_コンサル'!D25 | D5: =+'SIM①_コンサル'!G61 | E5: =+'SIM①_コンサル'!J61
A6: 友だち数想定 | C6: =+'SIM①_コンサル'!D28 | D6: =+'SIM①_コンサル'!G28 | E6: =+'SIM①_コンサル'!J28
A7: ブロック率想定 | C7: =+'SIM①_コンサル'!D27 | D7: =+'SIM①_コンサル'!G27 | E7: =+'SIM①_コンサル'!J27
A8: 友だち数（アクティブ）想定 | C8: =+'SIM①_コンサル'!D29 | D8: =+'SIM①_コンサル'!G29 | E8: =+'SIM①_コンサル'!J29
A10: メッセ通数 | C10: =+'SIM①_コンサル'!D34 | D10: =+'SIM①_コンサル'!G34 | E10: =+'SIM①_コンサル'!J34
A11: サイト流入数（LINEから） | C11: =+'SIM①_コンサル'!D35 | D11: =+'SIM①_コンサル'!G35 | E11: =+'SIM①_コンサル'!J35
A12: 想定CPC（LINEOA施策）_成果報酬プラン | C12: =+IFERROR(C5/C11,0) | D12: =+D4/D11 | E12: =+E4/E11
A13: 想定CPC（LINEOA施策）_固定運用プラン | C13: =+IFERROR(C6/C12,0) | D13: =+D5/D11 | E13: =+E5/E11
R14: ■従量計算式↓
A15: 応募（サイト・仮に） | C15: =+'SIM①_コンサル'!$H$10 | D15: =+'SIM①_コンサル'!$H$10 | E15: =+'SIM①_コンサル'!$H$10 | R15: ■料金テーブル
A16: CV数（+LINEOA施策） | C16: =SUM(C17:C20) | D16: =SUM(D17:D20) | E16: =SUM(E17:E20) | R16: 課金対象配信総数 | V16: 費用 | Y16: 単価
A17: CV①_新規応募 | C17: =+'SIM①_コンサル'!D36 | D17: =+'SIM①_コンサル'!G36 | E17: =+'SIM①_コンサル'!J36 | R17: 0 | S17: - | T17: 200000 | V17: 0 | W17: - | X17: 600000 | Y17: 3
A18: - | C18: =+'SIM①_コンサル'!D37 | D18: =+'SIM①_コンサル'!G37 | E18: =+'SIM①_コンサル'!J37 | R18: 200000 | S18: - | T18: 15000000 | V18: 600000 | W18: - | X18: =+T18*2.5 | Y18: 2.5
A19: CV③_再応募 | C19: =+'SIM①_コンサル'!D38 | D19: =+'SIM①_コンサル'!G38 | E19: =+'SIM①_コンサル'!J38
A20: - | C20: =+'SIM①_コンサル'!D39 | D20: =+'SIM①_コンサル'!G39 | E20: =+'SIM①_コンサル'!J39
A22: 成果報酬プラン_CPA（単純計算） | C22: =+IFERROR(C4/C16,"--") | D22: =+IFERROR(D4/D16,"--") | E22: =+IFERROR(E4/E16,"--")
A23: 固定費プラン_CPA（単純計算） | C23: =+IFERROR(C5/C16,"--") | D23: =+IFERROR(D5/D16,"--") | E23: =+IFERROR(E5/E16,"--")
A25: 備考_合計コスト(従量課金) ※アカウント費用 | C25: =+'SIM①_コンサル'!E68+C29*C30 | D25: =+'SIM①_コンサル'!G68+D29*D30 | E25: =+'SIM①_コンサル'!J68+E29*E30
A29: 従量課金対象単価 | C29: =+IF(C10<=30000,0,C10-30000) | D29: =+IF(D10<=30000,0,D10-30000) | E29: =+IF(E10<=30000,0,E10-30000)
A30: 備考単価 | C30: =+IF(C29<=$T$17,$Y$17,IF(C29<=$T$18,$Y$18,IF(C29<=$T$19,$Y$19,IF(C29<=$T$20,$Y$20,IF(C29<=$T$21,$Y$21,IF(C29<=$T$22,$Y$22,IF(C29<=$T$23,$Y$23,IF(C29<=$T$24,$Y$24,IF(C29<=$T$25,$Y$25,IF(C29<=$T$26,$Y$26,IF(C29<=$T$27,$Y$27,IF(C29<=$T$28,$Y$28,IF(C29<=$T$29,$Y$29,0))))))))))))) | D30: =+IF(D29<=$T$17,$Y$17,IF(D29<=$T$18,$Y$18,IF(D29<=$T$19,$Y$19,IF(D29<=$T$20,$Y$20,IF(D29<=$T$21,$Y$21,IF(D29<=$T$22,$Y$22,IF(D29<=$T$23,$Y$23,IF(D29<=$T$24,$Y$24,IF(D29<=$T$25,$Y$25,IF(D29<=$T$26,$Y$26,IF(D29<=$T$27,$Y$27,IF(D29<=$T$28,$Y$28,IF(D29<=$T$29,$Y$29,0))))))))))))) | E30: =+IF(E29<=$T$17,$Y$17,IF(E29<=$T$18,$Y$18,IF(E29<=$T$19,$Y$19,IF(E29<=$T$20,$Y$20,IF(E29<=$T$21,$Y$21,IF(E29<=$T$22,$Y$22,IF(E29<=$T$23,$Y$23,IF(E29<=$T$24,$Y$24,IF(E29<=$T$25,$Y$25,IF(E29<=$T$26,$Y$26,IF(E29<=$T$27,$Y$27,IF(E29<=$T$28,$Y$28,IF(E29<=$T$29,$Y$29,0)))))))))))))
A35: 階層別 | C35: 母数 | D35: 誘導率 | E35: 想定CVR | F35: 想定CVR

Sheet SIM②_成果報酬
A2: Ver. | B2: 46315
A4: 株式会社横浜シミズ御中_LINEOA施策提案【SIM】成果報酬（応募1件 8,000円）（サイトのLINEボタン＋離脱防止＋サンクスLINE誘導＋通知メッセージ）
N5: ※これより→はPDFにするときに消すようにする（範囲外に）
A7: ■要件定義 | B7: 地点 | C7: 名称 | D7: 成果単価
A8: 新規CV | B8: ①_CV地点 | C8: 新規応募 | D8: 8000 | G8: サイトUU | H8: 8947 | J8: 想定顧客リスト | K8: 5000 | N8: CV①新規応募：サイトのLINEボタン・離脱防止で友だちになった方（応募前）が、配信から応募した数。サンクスLINE誘導で友だちになった方は応募済みなので、新規応募には数えない | O8: ※メルマガ、他SNS等でのリリースが出来るか
B9: ②_CV地点 | C9: - | D9: 0 | G9: うち広告 | H9: 0 | N9: 広告比率等を参考に | O9: LINEプレスリリースの可否 | P9: FALSE
A10: リピートCV | B10: ③_CV地点 | C10: 再応募 | D10: 8000 | G10: 応募（サイト・仮に） | H10: 150 | I10: リード（イメージ） | N10: サイトからの応募は、仮に月150件（新規登録は月約300人＝マイナビの求人10件×1件30人×4週ごと。そのうち自社サイトからの応募を半分と置いた。マイナビ経由はマイナビの完了画面で終わるので、サンクスLINE誘導の母数に入れない）
B11: ④_CV地点 | C11: - | D11: 0 | G11: CV（別施策）2 | H11: 0 | I11: マネタイズ（イメージ）
O12: ↓調整可能です！
A13: 項目 | D13: ※↓現状数値 | E13: 1か月目 | F13: 2か月目 | G13: 3か月目 | H13: 4か月目 | I13: 5か月目 | J13: 6か月目 | K13: 半年合計 | L13: 単月平均（６ヶ月） | N13: 20%くらいの調整は可能です。 | O13: →DYM作業用
A14: WEBサイト | B14: UU全体 | D14: =+H8 | E14: =+D14 | F14: =+E14 | G14: =+F14 | H14: =+G14 | I14: =+H14 | J14: =+I14 | N14: 求人サイトの月間UU 8,947（与件）。6か月同じ
B15: UU(うち広告) | D15: =+H9 | E15: =+D15 | F15: =+E15 | G15: =+F15 | H15: =+G15 | I15: =+H15 | J15: =+I15 | N15: （サイト固定リンク） | O15: AD以外のLINE誘導 | P15: 0.005 | S15: ■従量計算式↓
B16: CV（別施策） ※想定 | D16: =H10 | E16: =+D16 | F16: =+E16 | G16: =+F16 | H16: =+G16 | I16: =+H16 | J16: =+I16 | N16: （サイト固定リンク） | O16: ADでのLP/HP→LINE | P16: 0.0025 | S16: ■料金テーブル
A17: 施策 | B17: CPF | D17: FALSE | E17: FALSE | F17: FALSE | G17: FALSE | H17: FALSE | I17: FALSE | J17: FALSE | K17: -- | L17: -- | S17: 課金対象配信総数 | W17: 費用 | Z17: 単価
B18: 離脱防止ポップアップ | D18: FALSE | E18: TRUE | F18: TRUE | G18: TRUE | H18: TRUE | I18: TRUE | J18: TRUE | K18: -- | L18: -- | N18: KaiU表示率 | O18: 離脱防止表示率（AD） | P18: 0.65 | S18: 0 | T18: - | U18: 200000 | W18: 0 | X18: - | Y18: 600000 | Z18: 3
B19: サンクスLINE誘導 | D19: FALSE | E19: TRUE | F19: TRUE | G19: TRUE | H19: TRUE | I19: TRUE | J19: TRUE | N19: KaiU表示率 | O19: 離脱防止表示率（SEO） | P19: 0.55 | S19: 200000 | T19: - | U19: 15000000 | W19: 600000 | X19: - | Y19: =+U19*2.5 | Z19: 2.5
B20: 通知メッセージ_CV | D20: FALSE | E20: FALSE | F20: FALSE | G20: FALSE | H20: FALSE | I20: FALSE | J20: FALSE
B21: 通知メッセージ_既存リスト | D21: FALSE | E21: TRUE | F21: TRUE | G21: TRUE | H21: TRUE | I21: TRUE | J21: TRUE | K21: -- | L21: -- | N21: 通知メッセージ（既存リスト）：登録済みのスタッフに配信して友だち追加。リストは仮に5,000人（マイナビの求人10件×1件30人×4週ごと＝年約3,900人の新規登録＋それ以前から続けている方）。毎月リスト×15%×15%が友だちに（FMTの式） | O21: ↓企画投稿
A22: 施策増分 ※友だち | B22: CPF | D22: -- | E22: 0 | F22: 0 | G22: 0 | H22: 0 | I22: 0 | J22: 0 | N22: CPFコスト / CPFの単価設定 ※ブロック率が上がりやすい | O22: 開封率 | P22: 0.78
B23: 離脱防止ポップアップ | D23: -- | E23: =IF(E18=FALSE,0,E14*$P$18*0.125*0.125) | F23: =IF(F18=FALSE,0,F14*$P$18*0.125*0.125) | G23: =IF(G18=FALSE,0,G14*$P$18*0.125*0.125) | H23: =IF(H18=FALSE,0,H14*$P$18*0.125*0.125) | I23: =IF(I18=FALSE,0,I14*$P$18*0.125*0.125) | J23: =IF(J18=FALSE,0,J14*$P$18*0.125*0.125) | N23: 離脱防止ポップアップ＝UU×表示65%×クリック12.5%×追加12.5%（定義テキストの係数） | O23: クリック率 | P23: 0.1 | Q23: 4‐6か月後係数
B24: サンクスLINE誘導 | D24: -- | E24: =IF(E19=FALSE,0,E16*0.8*0.4) | F24: =IF(F19=FALSE,0,F16*0.8*0.4) | G24: =IF(G19=FALSE,0,G16*0.8*0.4) | H24: =IF(H19=FALSE,0,H16*0.8*0.4) | I24: =IF(I19=FALSE,0,I16*0.8*0.4) | J24: =IF(J19=FALSE,0,J16*0.8*0.4) | N24: サンクスLINE誘導＝応募×遷移80%×追加40%（資料と同じ・定義テキストの係数） | O24: audienceターゲ率 | P24: 0.8 | Q24: 0.8
B25: 通知メッセージ | D25: -- | E25: =+IF(E20=FALSE,0,SUM($H$10:$H$11)*0.7*0.3)+IF($E$21=FALSE,0,$K$8*0.15*0.15) | F25: =+IF(F20=FALSE,0,SUM($H$10:$H$11)*0.7*0.3)+IF($E$21=FALSE,0,$K$8*0.15*0.15) | G25: =+IF(G20=FALSE,0,SUM($H$10:$H$11)*0.7*0.3)+IF($E$21=FALSE,0,$K$8*0.15*0.15) | H25: =+IF(H20=FALSE,0,SUM($H$10:$H$11)*0.7*0.3)+IF($E$21=FALSE,0,$K$8*0.15*0.15) | I25: =+IF(I20=FALSE,0,SUM($H$10:$H$11)*0.7*0.3)+IF($E$21=FALSE,0,$K$8*0.15*0.15) | J25: =+IF(J20=FALSE,0,SUM($H$10:$H$11)*0.7*0.3)+IF($E$21=FALSE,0,$K$8*0.15*0.15) | N25: サンクス到達*情報一致率(70%前後)*実追加率 | O25: ↓ステップ配信
A26: 友だち数_増加数 | D26: -- | E26: =+SUM(E22:E25)+$H$9*$P$16+($H$8-$H$9)*$P$15+IF(P9=FALSE,0,$K$8*0.15*0.08) | F26: =+SUM(F22:F25)+$H$9*$P$16+($H$8-$H$9)*$P$15 | G26: =+SUM(G22:G25)+$H$9*$P$16+($H$8-$H$9)*$P$15 | H26: =+SUM(H22:H25)+$H$9*$P$16+($H$8-$H$9)*$P$15 | I26: =+SUM(I22:I25)+$H$9*$P$16+($H$8-$H$9)*$P$15 | J26: =+SUM(J22:J25)+$H$9*$P$16+($H$8-$H$9)*$P$15 | N26: サイトのLINEボタン（UUの0.5%・FMTの係数）＋離脱防止ポップアップ＋サンクスLINE誘導 | O26: 開封率 | P26: 0.725
A27: ブロック率 | D27: 0 | E27: 0.32 | F27: =+E$27*1.025 | G27: =+F$27*1.025 | H27: =+G$27*1.025 | I27: =+H$27*1.025 | J27: =+I$27*1.025 | N27: ブロック率：1か月目（E27）から、2か月目以降は前の月×1.025（式） | O27: クリック率 | P27: 0.12 | Q27: 4‐6か月後係数
A28: 友だち数 | D28: 0 | E28: =+D28+E26 | F28: =+E28+F26 | G28: =+F28+G26 | H28: =+G28+H26 | I28: =+H28+I26 | J28: =+I28+J26 | O28: audienceターゲ率 | P28: 0.2 | Q28: 0.8
A29: ターゲット数 | D29: =+D28*(1-D27) | E29: =+E28*(1-E27) | F29: =+F28*(1-F27) | G29: =+G28*(1-G27) | H29: =+H28*(1-H27) | I29: =+I28*(1-I27) | J29: =+J28*(1-J27) | N29: ※ターゲット数の増加分が通常の増加分を超えないように調整する
A30: 企画投稿数 | D30: 0 | E30: 4 | F30: 4 | G30: 4 | H30: 4 | I30: 4 | J30: 4 | N30: 企画配信 月4回（週1回。次回イベントの募集・会場の案内） | O30: CPFの単価設定
A31: 企画投稿からの流入 | D31: =+D30*D29*0.41*0.07 | E31: =+E29*E30*$P$24*$P$22*$P$23*$P$36 | F31: =+F29*F30*$P$24*$P$22*$P$23*$P$36 | G31: =+G29*G30*$P$24*$P$22*$P$23*$P$36 | H31: =+H29*H30*$P$24*$P$22*$P$23*$P$36*$Q$24 | I31: =+I29*I30*$P$24*$P$22*$P$23*$P$36*$Q$24 | J31: =+J29*J30*$P$24*$P$22*$P$23*$P$36*$Q$24
A32: ステップ配信本数 | D32: 0 | E32: 4 | F32: 4 | G32: 4 | H32: 4 | I32: 4 | J32: 4 | N32: ステップ配信 4通（あいさつメッセージの後、友だち追加から14日以内） | O32: 特典の強さ | P32: TRUE | Q32: =+IF(P32=TRUE,1.1,0.95)
A33: ステップ配信からの流入 | D33: 0 | E33: =+E29*E32*$P$26*$P$27*$P$28*$P$36 | F33: =+F29*F32*$P$26*$P$27*$P$28*$P$36 | G33: =+G29*G32*$P$26*$P$27*$P$28*$P$36 | H33: =+H29*H32*$P$26*$P$27*$P$28*$P$36*$Q$28 | I33: =+I29*I32*$P$26*$P$27*$P$28*$P$36*$Q$28 | J33: =+J29*J32*$P$26*$P$27*$P$28*$P$36*$Q$28 | O33: クリエイティブ強さ | P33: TRUE | Q33: =+IF(P33=TRUE,1.1,0.95)
A34: 配信数 | D34: =+D29*D30 | E34: =+E29*E30*$P$24+E29*E32*$P$28 | F34: =+F29*F30*$P$24+F29*F32*$P$28 | G34: =+G29*G30*$P$24+G29*G32*$P$28 | H34: =+H29*H30*$P$24*$Q$24+H29*H32*$P$28*$Q$28 | I34: =+I29*I30*$P$24*$Q$24+I29*I32*$P$28*$Q$28 | J34: =+J29*J30*$P$24*$Q$24+J29*J32*$P$28*$Q$28 | O34: 知名度強さ | P34: TRUE | Q34: =+IF(P34=TRUE,1.1,0.95)
A35: 想定Click数 | D35: =+D31*1.02 | E35: =+E31+E33+1.05*(E31+E33) | F35: =+F31+F33+1.05*(F31+F33) | G35: =+G31+G33+1.05*(G31+G33) | H35: =+H31+H33+1.05*(H31+H33) | I35: =+I31+I33+1.05*(I31+I33) | J35: =+J31+J33+1.05*(J31+J33) | O35: 動線の強さ | P35: TRUE | Q35: =+IF(P35=TRUE,1.1,0.95)
A36: 新規CV | B36: =+C8 | D36: 0 | E36: 2 | F36: 2 | G36: 4 | H36: 5 | I36: 5 | J36: 6 | K36: =SUM(E36:J36) | N36: 新規応募：サイトのLINEボタン・離脱防止で友だちになった方が、企画配信・ステップ配信から応募した数 | O36: 想定の係数（反応率） | P36: =1*(Q32*Q33*Q34*Q35)
B37: =+C9 | D37: 0 | E37: 0 | F37: 0 | G37: 0 | H37: 0 | I37: 0 | J37: 0 | K37: =SUM(E37:J37) | N37: 新規向け_
A38: リピートCV | B38: =+C10 | D38: 0 | E38: 0 | F38: 0 | G38: 1 | H38: 2 | I38: 3 | J38: 3 | K38: =SUM(E38:J38) | N38: 再応募：一度勤務した方が、次回イベントの募集から勤務希望を出した数（応募→勤務を経てからなので3か月目から） | O38: ※①＞②で作成
B39: =+C11 | D39: 0 | E39: 0 | F39: 0 | G39: 0 | H39: 0 | I39: 0 | J39: 0 | K39: =SUM(E39:J39) | N39: 既存向け_休眠顧客向け | O39: ※③＞④で作成
A40: 合計CV | D40: =+SUM(D36:D39) | E40: =+SUM(E36:E39) | F40: =+SUM(F36:F39) | G40: =+SUM(G36:G39) | H40: =+SUM(H36:H39) | I40: =+SUM(I36:I39) | J40: =+SUM(J36:J39) | K40: =SUM(E40:J40)
B41: CVR | D41: =+IFERROR(D40/D35,0) | E41: =+IFERROR(E40/E35,0) | F41: =+IFERROR(F40/F35,0) | G41: =+IFERROR(G40/G35,0) | H41: =+IFERROR(H40/H35,0) | I41: =+IFERROR(I40/I35,0) | J41: =+IFERROR(J40/J35,0) | N41: CV/流入数で計算、0.3%〜1%とかで推移。
A43: ■成果報酬運営 | C43: 現状数値 | D43: 初期
A44: 従量課金 | D44: -- | E44: =+E75*E76 | F44: =+F75*F76 | G44: =+G75*G76 | H44: =+H75*H76 | I44: =+I75*I76 | J44: =+J75*J76
...

Sheet SIM②_比較
E1: →通数減らすように係数： | F1: 0.6
A3: 比較項目 | C3: DYM実装前 | D3: DYM実装後（③か月） | E3: DYM実装後（⑥か月）
A4: コスト想定 ※月額（成果報酬プラン） | C4: =+'SIM②_成果報酬'!D24 | D4: =+'SIM②_成果報酬'!G51 | E4: =+'SIM②_成果報酬'!J51
A5: コスト想定 ※月額（固定プラン） | C5: =+'SIM②_成果報酬'!D25 | D5: =+'SIM②_成果報酬'!G61 | E5: =+'SIM②_成果報酬'!J61
A6: 友だち数想定 | C6: =+'SIM②_成果報酬'!D28 | D6: =+'SIM②_成果報酬'!G28 | E6: =+'SIM②_成果報酬'!J28
A7: ブロック率想定 | C7: =+'SIM②_成果報酬'!D27 | D7: =+'SIM②_成果報酬'!G27 | E7: =+'SIM②_成果報酬'!J27
A8: 友だち数（アクティブ）想定 | C8: =+'SIM②_成果報酬'!D29 | D8: =+'SIM②_成果報酬'!G29 | E8: =+'SIM②_成果報酬'!J29
A10: メッセ通数 | C10: =+'SIM②_成果報酬'!D34 | D10: =+'SIM②_成果報酬'!G34 | E10: =+'SIM②_成果報酬'!J34
A11: サイト流入数（LINEから） | C11: =+'SIM②_成果報酬'!D35 | D11: =+'SIM②_成果報酬'!G35 | E11: =+'SIM②_成果報酬'!J35
A12: 想定CPC（LINEOA施策）_成果報酬プラン | C12: =+IFERROR(C5/C11,0) | D12: =+D4/D11 | E12: =+E4/E11
A13: 想定CPC（LINEOA施策）_固定運用プラン | C13: =+IFERROR(C6/C12,0) | D13: =+D5/D11 | E13: =+E5/E11
R14: ■従量計算式↓
A15: 応募（サイト・仮に） | C15: =+'SIM②_成果報酬'!$H$10 | D15: =+'SIM②_成果報酬'!$H$10 | E15: =+'SIM②_成果報酬'!$H$10 | R15: ■料金テーブル
A16: CV数（+LINEOA施策） | C16: =SUM(C17:C20) | D16: =SUM(D17:D20) | E16: =SUM(E17:E20) | R16: 課金対象配信総数 | V16: 費用 | Y16: 単価
A17: CV①_新規応募 | C17: =+'SIM②_成果報酬'!D36 | D17: =+'SIM②_成果報酬'!G36 | E17: =+'SIM②_成果報酬'!J36 | R17: 0 | S17: - | T17: 200000 | V17: 0 | W17: - | X17: 600000 | Y17: 3
A18: - | C18: =+'SIM②_成果報酬'!D37 | D18: =+'SIM②_成果報酬'!G37 | E18: =+'SIM②_成果報酬'!J37 | R18: 200000 | S18: - | T18: 15000000 | V18: 600000 | W18: - | X18: =+T18*2.5 | Y18: 2.5
A19: CV③_再応募 | C19: =+'SIM②_成果報酬'!D38 | D19: =+'SIM②_成果報酬'!G38 | E19: =+'SIM②_成果報酬'!J38
A20: - | C20: =+'SIM②_成果報酬'!D39 | D20: =+'SIM②_成果報酬'!G39 | E20: =+'SIM②_成果報酬'!J39
A22: 成果報酬プラン_CPA（単純計算） | C22: =+IFERROR(C4/C16,"--") | D22: =+IFERROR(D4/D16,"--") | E22: =+IFERROR(E4/E16,"--")
A23: 固定費プラン_CPA（単純計算） | C23: =+IFERROR(C5/C16,"--") | D23: =+IFERROR(D5/D16,"--") | E23: =+IFERROR(E5/E16,"--")
A25: 備考_合計コスト(従量課金) ※アカウント費用 | C25: =+'SIM②_成果報酬'!E68+C29*C30 | D25: =+'SIM②_成果報酬'!G68+D29*D30 | E25: =+'SIM②_成果報酬'!J68+E29*E30
A29: 従量課金対象単価 | C29: =+IF(C10<=30000,0,C10-30000) | D29: =+IF(D10<=30000,0,D10-30000) | E29: =+IF(E10<=30000,0,E10-30000)
A30: 備考単価 | C30: =+IF(C29<=$T$17,$Y$17,IF(C29<=$T$18,$Y$18,IF(C29<=$T$19,$Y$19,IF(C29<=$T$20,$Y$20,IF(C29<=$T$21,$Y$21,IF(C29<=$T$22,$Y$22,IF(C29<=$T$23,$Y$23,IF(C29<=$T$24,$Y$24,IF(C29<=$T$25,$Y$25,IF(C29<=$T$26,$Y$26,IF(C29<=$T$27,$Y$27,IF(C29<=$T$28,$Y$28,IF(C29<=$T$29,$Y$29,0))))))))))))) | D30: =+IF(D29<=$T$17,$Y$17,IF(D29<=$T$18,$Y$18,IF(D29<=$T$19,$Y$19,IF(D29<=$T$20,$Y$20,IF(D29<=$T$21,$Y$21,IF(D29<=$T$22,$Y$22,IF(D29<=$T$23,$Y$23,IF(D29<=$T$24,$Y$24,IF(D29<=$T$25,$Y$25,IF(D29<=$T$26,$Y$26,IF(D29<=$T$27,$Y$27,IF(D29<=$T$28,$Y$28,IF(D29<=$T$29,$Y$29,0))))))))))))) | E30: =+IF(E29<=$T$17,$Y$17,IF(E29<=$T$18,$Y$18,IF(E29<=$T$19,$Y$19,IF(E29<=$T$20,$Y$20,IF(E29<=$T$21,$Y$21,IF(E29<=$T$22,$Y$22,IF(E29<=$T$23,$Y$23,IF(E29<=$T$24,$Y$24,IF(E29<=$T$25,$Y$25,IF(E29<=$T$26,$Y$26,IF(E29<=$T$27,$Y$27,IF(E29<=$T$28,$Y$28,IF(E29<=$T$29,$Y$29,0)))))))))))))
A35: 階層別 | C35: 母数 | D35: 誘導率 | E35: 想定CVR | F35: 想定CVR

Sheet SIM考え方
A2: 友だち数_増加施策
A3: 離脱防止 ※
A4: 掲載率 | B4: ※サイト構成、要望により変動 | E4: 1000
A5: クリック率 | B5: 0.085
A6: 追加率 | B6: 0.08
E7: =+E4*B5*B6
A8: サイト→LINEの導線の改善 ※
A9: 掲載率 | B9: ※サイト構成、要望により変動 | E9: 1000
A10: クリック率 | B10: 0.005
A11: 追加率 | B11: 0.08
E12: =+E9*B10*B11
A13: サンクスページ誘導 ※ | D13: ただCVが増えるわけではない
A14: 掲載数 | B14: ※サイト構成、要望により変動 | E14: 1000
A15: クリック率 | B15: 0.9 | C15: ※カウントしない
A16: 追加率 | B16: 0.35
E17: =+E14*B15*B16
A18: 通知メッセの改善 ※ | D18: ただCVが増えるわけではない
A19: 掲載率 | B19: 0.7 | C19: ※サイト構成、要望により変動 | E19: 1000
A20: クリック率 | B20: 1
A21: 追加率 | B21: 0.2
E22: =+E19*B20*B21
A23: 配信効率改善施策 | C23: ※具体的なセグメントの仕方、企画により変動 | I23: 課金
A24: > 通常メッセ | I24: 1 | J24: 企画投稿（セグメントor一斉配信）
A25: 開封率 | B25: 0.8 | I25: 2 | J25: 追いメッセージ（ステップ、シナリオ）
A26: クリック率 | B26: 0.06 | I26: 3 | J26: VOOM投稿 ※同時進行の場合が多い
A27: CV率 | B27: 0.003 | I27: 4 | J27: 通知メッセージ（1通7円くらいの想定） ※機能導入が必要 ※ツール費：月8万～
A29: > 追いメッセ（ステップ、シナリオ） | I29: 非課金
A30: 開封率 | B30: 0.75 | I30: 1 | J30: 自動の即時応答
A31: クリック率 | B31: 0.08 | I31: 2 | J31: 個別チャット対応
A32: CV率 | B32: 0.006 | I32: 3 | J32: あいさつメッセージ
I33: 4 | J33: （リッチメニュー）
A34: > その他（リッチメニュー）
A35: 開封率 | B35: --
A36: クリック率 | B36: 0.02
A37: CV率 | B37: 0.004
A39: >挨拶メッセ | E39: >挨拶メッセ（アンケート回答率）
A40: 開封率 | B40: 1 | E40: 開封率 | F40: --
A41: クリック率 | B41: 0.035 | E41: 回答率 | F41: 0.25
A42: CV率 | B42: 0.006
