Workbook

Sheet SIM2_チャイルドアイズ
A2: Ver. | B2: 46269
A4: 株式会社やる気スイッチグループ_LINEOA施策提案【SIM】
N5: ※これより→はPDFにするときに消すようにする（範囲外に）
A7: ■要件定義 | B7: 地点 | C7: 名称 | D7: 成果単価
A8: 新規CV | B8: ①_CV地点 | C8: 体験予約 | D8: 2000 | G8: UU | H8: 18784 | J8: 想定顧客リスト | K8: 500 | N8: SimilarWeb等を参考に | O8: ※メルマガ、他SNS等でのリリースが出来るか
B9: ②_CV地点 | C9: - | D9: 0 | G9: 広告・アフィUU | H9: 4500 | N9: 広告比率等を参考に | O9: LINEプレスリリースの可否 | P9: TRUE
A10: リピートCV | B10: ③_CV地点 | C10: - | D10: 0 | G10: CV（別施策）1 | H10: 100 | I10: リード（イメージ） | N10: CV聞けてれば→通知メッセ、サンクスLINE誘導
B11: ④_CV地点 | C11: - | D11: 0 | G11: CV（別施策）2 | H11: 0 | I11: マネタイズ（イメージ）
O12: ↓調整可能です！
A13: 項目 | D13: ※↓現状数値 | E13: 1か月目 | F13: 2か月目 | G13: 3か月目 | H13: 4か月目 | I13: 5か月目 | J13: 6か月目 | K13: 半年合計 | L13: 単月平均（６ヶ月） | N13: 20%くらいの調整は可能です。 | O13: →DYM作業用
A14: WEBサイト | B14: UU全体 | D14: =+H8 -> 18784 | E14: =+D14 -> 18784 | F14: =+E14 -> 18784 | G14: =+F14 -> 18784 | H14: =+G14 -> 18784 | I14: =+H14 -> 18784 | J14: =+I14 -> 18784
B15: UU(うち広告) | D15: =+H9 -> 4500 | E15: =+D15 -> 4500 | F15: =+E15 -> 4500 | G15: =+F15 -> 4500 | H15: =+G15 -> 4500 | I15: =+H15 -> 4500 | J15: =+I15 -> 4500 | N15: （サイト固定リンク） | O15: AD以外のLINE誘導 | P15: 0.005 | S15: ■従量計算式↓
B16: CV（別施策） ※想定 | D16: =H10 -> 100 | E16: =+D16 -> 100 | F16: =+E16 -> 100 | G16: =+F16 -> 100 | H16: =+G16 -> 100 | I16: =+H16 -> 100 | J16: =+I16 -> 100 | N16: （サイト固定リンク） | O16: ADでのLP/HP→LINE | P16: 0.0025 | S16: ■料金テーブル
A17: 施策 | B17: CPF | D17: FALSE | E17: FALSE | F17: FALSE | G17: FALSE | H17: FALSE | I17: FALSE | J17: FALSE | K17: -- | L17: -- | S17: 課金対象配信総数 | W17: 費用 | Z17: 単価
B18: 離脱防止 | D18: FALSE | E18: TRUE | F18: TRUE | G18: TRUE | H18: TRUE | I18: TRUE | J18: TRUE | K18: -- | L18: -- | N18: KaiU表示率 | O18: 離脱防止表示率（AD） | P18: 0.65 | S18: 0 | T18: - | U18: 200000 | W18: 0 | X18: - | Y18: 600000 | Z18: 3
B19: サンクスLINE誘導 | D19: FALSE | E19: FALSE | F19: FALSE | G19: FALSE | H19: FALSE | I19: FALSE | J19: FALSE | N19: KaiU表示率 | O19: 離脱防止表示率（SEO） | P19: 0.55 | S19: 200000 | T19: - | U19: 15000000 | W19: 600000 | X19: - | Y19: =+U19*2.5 -> 37500000 | Z19: 2.5
B20: 通知メッセージ_CV | D20: FALSE | E20: FALSE | F20: FALSE | G20: FALSE | H20: FALSE | I20: FALSE | J20: FALSE
B21: 通知メッセージ_既存リスト | D21: FALSE | E21: FALSE | F21: FALSE | G21: FALSE | H21: FALSE | I21: FALSE | J21: FALSE | K21: -- | L21: -- | O21: ↓企画投稿
A22: 施策増分 ※友だち | B22: CPF | D22: -- | E22: =IF(E17=FALSE,0,IF(E65=0,0,IFERROR(E65/P30,"D63を記入してください"))) -> 0 | F22: =E22*1.01 -> 0 | G22: =F22*1.01 -> 0 | H22: =G22*1.01 -> 0 | I22: =H22*1.01 -> 0 | J22: =I22*1.01 -> 0 | N22: CPFコスト / CPFの単価設定 ※ブロック率が上がりやすい | O22: 開封率 | P22: 0.78
B23: 離脱防止 | D23: -- | E23: =IF(E18=FALSE,0,E15*$P$18*0.08*0.08+(E14-E15)*$P$19*0.12*0.12) -> 131.84928 | F23: =IF(F18=FALSE,0,F15*$P$18*0.08*0.08+(F14-F15)*$P$19*0.12*0.12) -> 131.84928 | G23: =F23*1.01 -> 133.16777 | H23: =G23*1.01 -> 134.49945 | I23: =H23*1.01 -> 135.84445 | J23: =I23*1.01 -> 137.20289 | N23: 離脱防止表示率×UU×クリック率×実追加率 | O23: クリック率 | P23: 0.1 | Q23: 4‐6か月後係数
B24: サンクスLINE誘導 | D24: -- | E24: =+IF(E19=FALSE,0,SUM(H10:H11)*0.15) -> 0 | F24: =E24*1.01 -> 0 | G24: =F24*1.01 -> 0 | H24: =G24*1.01 -> 0 | I24: =H24*1.01 -> 0 | J24: =I24*1.01 -> 0 | N24: CV(別施策)*誘導成功率*実追加率 | O24: audienceターゲ率 | P24: 0.8 | Q24: 0.8
B25: 通知メッセージ | D25: -- | E25: =+IF(E20=FALSE,0,SUM($H$10:$H$11)*0.7*0.3)+IF($E$21=FALSE,0,$K$8*0.15*0.15) -> 0 | F25: =+IF(F20=FALSE,0,SUM($H$10:$H$11)*0.7*0.3)+IF($E$21=FALSE,0,$K$8*0.15*0.15) -> 0 | G25: =+IF(G20=FALSE,0,SUM($H$10:$H$11)*0.7*0.3)+IF($E$21=FALSE,0,$K$8*0.15*0.15) -> 0 | H25: =+IF(H20=FALSE,0,SUM($H$10:$H$11)*0.7*0.3)+IF($E$21=FALSE,0,$K$8*0.15*0.15) -> 0 | I25: =+IF(I20=FALSE,0,SUM($H$10:$H$11)*0.7*0.3)+IF($E$21=FALSE,0,$K$8*0.15*0.15) -> 0 | J25: =+IF(J20=FALSE,0,SUM($H$10:$H$11)*0.7*0.3)+IF($E$21=FALSE,0,$K$8*0.15*0.15) -> 0 | N25: サンクス到達*情報一致率(70%前後)*実追加率 | O25: ↓ステップ配信
A26: 友だち数_増加数 | D26: -- | E26: =+SUM(E22:E25)+$H$9*$P$16+($H$8-$H$9)*$P$15+IF(P9=FALSE,0,$K$8*0.15*0.08) -> 220.51928 | F26: =+SUM(F22:F25)+$H$9*$P$16+($H$8-$H$9)*$P$15 -> 214.51928 | G26: =+SUM(G22:G25)+$H$9*$P$16+($H$8-$H$9)*$P$15 -> 215.83777 | H26: =+SUM(H22:H25)+$H$9*$P$16+($H$8-$H$9)*$P$15 -> 217.16945 | I26: =+SUM(I22:I25)+$H$9*$P$16+($H$8-$H$9)*$P$15 -> 218.51445 | J26: =+SUM(J22:J25)+$H$9*$P$16+($H$8-$H$9)*$P$15 -> 219.87289 | N26: ※上記記載に追加して、LP、HPからのLINE誘導を加味する | O26: 開封率 | P26: 0.725
A27: ブロック率 | D27: 0 | E27: 0.316 | F27: =+E27*1.025 -> 0.3239 | G27: =+F27*1.025 -> 0.3319975 | H27: =+G27*1.025 -> 0.34029744 | I27: =+H27*1.025 -> 0.34880487 | J27: =+I27*1.025 -> 0.357525 | O27: クリック率 | P27: 0.12 | Q27: 4‐6か月後係数
A28: 友だち数 | D28: 0 | E28: =+D28+E26 -> 220.51928 | F28: =+E28+F26 -> 435.03856 | G28: =+F28+G26 -> 650.87633 | H28: =+G28+H26 -> 868.04578 | I28: =+H28+I26 -> 1086.5602 | J28: =+I28+J26 -> 1306.4331 | O28: audienceターゲ率 | P28: 0.2 | Q28: 0.8
A29: ターゲット数 | D29: 0 | E29: =+E28*(1-E27) -> 150.83519 | F29: =+F28*(1-F27) -> 294.12957 | G29: =+G28*(1-G27) -> 434.78702 | H29: =+H28*(1-H27) -> 572.65203 | I29: =+I28*(1-I27) -> 707.56273 | J29: =+J28*(1-J27) -> 839.35062 | N29: ※ターゲット数の増加分が通常の増加分を超えないように調整する
A30: 企画投稿数 | D30: 0 | E30: 3 | F30: 3 | G30: 3 | H30: 3 | I30: 3 | J30: 3 | N30: ←基本本数が4本として設計する（ユーザー数と固定費で調整） | O30: CPFの単価設定
A31: 企画投稿からの流入 | D31: =+D30*D29*0.41*0.07 -> 0 | E31: =+E29*E30*$P$24*$P$22*$P$23*$P$36 -> 41.340836 | F31: =+F29*F30*$P$24*$P$22*$P$23*$P$36 -> 80.614891 | G31: =+G29*G30*$P$24*$P$22*$P$23*$P$36 -> 119.16622 | H31: =+H29*H30*$P$24*$P$22*$P$23*$P$36*$Q$24 -> 125.56175 | I31: =+I29*I30*$P$24*$P$22*$P$23*$P$36*$Q$24 -> 155.14276 | J31: =+J29*J30*$P$24*$P$22*$P$23*$P$36*$Q$24 -> 184.03905
A32: ステップ配信本数 | D32: 0 | E32: 10 | F32: 10 | G32: 10 | H32: 10 | I32: 10 | J32: 10 | N32: ←基本本数が4本として設計する | O32: 特典の強さ | P32: TRUE | Q32: =+IF(P32=TRUE,1.1,0.95) -> 1.1
A33: ステップ配信からの流入 | D33: 0 | E33: =+E29*E32*$P$26*$P$27*$P$28*$P$36 -> 38.425777 | F33: =+F29*F32*$P$26*$P$27*$P$28*$P$36 -> 74.930508 | G33: =+G29*G32*$P$26*$P$27*$P$28*$P$36 -> 110.76347 | H33: =+H29*H32*$P$26*$P$27*$P$28*$P$36*$Q$28 -> 116.70804 | I33: =+I29*I32*$P$26*$P$27*$P$28*$P$36*$Q$28 -> 144.20321 | J33: =+J29*J32*$P$26*$P$27*$P$28*$P$36*$Q$28 -> 171.06194 | O33: クリエイティブ強さ | P33: TRUE | Q33: =+IF(P33=TRUE,1.1,0.95) -> 1.1
A34: 配信数 | D34: =+D29*D30 -> 0 | E34: =+E29*E30*$P$24+E29*E32*$P$28 -> 663.67483 | F34: =+F29*F30*$P$24+F29*F32*$P$28 -> 1294.1701 | G34: =+G29*G30*$P$24+G29*G32*$P$28 -> 1913.0629 | H34: =+H29*H30*$P$24*$Q$24+H29*H32*$P$28*$Q$28 -> 2015.7351 | I34: =+I29*I30*$P$24*$Q$24+I29*I32*$P$28*$Q$28 -> 2490.6208 | J34: =+J29*J30*$P$24*$Q$24+J29*J32*$P$28*$Q$28 -> 2954.5142 | O34: 知名度強さ | P34: TRUE | Q34: =+IF(P34=TRUE,1.1,0.95) -> 1.1
A35: 想定Click数 | D35: =+D31*1.02 -> 0 | E35: =+E31+E33+1.05*(E31+E33) -> 163.52156 | F35: =+F31+F33+1.05*(F31+F33) -> 318.86807 | G35: =+G31+G33+1.05*(G31+G33) -> 471.35586 | H35: =+H31+H33+1.05*(H31+H33) -> 496.65308 | I35: =+I31+I33+1.05*(I31+I33) -> 613.65924 | J35: =+J31+J33+1.05*(J31+J33) -> 727.95704 | O35: 動線の強さ | P35: TRUE | Q35: =+IF(P35=TRUE,1.1,0.95) -> 1.1
A36: 新規CV | B36: =+C8 -> 体験予約 | D36: 0 | E36: 2 | F36: 4 | G36: 7 | H36: 9 | I36: 10 | J36: 12 | K36: =SUM(E36:J36) -> 44 | N36: 新規向け_ | O36: 想定の係数（反応率） | P36: =1*(Q32*Q33*Q34*Q35) -> 1.4641
B37: =+C9 -> - | D37: 0 | E37: 0 | F37: 0 | G37: 0 | H37: 0 | I37: 0 | J37: 0 | K37: =SUM(E37:J37) -> 0 | N37: 新規向け_
A38: リピートCV | B38: =+C10 -> - | D38: 0 | E38: 0 | F38: 0 | G38: 0 | H38: 0 | I38: 0 | J38: 0 | K38: =SUM(E38:J38) -> 0 | N38: 既存向け_休眠顧客向け | O38: ※①＞②で作成
B39: =+C11 -> - | D39: 0 | E39: 0 | F39: 0 | G39: 0 | H39: 0 | I39: 0 | J39: 0 | K39: =SUM(E39:J39) -> 0 | N39: 既存向け_休眠顧客向け | O39: ※③＞④で作成
A40: 合計CV | D40: =+SUM(D36:D39) -> 0 | E40: =+SUM(E36:E39) -> 2 | F40: =+SUM(F36:F39) -> 4 | G40: =+SUM(G36:G39) -> 7 | H40: =+SUM(H36:H39) -> 9 | I40: =+SUM(I36:I39) -> 10 | J40: =+SUM(J36:J39) -> 12 | K40: =SUM(E40:J40) -> 44
B41: CVR | D41: =+IFERROR(D40/D35,0) -> 0 | E41: =+IFERROR(E40/E35,0) -> 0.012230803 | F41: =+IFERROR(F40/F35,0) -> 0.012544373 | G41: =+IFERROR(G40/G35,0) -> 0.014850775 | H41: =+IFERROR(H40/H35,0) -> 0.018121301 | I41: =+IFERROR(I40/I35,0) -> 0.016295689 | J41: =+IFERROR(J40/J35,0) -> 0.016484489 | N41: CV/流入数で計算、0.3%〜1%とかで推移。
A43: ■成果報酬運営 | C43: 現状数値 | D43: 初期
A44: 従量課金 | D44: -- | E44: =+E75*E76 -> 0 | F44: =+F75*F76 -> 0 | G44: =+G75*G76 -> 0 | H44: =+H75*H76 -> 0 | I44: =+I75*I76 -> 0 | J44: =+J75*J76 -> 0
...

Sheet SIM1_忍者ナイン
A2: Ver. | B2: 46269
A4: 株式会社やる気スイッチグループ_LINEOA施策提案【SIM】
N5: ※これより→はPDFにするときに消すようにする（範囲外に）
A7: ■要件定義 | B7: 地点 | C7: 名称 | D7: 成果単価
A8: 新規CV | B8: ①_CV地点 | C8: 体験予約 | D8: 2000 | G8: UU | H8: 17607 | J8: 想定顧客リスト | K8: 500 | N8: SimilarWeb等を参考に | O8: ※メルマガ、他SNS等でのリリースが出来るか
B9: ②_CV地点 | C9: - | D9: 0 | G9: 広告・アフィUU | H9: 7000 | N9: 広告比率等を参考に | O9: LINEプレスリリースの可否 | P9: TRUE
A10: リピートCV | B10: ③_CV地点 | C10: - | D10: 0 | G10: CV（別施策）1 | H10: 100 | I10: リード（イメージ） | N10: CV聞けてれば→通知メッセ、サンクスLINE誘導
B11: ④_CV地点 | C11: - | D11: 0 | G11: CV（別施策）2 | H11: 0 | I11: マネタイズ（イメージ）
O12: ↓調整可能です！
A13: 項目 | D13: ※↓現状数値 | E13: 1か月目 | F13: 2か月目 | G13: 3か月目 | H13: 4か月目 | I13: 5か月目 | J13: 6か月目 | K13: 半年合計 | L13: 単月平均（６ヶ月） | N13: 20%くらいの調整は可能です。 | O13: →DYM作業用
A14: WEBサイト | B14: UU全体 | D14: =+H8 -> 17607 | E14: =+D14 -> 17607 | F14: =+E14 -> 17607 | G14: =+F14 -> 17607 | H14: =+G14 -> 17607 | I14: =+H14 -> 17607 | J14: =+I14 -> 17607
B15: UU(うち広告) | D15: =+H9 -> 7000 | E15: =+D15 -> 7000 | F15: =+E15 -> 7000 | G15: =+F15 -> 7000 | H15: =+G15 -> 7000 | I15: =+H15 -> 7000 | J15: =+I15 -> 7000 | N15: （サイト固定リンク） | O15: AD以外のLINE誘導 | P15: 0.005 | S15: ■従量計算式↓
B16: CV（別施策） ※想定 | D16: =H10 -> 100 | E16: =+D16 -> 100 | F16: =+E16 -> 100 | G16: =+F16 -> 100 | H16: =+G16 -> 100 | I16: =+H16 -> 100 | J16: =+I16 -> 100 | N16: （サイト固定リンク） | O16: ADでのLP/HP→LINE | P16: 0.0025 | S16: ■料金テーブル
A17: 施策 | B17: CPF | D17: FALSE | E17: FALSE | F17: FALSE | G17: FALSE | H17: FALSE | I17: FALSE | J17: FALSE | K17: -- | L17: -- | S17: 課金対象配信総数 | W17: 費用 | Z17: 単価
B18: 離脱防止 | D18: FALSE | E18: TRUE | F18: TRUE | G18: TRUE | H18: TRUE | I18: TRUE | J18: TRUE | K18: -- | L18: -- | N18: KaiU表示率 | O18: 離脱防止表示率（AD） | P18: 0.65 | S18: 0 | T18: - | U18: 200000 | W18: 0 | X18: - | Y18: 600000 | Z18: 3
B19: サンクスLINE誘導 | D19: FALSE | E19: FALSE | F19: FALSE | G19: FALSE | H19: FALSE | I19: FALSE | J19: FALSE | N19: KaiU表示率 | O19: 離脱防止表示率（SEO） | P19: 0.55 | S19: 200000 | T19: - | U19: 15000000 | W19: 600000 | X19: - | Y19: =+U19*2.5 -> 37500000 | Z19: 2.5
B20: 通知メッセージ_CV | D20: FALSE | E20: FALSE | F20: FALSE | G20: FALSE | H20: FALSE | I20: FALSE | J20: FALSE
B21: 通知メッセージ_既存リスト | D21: FALSE | E21: FALSE | F21: FALSE | G21: FALSE | H21: FALSE | I21: FALSE | J21: FALSE | K21: -- | L21: -- | O21: ↓企画投稿
A22: 施策増分 ※友だち | B22: CPF | D22: -- | E22: =IF(E17=FALSE,0,IF(E65=0,0,IFERROR(E65/P30,"D63を記入してください"))) -> 0 | F22: =E22*1.01 -> 0 | G22: =F22*1.01 -> 0 | H22: =G22*1.01 -> 0 | I22: =H22*1.01 -> 0 | J22: =I22*1.01 -> 0 | N22: CPFコスト / CPFの単価設定 ※ブロック率が上がりやすい | O22: 開封率 | P22: 0.78
B23: 離脱防止 | D23: -- | E23: =IF(E18=FALSE,0,E15*$P$18*0.08*0.08+(E14-E15)*$P$19*0.12*0.12) -> 113.12744 | F23: =IF(F18=FALSE,0,F15*$P$18*0.08*0.08+(F14-F15)*$P$19*0.12*0.12) -> 113.12744 | G23: =F23*1.01 -> 114.25871 | H23: =G23*1.01 -> 115.4013 | I23: =H23*1.01 -> 116.55531 | J23: =I23*1.01 -> 117.72087 | N23: 離脱防止表示率×UU×クリック率×実追加率 | O23: クリック率 | P23: 0.1 | Q23: 4‐6か月後係数
B24: サンクスLINE誘導 | D24: -- | E24: =+IF(E19=FALSE,0,SUM(H10:H11)*0.15) -> 0 | F24: =E24*1.01 -> 0 | G24: =F24*1.01 -> 0 | H24: =G24*1.01 -> 0 | I24: =H24*1.01 -> 0 | J24: =I24*1.01 -> 0 | N24: CV(別施策)*誘導成功率*実追加率 | O24: audienceターゲ率 | P24: 0.8 | Q24: 0.8
B25: 通知メッセージ | D25: -- | E25: =+IF(E20=FALSE,0,SUM($H$10:$H$11)*0.7*0.3)+IF($E$21=FALSE,0,$K$8*0.15*0.15) -> 0 | F25: =+IF(F20=FALSE,0,SUM($H$10:$H$11)*0.7*0.3)+IF($E$21=FALSE,0,$K$8*0.15*0.15) -> 0 | G25: =+IF(G20=FALSE,0,SUM($H$10:$H$11)*0.7*0.3)+IF($E$21=FALSE,0,$K$8*0.15*0.15) -> 0 | H25: =+IF(H20=FALSE,0,SUM($H$10:$H$11)*0.7*0.3)+IF($E$21=FALSE,0,$K$8*0.15*0.15) -> 0 | I25: =+IF(I20=FALSE,0,SUM($H$10:$H$11)*0.7*0.3)+IF($E$21=FALSE,0,$K$8*0.15*0.15) -> 0 | J25: =+IF(J20=FALSE,0,SUM($H$10:$H$11)*0.7*0.3)+IF($E$21=FALSE,0,$K$8*0.15*0.15) -> 0 | N25: サンクス到達*情報一致率(70%前後)*実追加率 | O25: ↓ステップ配信
A26: 友だち数_増加数 | D26: -- | E26: =+SUM(E22:E25)+$H$9*$P$16+($H$8-$H$9)*$P$15+IF(P9=FALSE,0,$K$8*0.15*0.08) -> 189.66244 | F26: =+SUM(F22:F25)+$H$9*$P$16+($H$8-$H$9)*$P$15 -> 183.66244 | G26: =+SUM(G22:G25)+$H$9*$P$16+($H$8-$H$9)*$P$15 -> 184.79371 | H26: =+SUM(H22:H25)+$H$9*$P$16+($H$8-$H$9)*$P$15 -> 185.9363 | I26: =+SUM(I22:I25)+$H$9*$P$16+($H$8-$H$9)*$P$15 -> 187.09031 | J26: =+SUM(J22:J25)+$H$9*$P$16+($H$8-$H$9)*$P$15 -> 188.25587 | N26: ※上記記載に追加して、LP、HPからのLINE誘導を加味する | O26: 開封率 | P26: 0.725
A27: ブロック率 | D27: 0 | E27: 0.316 | F27: =+E27*1.025 -> 0.3239 | G27: =+F27*1.025 -> 0.3319975 | H27: =+G27*1.025 -> 0.34029744 | I27: =+H27*1.025 -> 0.34880487 | J27: =+I27*1.025 -> 0.357525 | O27: クリック率 | P27: 0.12 | Q27: 4‐6か月後係数
A28: 友だち数 | D28: 0 | E28: =+D28+E26 -> 189.66244 | F28: =+E28+F26 -> 373.32488 | G28: =+F28+G26 -> 558.11859 | H28: =+G28+H26 -> 744.0549 | I28: =+H28+I26 -> 931.14521 | J28: =+I28+J26 -> 1119.4011 | O28: audienceターゲ率 | P28: 0.2 | Q28: 0.8
A29: ターゲット数 | D29: 0 | E29: =+E28*(1-E27) -> 129.72911 | F29: =+F28*(1-F27) -> 252.40495 | G29: =+G28*(1-G27) -> 372.82462 | H29: =+H28*(1-H27) -> 490.85492 | I29: =+I28*(1-I27) -> 606.35722 | J29: =+J28*(1-J27) -> 719.18721 | N29: ※ターゲット数の増加分が通常の増加分を超えないように調整する
A30: 企画投稿数 | D30: 0 | E30: 3 | F30: 3 | G30: 3 | H30: 3 | I30: 3 | J30: 3 | N30: ←基本本数が4本として設計する（ユーザー数と固定費で調整） | O30: CPFの単価設定
A31: 企画投稿からの流入 | D31: =+D30*D29*0.41*0.07 -> 0 | E31: =+E29*E30*$P$24*$P$22*$P$23*$P$36 -> 35.556092 | F31: =+F29*F30*$P$24*$P$22*$P$23*$P$36 -> 69.179028 | G31: =+G29*G30*$P$24*$P$22*$P$23*$P$36 -> 102.18359 | H31: =+H29*H30*$P$24*$P$22*$P$23*$P$36*$Q$24 -> 107.62663 | I31: =+I29*I30*$P$24*$P$22*$P$23*$P$36*$Q$24 -> 132.95208 | J31: =+J29*J30*$P$24*$P$22*$P$23*$P$36*$Q$24 -> 157.69159
A32: ステップ配信本数 | D32: 0 | E32: 10 | F32: 10 | G32: 10 | H32: 10 | I32: 10 | J32: 10 | N32: ←基本本数が4本として設計する | O32: 特典の強さ | P32: TRUE | Q32: =+IF(P32=TRUE,1.1,0.95) -> 1.1
A33: ステップ配信からの流入 | D33: 0 | E33: =+E29*E32*$P$26*$P$27*$P$28*$P$36 -> 33.048932 | F33: =+F29*F32*$P$26*$P$27*$P$28*$P$36 -> 64.30102 | G33: =+G29*G32*$P$26*$P$27*$P$28*$P$36 -> 94.978339 | H33: =+H29*H32*$P$26*$P$27*$P$28*$P$36*$Q$28 -> 100.03757 | I33: =+I29*I32*$P$26*$P$27*$P$28*$P$36*$Q$28 -> 123.57725 | J33: =+J29*J32*$P$26*$P$27*$P$28*$P$36*$Q$28 -> 146.57231 | O33: クリエイティブ強さ | P33: TRUE | Q33: =+IF(P33=TRUE,1.1,0.95) -> 1.1
A34: 配信数 | D34: =+D29*D30 -> 0 | E34: =+E29*E30*$P$24+E29*E32*$P$28 -> 570.80808 | F34: =+F29*F30*$P$24+F29*F32*$P$28 -> 1110.5818 | G34: =+G29*G30*$P$24+G29*G32*$P$28 -> 1640.4283 | H34: =+H29*H30*$P$24*$Q$24+H29*H32*$P$28*$Q$28 -> 1727.8093 | I34: =+I29*I30*$P$24*$Q$24+I29*I32*$P$28*$Q$28 -> 2134.3774 | J34: =+J29*J30*$P$24*$Q$24+J29*J32*$P$28*$Q$28 -> 2531.539 | O34: 知名度強さ | P34: TRUE | Q34: =+IF(P34=TRUE,1.1,0.95) -> 1.1
A35: 想定Click数 | D35: =+D31*1.02 -> 0 | E35: =+E31+E33+1.05*(E31+E33) -> 140.6403 | F35: =+F31+F33+1.05*(F31+F33) -> 273.6341 | G35: =+G31+G33+1.05*(G31+G33) -> 404.18196 | H35: =+H31+H33+1.05*(H31+H33) -> 425.7116 | I35: =+I31+I33+1.05*(I31+I33) -> 525.88512 | J35: =+J31+J33+1.05*(J31+J33) -> 623.74099 | O35: 動線の強さ | P35: TRUE | Q35: =+IF(P35=TRUE,1.1,0.95) -> 1.1
A36: 新規CV | B36: =+C8 -> 体験予約 | D36: 0 | E36: 2 | F36: 4 | G36: 6 | H36: 8 | I36: 11 | J36: 13 | K36: =SUM(E36:J36) -> 44 | N36: 新規向け_ | O36: 想定の係数（反応率） | P36: =1*(Q32*Q33*Q34*Q35) -> 1.4641
B37: =+C9 -> - | D37: 0 | E37: 0 | F37: 0 | G37: 0 | H37: 0 | I37: 0 | J37: 0 | K37: =SUM(E37:J37) -> 0 | N37: 新規向け_
A38: リピートCV | B38: =+C10 -> - | D38: 0 | E38: 0 | F38: 0 | G38: 0 | H38: 0 | I38: 0 | J38: 0 | K38: =SUM(E38:J38) -> 0 | N38: 既存向け_休眠顧客向け | O38: ※①＞②で作成
B39: =+C11 -> - | D39: 0 | E39: 0 | F39: 0 | G39: 0 | H39: 0 | I39: 0 | J39: 0 | K39: =SUM(E39:J39) -> 0 | N39: 既存向け_休眠顧客向け | O39: ※③＞④で作成
A40: 合計CV | D40: =+SUM(D36:D39) -> 0 | E40: =+SUM(E36:E39) -> 2 | F40: =+SUM(F36:F39) -> 4 | G40: =+SUM(G36:G39) -> 6 | H40: =+SUM(H36:H39) -> 8 | I40: =+SUM(I36:I39) -> 11 | J40: =+SUM(J36:J39) -> 13 | K40: =SUM(E40:J40) -> 44
B41: CVR | D41: =+IFERROR(D40/D35,0) -> 0 | E41: =+IFERROR(E40/E35,0) -> 0.014220675 | F41: =+IFERROR(F40/F35,0) -> 0.014618061 | G41: =+IFERROR(G40/G35,0) -> 0.014844799 | H41: =+IFERROR(H40/H35,0) -> 0.018792065 | I41: =+IFERROR(I40/I35,0) -> 0.020917116 | J41: =+IFERROR(J40/J35,0) -> 0.020841984 | N41: CV/流入数で計算、0.3%〜1%とかで推移。
A43: ■成果報酬運営 | C43: 現状数値 | D43: 初期
A44: 従量課金 | D44: -- | E44: =+E75*E76 -> 0 | F44: =+F75*F76 -> 0 | G44: =+G75*G76 -> 0 | H44: =+H75*H76 -> 0 | I44: =+I75*I76 -> 0 | J44: =+J75*J76 -> 0
...

Sheet SIM1_比較
E1: →通数減らすように係数： | F1: 0.6
A3: 比較項目 | C3: DYM実装前 | D3: DYM実装後（③か月） | E3: DYM実装後（⑥か月）
A4: コスト想定 ※月額（成果報酬プラン） | C4: =+SIM1_忍者ナイン!D24 -> -- | D4: =+SIM1_忍者ナイン!G51 -> 32000 | E4: =+SIM1_忍者ナイン!J51 -> 66000
A5: コスト想定 ※月額（固定プラン） | C5: =+SIM1_忍者ナイン!D25 -> -- | D5: =+SIM1_忍者ナイン!G61 -> 20000 | E5: =+SIM1_忍者ナイン!J61 -> 40000
A6: 友だち数想定 | C6: =+SIM1_忍者ナイン!D28 -> 0 | D6: =+SIM1_忍者ナイン!G28 -> 558.11859 | E6: =+SIM1_忍者ナイン!J28 -> 1119.4011
A7: ブロック率想定 | C7: =+SIM1_忍者ナイン!D27 -> 0 | D7: =+D8/D6 -> 0.6680025 | E7: =+E8/E6 -> 0.642475
A8: 友だち数（アクティブ）想定 | C8: =+SIM1_忍者ナイン!D29 -> 0 | D8: =+SIM1_忍者ナイン!G29 -> 372.82462 | E8: =+SIM1_忍者ナイン!J29 -> 719.18721
A10: メッセ通数 | C10: =+SIM1_忍者ナイン!D34 -> 0 | D10: =+SIM1_忍者ナイン!G34 -> 1640.4283 | E10: =+SIM1_忍者ナイン!J34 -> 2531.539
A11: サイト流入数（LINEから） | C11: =+SIM1_忍者ナイン!D35 -> 0 | D11: =+SIM1_忍者ナイン!G35 -> 404.18196 | E11: =+SIM1_忍者ナイン!J35 -> 623.74099
A12: 想定CPC（LINEOA施策）_成果報酬プラン | C12: =+IFERROR(C5/C11,0) -> 0 | D12: =+D4/D11 -> 79.172262 | E12: =+E4/E11 -> 105.81315
A13: 想定CPC（LINEOA施策）_固定運用プラン | C13: =+IFERROR(C6/C12,0) -> 0 | D13: =+D5/D11 -> 49.482664 | E13: =+E5/E11 -> 64.129183
R14: ■従量計算式↓
A15: CV数（もともと） | C15: =+SIM1_忍者ナイン!D16 -> 100 | D15: =+SIM1_忍者ナイン!E16 -> 100 | E15: =+SIM1_忍者ナイン!F16 -> 100 | R15: ■料金テーブル
A16: CV数（+LINEOA施策） | C16: =SUM(C17:C20) -> 0 | D16: =SUM(D17:D20) -> 6 | E16: =SUM(E17:E20) -> 13 | R16: 課金対象配信総数 | V16: 費用 | Y16: 単価
A17: OA施策CV_内訳①_新規CV1 | C17: =+SIM1_忍者ナイン!D36 -> 0 | D17: =+SIM1_忍者ナイン!G36 -> 6 | E17: =+SIM1_忍者ナイン!J36 -> 13 | R17: 0 | S17: - | T17: 200000 | V17: 0 | W17: - | X17: 600000 | Y17: 3
A18: OA施策CV_内訳②_新規CV2 | C18: =+SIM1_忍者ナイン!D37 -> 0 | D18: =+SIM1_忍者ナイン!G37 -> 0 | E18: =+SIM1_忍者ナイン!J37 -> 0 | R18: 200000 | S18: - | T18: 15000000 | V18: 600000 | W18: - | X18: =+T18*2.5 -> 37500000 | Y18: 2.5
A19: OA施策CV_内訳③_リピCV3 | C19: =+SIM1_忍者ナイン!D38 -> 0 | D19: =+SIM1_忍者ナイン!G38 -> 0 | E19: =+SIM1_忍者ナイン!J38 -> 0
A20: OA施策CV_内訳④_リピCV4 | C20: =+SIM1_忍者ナイン!D39 -> 0 | D20: =+SIM1_忍者ナイン!G39 -> 0 | E20: =+SIM1_忍者ナイン!J39 -> 0
A22: 成果報酬プラン_CPA（単純計算） | C22: =+IFERROR(C4/C16,"--") -> -- | D22: =+IFERROR(D4/D16,"--") -> 5333.3333 | E22: =+IFERROR(E4/E16,"--") -> 5076.9231
A23: 固定費プラン_CPA（単純計算） | C23: =+IFERROR(C5/C16,"--") -> -- | D23: =+IFERROR(D5/D16,"--") -> 3333.3333 | E23: =+IFERROR(E5/E16,"--") -> 3076.9231
A25: 備考_合計コスト(従量課金) ※アカウント費用 | C25: =15000+C29*C30 -> 15000 | D25: =15000+D29*D30 -> 15000 | E25: =15000+E29*E30 -> 15000
A29: 従量課金対象単価 | C29: =+IF(C10<=30000,0,C10-30000) -> 0 | D29: =+IF(D10<=30000,0,D10-30000) -> 0 | E29: =+IF(E10<=30000,0,E10-30000) -> 0
A30: 備考単価 | C30: =+IF(C29<=$T$17,$Y$17,IF(C29<=$T$18,$Y$18,IF(C29<=$T$19,$Y$19,IF(C29<=$T$20,$Y$20,IF(C29<=$T$21,$Y$21,IF(C29<=$T$22,$Y$22,IF(C29<=$T$23,$Y$23,IF(C29<=$T$24,$Y$24,IF(C29<=$T$25,$Y$25,IF(C29<=$T$26,$Y$26,IF(C29<=$T$27,$Y$27,IF(C29<=$T$28,$Y$28,IF(C29<=$T$29,$Y$29,0))))))))))))) -> 3 | D30: =+IF(D29<=$T$17,$Y$17,IF(D29<=$T$18,$Y$18,IF(D29<=$T$19,$Y$19,IF(D29<=$T$20,$Y$20,IF(D29<=$T$21,$Y$21,IF(D29<=$T$22,$Y$22,IF(D29<=$T$23,$Y$23,IF(D29<=$T$24,$Y$24,IF(D29<=$T$25,$Y$25,IF(D29<=$T$26,$Y$26,IF(D29<=$T$27,$Y$27,IF(D29<=$T$28,$Y$28,IF(D29<=$T$29,$Y$29,0))))))))))))) -> 3 | E30: =+IF(E29<=$T$17,$Y$17,IF(E29<=$T$18,$Y$18,IF(E29<=$T$19,$Y$19,IF(E29<=$T$20,$Y$20,IF(E29<=$T$21,$Y$21,IF(E29<=$T$22,$Y$22,IF(E29<=$T$23,$Y$23,IF(E29<=$T$24,$Y$24,IF(E29<=$T$25,$Y$25,IF(E29<=$T$26,$Y$26,IF(E29<=$T$27,$Y$27,IF(E29<=$T$28,$Y$28,IF(E29<=$T$29,$Y$29,0))))))))))))) -> 3
A35: 階層別 | C35: 母数 | D35: 誘導率 | E35: 想定CVR | F35: 想定CVR

Sheet SIM考え方
A2: 友だち数_増加施策
A3: 離脱防止 ※
A4: 掲載率 | B4: ※サイト構成、要望により変動 | E4: 1000
A5: クリック率 | B5: 0.085
A6: 追加率 | B6: 0.08
E7: =+E4*B5*B6 -> 6.8
A8: サイト→LINEの導線の改善 ※
A9: 掲載率 | B9: ※サイト構成、要望により変動 | E9: 1000
A10: クリック率 | B10: 0.005
A11: 追加率 | B11: 0.08
E12: =+E9*B10*B11 -> 0.4
A13: サンクスページ誘導 ※ | D13: ただCVが増えるわけではない
A14: 掲載数 | B14: ※サイト構成、要望により変動 | E14: 1000
A15: クリック率 | B15: 0.9 | C15: ※カウントしない
A16: 追加率 | B16: 0.35
E17: =+E14*B15*B16 -> 315
A18: 通知メッセの改善 ※ | D18: ただCVが増えるわけではない
A19: 掲載率 | B19: 0.7 | C19: ※サイト構成、要望により変動 | E19: 1000
A20: クリック率 | B20: 1
A21: 追加率 | B21: 0.2
E22: =+E19*B20*B21 -> 200
A23: 配信効率改善施策 | C23: ※具体的なセグメントの仕方、企画により変動 | I23: 課金
A24: > 通常メッセ | I24: 1 | J24: 企画投稿（セグメントor一斉配信）
A25: 開封率 | B25: 0.8 | I25: 2 | J25: 追いメッセージ（ステップ、シナリオ）
A26: クリック率 | B26: 0.06 | I26: 3 | J26: VOOM投稿 ※同時進行の場合が多い
A27: CV率 | B27: 0.003 | I27: 4 | J27: 通知メッセージ（1通7円くらいの想定） ※機能導入が必要 ※ツール費：月8万～
A29: > 追いメッセ（ステップ、シナリオ） | I29: 非課金
A30: 開封率 | B30: 0.75 | I30: 1 | J30: 自動の即時応答
A31: クリック率 | B31: 0.08 | I31: 2 | J31: 個別チャット対応
A32: CV率 | B32: 0.006 | I32: 3 | J32: あいさつメッセージ
I33: 4 | J33: （リッチメニュー）
A34: > その他（リッチメニュー）
A35: 開封率 | B35: --
A36: クリック率 | B36: 0.02
A37: CV率 | B37: 0.004
A39: >挨拶メッセ | E39: >挨拶メッセ（アンケート回答率）
A40: 開封率 | B40: 1 | E40: 開封率 | F40: --
A41: クリック率 | B41: 0.035 | E41: 回答率 | F41: 0.25
A42: CV率 | B42: 0.006
